Workbook
Name lst_Shift: Lists!$A$6:INDEX(Lists!$A:$A,5+COUNTA(Lists!$A$6:$A$1048576))
Name lst_Material: Lists!$C$6:INDEX(Lists!$C:$C,5+COUNTA(Lists!$C$6:$C$1048576))
Name lst_Area: Lists!$E$6:INDEX(Lists!$E:$E,5+COUNTA(Lists!$E$6:$E$1048576))
Name lst_Equipment_Class: Lists!$G$6:INDEX(Lists!$G:$G,5+COUNTA(Lists!$G$6:$G$1048576))
Name lst_Gold_Movement_Type: Lists!$I$6:INDEX(Lists!$I:$I,5+COUNTA(Lists!$I$6:$I$1048576))
Name lst_Yes_No: Lists!$K$6:INDEX(Lists!$K:$K,5+COUNTA(Lists!$K$6:$K$1048576))
Name lst_Source_Type: Lists!$M$6:INDEX(Lists!$M:$M,5+COUNTA(Lists!$M$6:$M$1048576))
Name lst_Destination_Type: Lists!$O$6:INDEX(Lists!$O:$O,5+COUNTA(Lists!$O$6:$O$1048576))
Name lst_Source: Lists!$R$6:INDEX(Lists!$R:$R,5+COUNTA(Lists!$R$6:$R$1048576))
Name lst_Destination: Lists!$U$6:INDEX(Lists!$U:$U,5+COUNTA(Lists!$U$6:$U$1048576))
Name cfg_Site: Config!$B$5
Name cfg_Company: Config!$B$6
Name cfg_ReportTitle: Config!$B$7
Name cfg_PriorLTIDate: Config!$B$8
Name cfg_TroyOz: Config!$B$9
Name cfg_HoursPerDay: Config!$B$10
Name cfg_RateBasisHours: Config!$B$11
Name cfg_Year: Config!$B$14
Name cfg_YearStart: Config!$B$15
Name cfg_YearEnd: Config!$B$16
Name cfg_LastDataDate: Config!$B$17
Name cfg_FeedCheck: Config!$B$18
Name cfg_YearCheck: Config!$B$19
Name cd_Date: Calc_Daily!$A$2:$A$366
Name cd_Month: Calc_Daily!$B$2:$B$366
Name cd_Day: Calc_Daily!$C$2:$C$366
Name cd_Days_In_Month: Calc_Daily!$D$2:$D$366
Name cd_Month_Start: Calc_Daily!$E$2:$E$366
Name cd_Ore_Mined_t: Calc_Daily!$F$2:$F$366
Name cd_Ore_Mined_t_MTD: Calc_Daily!$G$2:$G$366
Name cd_Ore_Mined_t_YTD: Calc_Daily!$H$2:$H$366
Name cd_Ore_Mined_oz: Calc_Daily!$I$2:$I$366
Name cd_Ore_Mined_oz_MTD: Calc_Daily!$J$2:$J$366
Name cd_Ore_Mined_oz_YTD: Calc_Daily!$K$2:$K$366
Name cd_Ore_Graded_t: Calc_Daily!$L$2:$L$366
Name cd_Ore_Graded_t_MTD: Calc_Daily!$M$2:$M$366
Name cd_Ore_Graded_t_YTD: Calc_Daily!$N$2:$N$366
Name cd_Ore_Grade_gpt: Calc_Daily!$O$2:$O$366
Name cd_Ore_Grade_gpt_MTD: Calc_Daily!$P$2:$P$366
Name cd_Ore_Grade_gpt_YTD: Calc_Daily!$Q$2:$Q$366
Name cd_Ore_Ungraded_t: Calc_Daily!$R$2:$R$366
Name cd_Ore_Ungraded_t_MTD: Calc_Daily!$S$2:$S$366
Name cd_Ore_Ungraded_t_YTD: Calc_Daily!$T$2:$T$366
Name cd_Waste_t: Calc_Daily!$U$2:$U$366
Name cd_Waste_t_MTD: Calc_Daily!$V$2:$V$366
Name cd_Waste_t_YTD: Calc_Daily!$W$2:$W$366
Name cd_TMM_t: Calc_Daily!$X$2:$X$366
Name cd_TMM_t_MTD: Calc_Daily!$Y$2:$Y$366
Name cd_TMM_t_YTD: Calc_Daily!$Z$2:$Z$366
Name cd_Strip_Ratio: Calc_Daily!$AA$2:$AA$366
Name cd_Strip_Ratio_MTD: Calc_Daily!$AB$2:$AB$366
Name cd_Strip_Ratio_YTD: Calc_Daily!$AC$2:$AC$366
Name cd_Rehandle_t: Calc_Daily!$AD$2:$AD$366
Name cd_Rehandle_t_MTD: Calc_Daily!$AE$2:$AE$366
Name cd_Rehandle_t_YTD: Calc_Daily!$AF$2:$AF$366
Name cd_Moved_Total_t: Calc_Daily!$AG$2:$AG$366
Name cd_Moved_Total_t_MTD: Calc_Daily!$AH$2:$AH$366
Name cd_Moved_Total_t_YTD: Calc_Daily!$AI$2:$AI$366
Name cd_Unclassified_t: Calc_Daily!$AJ$2:$AJ$366
Name cd_Unclassified_t_MTD: Calc_Daily!$AK$2:$AK$366

Sheet README
B2: Mako Gold Mine Production System, 2026
B3: Petowal Mining Company S.A.. Version 0.3.0. Generated workbook: do not restructure by hand; change the schema and regenerate.
B5: How the workbook works
B6: 1. Inputs are the green tabs: Plant, Mining_Movements, Mining_Daily, Fleet, Safety, Gold, Budget, Commentary. Each is an Excel table. Type in the blue-headed columns only; grey-headed columns are formulas that fill automatically.
B7: 2. Calc_Daily rebuilds every KPI per day from the tables (day, month to date, year to date, budget). Daily_Report, Monthly_Summary and Dashboard read only from Calc_Daily.
B8: 3. There are no links to other workbooks and no macros. Copying the file anywhere keeps it working.
B9: 4. Lists holds every drop-down. Add a new pit, stockpile or equipment class there; do not type free text into list columns.
B10: 5. Config holds the site constants (troy ounce, hours per day, injury rate basis), the stockpile opening balances (exactly one stockpile has Plant_Feed = Y) and the monthly safety history used for rolling 12-month rates. The reporting year is fixed when the workbook is generated; to roll to a new year run build_workbook.py --year, do not type over it.
B11: 6. If the report opens blank behind a yellow Protected View bar (a file received by e-mail or download), click Enable Editing; the workbook then calculates.
B13: Daily routine
B14: Plant: enter the row for the day (dates are pre-filled). Mining: add one movement row per source, material and destination; add the Mining_Daily row and one Fleet row per equipment class. HSE: enter the Safety row. Everyone: one Commentary row per topic. Then open Daily_Report, check the date in C5 and the 'Rows for this date' line in B7, and print or export to PDF.
B15: One person edits the file at a time: open, enter, save, close. If Excel opens it Read-Only someone else has it: wait, do not Save As a copy. Suggested order: Mining 06:30, Plant 06:45, HSE 07:00, Commentary 07:15. Simultaneous entry needs the file on SharePoint or OneDrive.
... B26: Schema and generator: mps_schema.json and build_workbook.py in the MPS tools folder. Report issues to the Director, Operations and Projects.

Sheet Daily_Report
B2: =cfg_ReportTitle
B3: =cfg_Company&" | "&cfg_Site
L4: row
B5: Report date | C5: =MAX(cfg_YearStart,MIN(TODAY()-1,cfg_YearEnd,IF(N(cfg_LastDataDate)>0,cfg_LastDataDate,cfg_YearEnd))) | F5: =IF(ISNUMBER(rpt_Row),cfg_YearCheck,"Report date is outside the reporting year: enter a date between 1 January and 31 December "&cfg_Year) | L5: =IFERROR(MATCH($C$5,cd_Date,0),NA())
B6: =IF(ISNUMBER(rpt_Row),"Data to "&IF(N(cfg_LastDataDate)>0,DAY(cfg_LastDataDate)&" "&CHOOSE(MONTH(cfg_LastDataDate),"Jan","Feb","Mar","Apr","May","Jun","Jul","Aug","Sep","Oct","Nov","Dec")&" "&YEAR(cfg_LastDataDate),"(no plant data yet)")&" | Week "&_xlfn.ISOWEEKNUM($C$5)&" | Day "&DAY($C$5)&" of "&DAY(EOMONTH($C$5,0)),"Report date is outside the reporting year")
B7: ="Rows for this date: Plant "&COUNTIFS(tblPlant[Date],rpt_Date,tblPlant[Milled_t],"<>")&", Movements "&COUNTIFS(tblMovement[Date],rpt_Date)&", Fleet "&COUNTIFS(tblFleet[Date],rpt_Date)&", Mining daily "&COUNTIFS(tblMiningDaily[Date],rpt_Date,tblMiningDaily[Diesel_L],"<>")&", Safety "&COUNTIFS(tblSafety[Date],rpt_Date,tblSafety[Hours_Employees],"<>")&", Comments "&COUNTIFS(tblCommentary[Date],rpt_Date)&" | Movement rows with unknown source or destination: "&(COUNTIF(tblMovement[Source_Type],"?")+COUNTIF(tblMovement[Dest_Type],"?"))&" | Movement rows dated outside the year: "&(COUNTIFS(tblMovement[Date],"<"&cfg_YearStart)+COUNTIFS(tblMovement[Date],">"&cfg_YearEnd))
B8: SAFETY | C8: Unit | D8: Day | E8: MTD | F8: MTD budget | G8: Var % | H8: YTD | I8: YTD budget | J8: Var %
B9: Hours worked | C9: h | D9: =IFERROR(INDEX(cd_Hours_Worked,rpt_Row),"") | E9: =IFERROR(INDEX(cd_Hours_Worked_MTD,rpt_Row),"") | F9: =IFERROR(INDEX(cd_Bud_Hours_Worked_MTD,rpt_Row),"") | G9: =IF(AND(ISNUMBER(F9),ISNUMBER(E9),F9<>0),E9/F9-1,"") | H9: =IFERROR(INDEX(cd_Hours_Worked_YTD,rpt_Row),"") | I9: =IFERROR(INDEX(cd_Bud_Hours_Worked_YTD,rpt_Row),"") | J9: =IF(AND(ISNUMBER(I9),ISNUMBER(H9),I9<>0),H9/I9-1,"")
B10: Recordable injuries | D10: =IFERROR(INDEX(cd_Recordables,rpt_Row),"") | E10: =IFERROR(INDEX(cd_Recordables_MTD,rpt_Row),"") | H10: =IFERROR(INDEX(cd_Recordables_YTD,rpt_Row),"")
B11: Lost time injuries | D11: =IFERROR(INDEX(cd_LTI,rpt_Row),"") | E11: =IFERROR(INDEX(cd_LTI_MTD,rpt_Row),"") | H11: =IFERROR(INDEX(cd_LTI_YTD,rpt_Row),"")
B12: Restricted work injuries | D12: =IFERROR(INDEX(cd_RWI,rpt_Row),"") | E12: =IFERROR(INDEX(cd_RWI_MTD,rpt_Row),"") | H12: =IFERROR(INDEX(cd_RWI_YTD,rpt_Row),"")
B13: Medical treatment injuries | D13: =IFERROR(INDEX(cd_MTI,rpt_Row),"") | E13: =IFERROR(INDEX(cd_MTI_MTD,rpt_Row),"") | H13: =IFERROR(INDEX(cd_MTI_YTD,rpt_Row),"")
B14: First aid injuries | D14: =IFERROR(INDEX(cd_FAI,rpt_Row),"") | E14: =IFERROR(INDEX(cd_FAI_MTD,rpt_Row),"") | H14: =IFERROR(INDEX(cd_FAI_YTD,rpt_Row),"")
B15: Near misses | D15: =IFERROR(INDEX(cd_Near_Miss,rpt_Row),"") | E15: =IFERROR(INDEX(cd_Near_Miss_MTD,rpt_Row),"") | H15: =IFERROR(INDEX(cd_Near_Miss_YTD,rpt_Row),"")
B16: Hazard reports | D16: =IFERROR(INDEX(cd_Hazard_Reports,rpt_Row),"") | E16: =IFERROR(INDEX(cd_Hazard_Reports_MTD,rpt_Row),"") | H16: =IFERROR(INDEX(cd_Hazard_Reports_YTD,rpt_Row),"")
B17: High potential incidents | D17: =IFERROR(INDEX(cd_HPI,rpt_Row),"") | E17: =IFERROR(INDEX(cd_HPI_MTD,rpt_Row),"") | H17: =IFERROR(INDEX(cd_HPI_YTD,rpt_Row),"")
B18: Environmental incidents | D18: =IFERROR(INDEX(cd_Env_Incidents,rpt_Row),"") | E18: =IFERROR(INDEX(cd_Env_Incidents_MTD,rpt_Row),"") | H18: =IFERROR(INDEX(cd_Env_Incidents_YTD,rpt_Row),"")
B19: Community incidents | D19: =IFERROR(INDEX(cd_Community_Incidents,rpt_Row),"") | E19: =IFERROR(INDEX(cd_Community_Incidents_MTD,rpt_Row),"") | H19: =IFERROR(INDEX(cd_Community_Incidents_YTD,rpt_Row),"")
B20: Vehicle incidents | D20: =IFERROR(INDEX(cd_Vehicle_Incidents,rpt_Row),"") | E20: =IFERROR(INDEX(cd_Vehicle_Incidents_MTD,rpt_Row),"") | H20: =IFERROR(INDEX(cd_Vehicle_Incidents_YTD,rpt_Row),"")
B21: TRIFR, rolling 12 months + MTD | C21: ="per "&TEXT(cfg_RateBasisHours,"#,##0")&" h" | D21: =IFERROR(INDEX(cd_TRIFR_12m,rpt_Row),"")
B22: LTIFR, rolling 12 months + MTD | C22: ="per "&TEXT(cfg_RateBasisHours,"#,##0")&" h" | D22: =IFERROR(INDEX(cd_LTIFR_12m,rpt_Row),"")
B23: Days since last LTI | D23: =IFERROR(INDEX(cd_Days_Since_LTI,rpt_Row),"")
B25: MINING | C25: Unit | D25: Day | E25: MTD | F25: MTD budget | G25: Var % | H25: YTD | I25: YTD budget | J25: Var %
B26: Ore mined (ex-pit) | C26: t | D26: =IFERROR(INDEX(cd_Ore_Mined_t,rpt_Row),"") | E26: =IFERROR(INDEX(cd_Ore_Mined_t_MTD,rpt_Row),"") | F26: =IFERROR(INDEX(cd_Bud_Ore_Mined_t_MTD,rpt_Row),"") | G26: =IF(AND(ISNUMBER(F26),ISNUMBER(E26),F26<>0),E26/F26-1,"") | H26: =IFERROR(INDEX(cd_Ore_Mined_t_YTD,rpt_Row),"") | I26: =IFERROR(INDEX(cd_Bud_Ore_Mined_t_YTD,rpt_Row),"") | J26: =IF(AND(ISNUMBER(I26),ISNUMBER(H26),I26<>0),H26/I26-1,"")
B27: Ore grade mined | C27: g/t | D27: =IFERROR(INDEX(cd_Ore_Grade_gpt,rpt_Row),"") | E27: =IFERROR(INDEX(cd_Ore_Grade_gpt_MTD,rpt_Row),"") | F27: =IFERROR(INDEX(cd_Bud_Ore_Grade_gpt_MTD,rpt_Row),"") | G27: =IF(AND(ISNUMBER(F27),ISNUMBER(E27),F27<>0),E27/F27-1,"") | H27: =IFERROR(INDEX(cd_Ore_Grade_gpt_YTD,rpt_Row),"") | I27: =IFERROR(INDEX(cd_Bud_Ore_Grade_gpt_YTD,rpt_Row),"") | J27: =IF(AND(ISNUMBER(I27),ISNUMBER(H27),I27<>0),H27/I27-1,"")
B28: Contained gold mined | C28: oz | D28: =IFERROR(INDEX(cd_Ore_Mined_oz,rpt_Row),"") | E28: =IFERROR(INDEX(cd_Ore_Mined_oz_MTD,rpt_Row),"") | F28: =IFERROR(INDEX(cd_Bud_Ore_Mined_oz_MTD,rpt_Row),"") | G28: =IF(AND(ISNUMBER(F28),ISNUMBER(E28),F28<>0),E28/F28-1,"") | H28: =IFERROR(INDEX(cd_Ore_Mined_oz_YTD,rpt_Row),"") | I28: =IFERROR(INDEX(cd_Bud_Ore_Mined_oz_YTD,rpt_Row),"") | J28: =IF(AND(ISNUMBER(I28),ISNUMBER(H28),I28<>0),H28/I28-1,"")
B29: Ore mined without a grade (check) | C29: t | D29: =IFERROR(INDEX(cd_Ore_Ungraded_t,rpt_Row),"") | E29: =IFERROR(INDEX(cd_Ore_Ungraded_t_MTD,rpt_Row),"") | H29: =IFERROR(INDEX(cd_Ore_Ungraded_t_YTD,rpt_Row),"")
B30: Waste mined | C30: t | D30: =IFERROR(INDEX(cd_Waste_t,rpt_Row),"") | E30: =IFERROR(INDEX(cd_Waste_t_MTD,rpt_Row),"") | F30: =IFERROR(INDEX(cd_Bud_Waste_t_MTD,rpt_Row),"") | G30: =IF(AND(ISNUMBER(F30),ISNUMBER(E30),F30<>0),E30/F30-1,"") | H30: =IFERROR(INDEX(cd_Waste_t_YTD,rpt_Row),"") | I30: =IFERROR(INDEX(cd_Bud_Waste_t_YTD,rpt_Row),"") | J30: =IF(AND(ISNUMBER(I30),ISNUMBER(H30),I30<>0),H30/I30-1,"")
B31: Total material moved | C31: t | D31: =IFERROR(INDEX(cd_TMM_t,rpt_Row),"") | E31: =IFERROR(INDEX(cd_TMM_t_MTD,rpt_Row),"") | F31: =IFERROR(INDEX(cd_Bud_TMM_t_MTD,rpt_Row),"") | G31: =IF(AND(ISNUMBER(F31),ISNUMBER(E31),F31<>0),E31/F31-1,"") | H31: =IFERROR(INDEX(cd_TMM_t_YTD,rpt_Row),"") | I31: =IFERROR(INDEX(cd_Bud_TMM_t_YTD,rpt_Row),"") | J31: =IF(AND(ISNUMBER(I31),ISNUMBER(H31),I31<>0),H31/I31-1,"")
B32: Strip ratio (waste : ore) | D32: =IFERROR(INDEX(cd_Strip_Ratio,rpt_Row),"") | E32: =IFERROR(INDEX(cd_Strip_Ratio_MTD,rpt_Row),"") | F32: =IFERROR(INDEX(cd_Bud_Strip_Ratio_MTD,rpt_Row),"") | G32: =IF(AND(ISNUMBER(F32),ISNUMBER(E32),F32<>0),E32/F32-1,"") | H32: =IFERROR(INDEX(cd_Strip_Ratio_YTD,rpt_Row),"") | I32: =IFERROR(INDEX(cd_Bud_Strip_Ratio_YTD,rpt_Row),"") | J32: =IF(AND(ISNUMBER(I32),ISNUMBER(H32),I32<>0),H32/I32-1,"")
B33: Rehandle from stockpiles | C33: t | D33: =IFERROR(INDEX(cd_Rehandle_t,rpt_Row),"") | E33: =IFERROR(INDEX(cd_Rehandle_t_MTD,rpt_Row),"") | H33: =IFERROR(INDEX(cd_Rehandle_t_YTD,rpt_Row),"")
B34: Movements with unknown source type (check) | C34: t | D34: =IFERROR(INDEX(cd_Unclassified_t,rpt_Row),"") | E34: =IFERROR(INDEX(cd_Unclassified_t_MTD,rpt_Row),"") | H34: =IFERROR(INDEX(cd_Unclassified_t_YTD,rpt_Row),"")
B35: Drilled | C35: m | D35: =IFERROR(INDEX(cd_Drill_m,rpt_Row),"") | E35: =IFERROR(INDEX(cd_Drill_m_MTD,rpt_Row),"") | F35: =IFERROR(INDEX(cd_Bud_Drill_m_MTD,rpt_Row),"") | G35: =IF(AND(ISNUMBER(F35),ISNUMBER(E35),F35<>0),E35/F35-1,"") | H35: =IFERROR(INDEX(cd_Drill_m_YTD,rpt_Row),"") | I35: =IFERROR(INDEX(cd_Bud_Drill_m_YTD,rpt_Row),"") | J35: =IF(AND(ISNUMBER(I35),ISNUMBER(H35),I35<>0),H35/I35-1,"")
B36: Grade control drilled | C36: m | D36: =IFERROR(INDEX(cd_GC_Drill_m,rpt_Row),"") | E36: =IFERROR(INDEX(cd_GC_Drill_m_MTD,rpt_Row),"") | H36: =IFERROR(INDEX(cd_GC_Drill_m_YTD,rpt_Row),"")
B37: Blasted | C37: t | D37: =IFERROR(INDEX(cd_Blast_t,rpt_Row),"") | E37: =IFERROR(INDEX(cd_Blast_t_MTD,rpt_Row),"") | H37: =IFERROR(INDEX(cd_Blast_t_YTD,rpt_Row),"")
B38: Powder factor | C38: kg/t | D38: =IFERROR(INDEX(cd_Powder_Factor_kgpt,rpt_Row),"") | E38: =IFERROR(INDEX(cd_Powder_Factor_kgpt_MTD,rpt_Row),"") | H38: =IFERROR(INDEX(cd_Powder_Factor_kgpt_YTD,rpt_Row),"")
B39: Mining diesel | C39: L | D39: =IFERROR(INDEX(cd_Diesel_Mining_L,rpt_Row),"") | E39: =IFERROR(INDEX(cd_Diesel_Mining_L_MTD,rpt_Row),"") | F39: =IFERROR(INDEX(cd_Bud_Diesel_Mining_L_MTD,rpt_Row),"") | G39: =IF(AND(ISNUMBER(F39),ISNUMBER(E39),F39<>0),E39/F39-1,"") | H39: =IFERROR(INDEX(cd_Diesel_Mining_L_YTD,rpt_Row),"") | I39: =IFERROR(INDEX(cd_Bud_Diesel_Mining_L_YTD,rpt_Row),"") | J39: =IF(AND(ISNUMBER(I39),ISNUMBER(H39),I39<>0),H39/I39-1,"")
B40: Excavator availability | C40: % | D40: =IFERROR(INDEX(cd_Exc_Availability_pct,rpt_Row),"") | E40: =IFERROR(INDEX(cd_Exc_Availability_pct_MTD,rpt_Row),"") | H40: =IFERROR(INDEX(cd_Exc_Availability_pct_YTD,rpt_Row),"")
B41: Excavator utilisation | C41: % | D41: =IFERROR(INDEX(cd_Exc_Utilisation_pct,rpt_Row),"") | E41: =IFERROR(INDEX(cd_Exc_Utilisation_pct_MTD,rpt_Row),"") | H41: =IFERROR(INDEX(cd_Exc_Utilisation_pct_YTD,rpt_Row),"")
B42: Excavator productivity (TMM + rehandle) | C42: t/h | D42: =IFERROR(INDEX(cd_Exc_Productivity_tph,rpt_Row),"") | E42: =IFERROR(INDEX(cd_Exc_Productivity_tph_MTD,rpt_Row),"") | H42: =IFERROR(INDEX(cd_Exc_Productivity_tph_YTD,rpt_Row),"")
...

Sheet Dashboard
B2: =cfg_Site&" dashboard "&cfg_Year
B3: ="Data to "&IF(N(cfg_LastDataDate)>0,DAY(cfg_LastDataDate)&" "&CHOOSE(MONTH(cfg_LastDataDate),"Jan","Feb","Mar","Apr","May","Jun","Jul","Aug","Sep","Oct","Nov","Dec")&" "&YEAR(cfg_LastDataDate),"(no plant data yet)")

Sheet Monthly_Summary
B2: =cfg_Site&" monthly summary "&cfg_Year
B3: ="Actuals to "&IF(N(cfg_LastDataDate)>0,DAY(cfg_LastDataDate)&" "&CHOOSE(MONTH(cfg_LastDataDate),"Jan","Feb","Mar","Apr","May","Jun","Jul","Aug","Sep","Oct","Nov","Dec")&" "&YEAR(cfg_LastDataDate),"(no plant data yet)")&". Budget from the Budget sheet, pro-rata to that date for the current month and the Year column; full month otherwise. Ratios are month values, not averages of days."
B5: KPI | D5: 46023 | E5: 46054 | F5: 46082 | G5: 46113 | H5: 46143 | I5: 46174 | J5: 46204 | K5: 46235 | L5: 46266 | M5: 46296 | N5: 46327 | O5: 46357 | P5: Year
B6: Hours worked | C6: Actual | D6: =IF(DATE(cfg_Year,1,1)>cfg_LastDataDate,"",IFERROR(INDEX(cd_Hours_Worked_MTD,MATCH(MIN(EOMONTH(DATE(cfg_Year,1,1),0),cfg_LastDataDate),cd_Date,0)),"")) | E6: =IF(DATE(cfg_Year,2,1)>cfg_LastDataDate,"",IFERROR(INDEX(cd_Hours_Worked_MTD,MATCH(MIN(EOMONTH(DATE(cfg_Year,2,1),0),cfg_LastDataDate),cd_Date,0)),"")) | F6: =IF(DATE(cfg_Year,3,1)>cfg_LastDataDate,"",IFERROR(INDEX(cd_Hours_Worked_MTD,MATCH(MIN(EOMONTH(DATE(cfg_Year,3,1),0),cfg_LastDataDate),cd_Date,0)),"")) | G6: =IF(DATE(cfg_Year,4,1)>cfg_LastDataDate,"",IFERROR(INDEX(cd_Hours_Worked_MTD,MATCH(MIN(EOMONTH(DATE(cfg_Year,4,1),0),cfg_LastDataDate),cd_Date,0)),"")) | H6: =IF(DATE(cfg_Year,5,1)>cfg_LastDataDate,"",IFERROR(INDEX(cd_Hours_Worked_MTD,MATCH(MIN(EOMONTH(DATE(cfg_Year,5,1),0),cfg_LastDataDate),cd_Date,0)),"")) | I6: =IF(DATE(cfg_Year,6,1)>cfg_LastDataDate,"",IFERROR(INDEX(cd_Hours_Worked_MTD,MATCH(MIN(EOMONTH(DATE(cfg_Year,6,1),0),cfg_LastDataDate),cd_Date,0)),"")) | J6: =IF(DATE(cfg_Year,7,1)>cfg_LastDataDate,"",IFERROR(INDEX(cd_Hours_Worked_MTD,MATCH(MIN(EOMONTH(DATE(cfg_Year,7,1),0),cfg_LastDataDate),cd_Date,0)),"")) | K6: =IF(DATE(cfg_Year,8,1)>cfg_LastDataDate,"",IFERROR(INDEX(cd_Hours_Worked_MTD,MATCH(MIN(EOMONTH(DATE(cfg_Year,8,1),0),cfg_LastDataDate),cd_Date,0)),"")) | L6: =IF(DATE(cfg_Year,9,1)>cfg_LastDataDate,"",IFERROR(INDEX(cd_Hours_Worked_MTD,MATCH(MIN(EOMONTH(DATE(cfg_Year,9,1),0),cfg_LastDataDate),cd_Date,0)),"")) | M6: =IF(DATE(cfg_Year,10,1)>cfg_LastDataDate,"",IFERROR(INDEX(cd_Hours_Worked_MTD,MATCH(MIN(EOMONTH(DATE(cfg_Year,10,1),0),cfg_LastDataDate),cd_Date,0)),"")) | N6: =IF(DATE(cfg_Year,11,1)>cfg_LastDataDate,"",IFERROR(INDEX(cd_Hours_Worked_MTD,MATCH(MIN(EOMONTH(DATE(cfg_Year,11,1),0),cfg_LastDataDate),cd_Date,0)),"")) | O6: =IF(DATE(cfg_Year,12,1)>cfg_LastDataDate,"",IFERROR(INDEX(cd_Hours_Worked_MTD,MATCH(MIN(EOMONTH(DATE(cfg_Year,12,1),0),cfg_LastDataDate),cd_Date,0)),"")) | P6: =IFERROR(INDEX(cd_Hours_Worked_YTD,MATCH(MIN(cfg_YearEnd,cfg_LastDataDate),cd_Date,0)),"")
C7: Budget | D7: =IF(DATE(cfg_Year,1,1)>cfg_LastDataDate,IFERROR(INDEX(cd_Bud_Hours_Worked_Month,MATCH(DATE(cfg_Year,1,1),cd_Date,0)),""),IFERROR(INDEX(cd_Bud_Hours_Worked_MTD,MATCH(MIN(EOMONTH(DATE(cfg_Year,1,1),0),cfg_LastDataDate),cd_Date,0)),"")) | E7: =IF(DATE(cfg_Year,2,1)>cfg_LastDataDate,IFERROR(INDEX(cd_Bud_Hours_Worked_Month,MATCH(DATE(cfg_Year,2,1),cd_Date,0)),""),IFERROR(INDEX(cd_Bud_Hours_Worked_MTD,MATCH(MIN(EOMONTH(DATE(cfg_Year,2,1),0),cfg_LastDataDate),cd_Date,0)),"")) | F7: =IF(DATE(cfg_Year,3,1)>cfg_LastDataDate,IFERROR(INDEX(cd_Bud_Hours_Worked_Month,MATCH(DATE(cfg_Year,3,1),cd_Date,0)),""),IFERROR(INDEX(cd_Bud_Hours_Worked_MTD,MATCH(MIN(EOMONTH(DATE(cfg_Year,3,1),0),cfg_LastDataDate),cd_Date,0)),"")) | G7: =IF(DATE(cfg_Year,4,1)>cfg_LastDataDate,IFERROR(INDEX(cd_Bud_Hours_Worked_Month,MATCH(DATE(cfg_Year,4,1),cd_Date,0)),""),IFERROR(INDEX(cd_Bud_Hours_Worked_MTD,MATCH(MIN(EOMONTH(DATE(cfg_Year,4,1),0),cfg_LastDataDate),cd_Date,0)),"")) | H7: =IF(DATE(cfg_Year,5,1)>cfg_LastDataDate,IFERROR(INDEX(cd_Bud_Hours_Worked_Month,MATCH(DATE(cfg_Year,5,1),cd_Date,0)),""),IFERROR(INDEX(cd_Bud_Hours_Worked_MTD,MATCH(MIN(EOMONTH(DATE(cfg_Year,5,1),0),cfg_LastDataDate),cd_Date,0)),"")) | I7: =IF(DATE(cfg_Year,6,1)>cfg_LastDataDate,IFERROR(INDEX(cd_Bud_Hours_Worked_Month,MATCH(DATE(cfg_Year,6,1),cd_Date,0)),""),IFERROR(INDEX(cd_Bud_Hours_Worked_MTD,MATCH(MIN(EOMONTH(DATE(cfg_Year,6,1),0),cfg_LastDataDate),cd_Date,0)),"")) | J7: =IF(DATE(cfg_Year,7,1)>cfg_LastDataDate,IFERROR(INDEX(cd_Bud_Hours_Worked_Month,MATCH(DATE(cfg_Year,7,1),cd_Date,0)),""),IFERROR(INDEX(cd_Bud_Hours_Worked_MTD,MATCH(MIN(EOMONTH(DATE(cfg_Year,7,1),0),cfg_LastDataDate),cd_Date,0)),"")) | K7: =IF(DATE(cfg_Year,8,1)>cfg_LastDataDate,IFERROR(INDEX(cd_Bud_Hours_Worked_Month,MATCH(DATE(cfg_Year,8,1),cd_Date,0)),""),IFERROR(INDEX(cd_Bud_Hours_Worked_MTD,MATCH(MIN(EOMONTH(DATE(cfg_Year,8,1),0),cfg_LastDataDate),cd_Date,0)),"")) | L7: =IF(DATE(cfg_Year,9,1)>cfg_LastDataDate,IFERROR(INDEX(cd_Bud_Hours_Worked_Month,MATCH(DATE(cfg_Year,9,1),cd_Date,0)),""),IFERROR(INDEX(cd_Bud_Hours_Worked_MTD,MATCH(MIN(EOMONTH(DATE(cfg_Year,9,1),0),cfg_LastDataDate),cd_Date,0)),"")) | M7: =IF(DATE(cfg_Year,10,1)>cfg_LastDataDate,IFERROR(INDEX(cd_Bud_Hours_Worked_Month,MATCH(DATE(cfg_Year,10,1),cd_Date,0)),""),IFERROR(INDEX(cd_Bud_Hours_Worked_MTD,MATCH(MIN(EOMONTH(DATE(cfg_Year,10,1),0),cfg_LastDataDate),cd_Date,0)),"")) | N7: =IF(DATE(cfg_Year,11,1)>cfg_LastDataDate,IFERROR(INDEX(cd_Bud_Hours_Worked_Month,MATCH(DATE(cfg_Year,11,1),cd_Date,0)),""),IFERROR(INDEX(cd_Bud_Hours_Worked_MTD,MATCH(MIN(EOMONTH(DATE(cfg_Year,11,1),0),cfg_LastDataDate),cd_Date,0)),"")) | O7: =IF(DATE(cfg_Year,12,1)>cfg_LastDataDate,IFERROR(INDEX(cd_Bud_Hours_Worked_Month,MATCH(DATE(cfg_Year,12,1),cd_Date,0)),""),IFERROR(INDEX(cd_Bud_Hours_Worked_MTD,MATCH(MIN(EOMONTH(DATE(cfg_Year,12,1),0),cfg_LastDataDate),cd_Date,0)),"")) | P7: =IFERROR(INDEX(cd_Bud_Hours_Worked_YTD,MATCH(IF(N(cfg_LastDataDate)>0,MIN(cfg_YearEnd,cfg_LastDataDate),cfg_YearEnd),cd_Date,0)),"")
C8: Variance | D8: =IF(AND(ISNUMBER(D6),ISNUMBER(D7),D7<>0),D6/D7-1,"") | E8: =IF(AND(ISNUMBER(E6),ISNUMBER(E7),E7<>0),E6/E7-1,"") | F8: =IF(AND(ISNUMBER(F6),ISNUMBER(F7),F7<>0),F6/F7-1,"") | G8: =IF(AND(ISNUMBER(G6),ISNUMBER(G7),G7<>0),G6/G7-1,"") | H8: =IF(AND(ISNUMBER(H6),ISNUMBER(H7),H7<>0),H6/H7-1,"") | I8: =IF(AND(ISNUMBER(I6),ISNUMBER(I7),I7<>0),I6/I7-1,"") | J8: =IF(AND(ISNUMBER(J6),ISNUMBER(J7),J7<>0),J6/J7-1,"") | K8: =IF(AND(ISNUMBER(K6),ISNUMBER(K7),K7<>0),K6/K7-1,"") | ... P8: =IF(AND(ISNUMBER(P6),ISNUMBER(P7),P7<>0),P6/P7-1,"")
B10: Recordable injuries | C10: Actual | D10: =IF(DATE(cfg_Year,1,1)>cfg_LastDataDate,"",IFERROR(INDEX(cd_Recordables_MTD,MATCH(MIN(EOMONTH(DATE(cfg_Year,1,1),0),cfg_LastDataDate),cd_Date,0)),"")) | E10: =IF(DATE(cfg_Year,2,1)>cfg_LastDataDate,"",IFERROR(INDEX(cd_Recordables_MTD,MATCH(MIN(EOMONTH(DATE(cfg_Year,2,1),0),cfg_LastDataDate),cd_Date,0)),"")) | F10: =IF(DATE(cfg_Year,3,1)>cfg_LastDataDate,"",IFERROR(INDEX(cd_Recordables_MTD,MATCH(MIN(EOMONTH(DATE(cfg_Year,3,1),0),cfg_LastDataDate),cd_Date,0)),"")) | G10: =IF(DATE(cfg_Year,4,1)>cfg_LastDataDate,"",IFERROR(INDEX(cd_Recordables_MTD,MATCH(MIN(EOMONTH(DATE(cfg_Year,4,1),0),cfg_LastDataDate),cd_Date,0)),"")) | H10: =IF(DATE(cfg_Year,5,1)>cfg_LastDataDate,"",IFERROR(INDEX(cd_Recordables_MTD,MATCH(MIN(EOMONTH(DATE(cfg_Year,5,1),0),cfg_LastDataDate),cd_Date,0)),"")) | I10: =IF(DATE(cfg_Year,6,1)>cfg_LastDataDate,"",IFERROR(INDEX(cd_Recordables_MTD,MATCH(MIN(EOMONTH(DATE(cfg_Year,6,1),0),cfg_LastDataDate),cd_Date,0)),"")) | J10: =IF(DATE(cfg_Year,7,1)>cfg_LastDataDate,"",IFERROR(INDEX(cd_Recordables_MTD,MATCH(MIN(EOMONTH(DATE(cfg_Year,7,1),0),cfg_LastDataDate),cd_Date,0)),"")) | K10: =IF(DATE(cfg_Year,8,1)>cfg_LastDataDate,"",IFERROR(INDEX(cd_Recordables_MTD,MATCH(MIN(EOMONTH(DATE(cfg_Year,8,1),0),cfg_LastDataDate),cd_Date,0)),"")) | L10: =IF(DATE(cfg_Year,9,1)>cfg_LastDataDate,"",IFERROR(INDEX(cd_Recordables_MTD,MATCH(MIN(EOMONTH(DATE(cfg_Year,9,1),0),cfg_LastDataDate),cd_Date,0)),"")) | M10: =IF(DATE(cfg_Year,10,1)>cfg_LastDataDate,"",IFERROR(INDEX(cd_Recordables_MTD,MATCH(MIN(EOMONTH(DATE(cfg_Year,10,1),0),cfg_LastDataDate),cd_Date,0)),"")) | N10: =IF(DATE(cfg_Year,11,1)>cfg_LastDataDate,"",IFERROR(INDEX(cd_Recordables_MTD,MATCH(MIN(EOMONTH(DATE(cfg_Year,11,1),0),cfg_LastDataDate),cd_Date,0)),"")) | O10: =IF(DATE(cfg_Year,12,1)>cfg_LastDataDate,"",IFERROR(INDEX(cd_Recordables_MTD,MATCH(MIN(EOMONTH(DATE(cfg_Year,12,1),0),cfg_LastDataDate),cd_Date,0)),"")) | P10: =IFERROR(INDEX(cd_Recordables_YTD,MATCH(MIN(cfg_YearEnd,cfg_LastDataDate),cd_Date,0)),"")
B11: Lost time injuries | C11: Actual | D11: =IF(DATE(cfg_Year,1,1)>cfg_LastDataDate,"",IFERROR(INDEX(cd_LTI_MTD,MATCH(MIN(EOMONTH(DATE(cfg_Year,1,1),0),cfg_LastDataDate),cd_Date,0)),"")) | E11: =IF(DATE(cfg_Year,2,1)>cfg_LastDataDate,"",IFERROR(INDEX(cd_LTI_MTD,MATCH(MIN(EOMONTH(DATE(cfg_Year,2,1),0),cfg_LastDataDate),cd_Date,0)),"")) | F11: =IF(DATE(cfg_Year,3,1)>cfg_LastDataDate,"",IFERROR(INDEX(cd_LTI_MTD,MATCH(MIN(EOMONTH(DATE(cfg_Year,3,1),0),cfg_LastDataDate),cd_Date,0)),"")) | G11: =IF(DATE(cfg_Year,4,1)>cfg_LastDataDate,"",IFERROR(INDEX(cd_LTI_MTD,MATCH(MIN(EOMONTH(DATE(cfg_Year,4,1),0),cfg_LastDataDate),cd_Date,0)),"")) | H11: =IF(DATE(cfg_Year,5,1)>cfg_LastDataDate,"",IFERROR(INDEX(cd_LTI_MTD,MATCH(MIN(EOMONTH(DATE(cfg_Year,5,1),0),cfg_LastDataDate),cd_Date,0)),"")) | I11: =IF(DATE(cfg_Year,6,1)>cfg_LastDataDate,"",IFERROR(INDEX(cd_LTI_MTD,MATCH(MIN(EOMONTH(DATE(cfg_Year,6,1),0),cfg_LastDataDate),cd_Date,0)),"")) | J11: =IF(DATE(cfg_Year,7,1)>cfg_LastDataDate,"",IFERROR(INDEX(cd_LTI_MTD,MATCH(MIN(EOMONTH(DATE(cfg_Year,7,1),0),cfg_LastDataDate),cd_Date,0)),"")) | K11: =IF(DATE(cfg_Year,8,1)>cfg_LastDataDate,"",IFERROR(INDEX(cd_LTI_MTD,MATCH(MIN(EOMONTH(DATE(cfg_Year,8,1),0),cfg_LastDataDate),cd_Date,0)),"")) | L11: =IF(DATE(cfg_Year,9,1)>cfg_LastDataDate,"",IFERROR(INDEX(cd_LTI_MTD,MATCH(MIN(EOMONTH(DATE(cfg_Year,9,1),0),cfg_LastDataDate),cd_Date,0)),"")) | M11: =IF(DATE(cfg_Year,10,1)>cfg_LastDataDate,"",IFERROR(INDEX(cd_LTI_MTD,MATCH(MIN(EOMONTH(DATE(cfg_Year,10,1),0),cfg_LastDataDate),cd_Date,0)),"")) | N11: =IF(DATE(cfg_Year,11,1)>cfg_LastDataDate,"",IFERROR(INDEX(cd_LTI_MTD,MATCH(MIN(EOMONTH(DATE(cfg_Year,11,1),0),cfg_LastDataDate),cd_Date,0)),"")) | O11: =IF(DATE(cfg_Year,12,1)>cfg_LastDataDate,"",IFERROR(INDEX(cd_LTI_MTD,MATCH(MIN(EOMONTH(DATE(cfg_Year,12,1),0),cfg_LastDataDate),cd_Date,0)),"")) | P11: =IFERROR(INDEX(cd_LTI_YTD,MATCH(MIN(cfg_YearEnd,cfg_LastDataDate),cd_Date,0)),"")
B12: TRIFR, rolling 12 months + MTD | C12: Actual | D12: =IF(DATE(cfg_Year,1,1)>cfg_LastDataDate,"",IFERROR(INDEX(cd_TRIFR_12m,MATCH(MIN(EOMONTH(DATE(cfg_Year,1,1),0),cfg_LastDataDate),cd_Date,0)),"")) | E12: =IF(DATE(cfg_Year,2,1)>cfg_LastDataDate,"",IFERROR(INDEX(cd_TRIFR_12m,MATCH(MIN(EOMONTH(DATE(cfg_Year,2,1),0),cfg_LastDataDate),cd_Date,0)),"")) | F12: =IF(DATE(cfg_Year,3,1)>cfg_LastDataDate,"",IFERROR(INDEX(cd_TRIFR_12m,MATCH(MIN(EOMONTH(DATE(cfg_Year,3,1),0),cfg_LastDataDate),cd_Date,0)),"")) | G12: =IF(DATE(cfg_Year,4,1)>cfg_LastDataDate,"",IFERROR(INDEX(cd_TRIFR_12m,MATCH(MIN(EOMONTH(DATE(cfg_Year,4,1),0),cfg_LastDataDate),cd_Date,0)),"")) | H12: =IF(DATE(cfg_Year,5,1)>cfg_LastDataDate,"",IFERROR(INDEX(cd_TRIFR_12m,MATCH(MIN(EOMONTH(DATE(cfg_Year,5,1),0),cfg_LastDataDate),cd_Date,0)),"")) | I12: =IF(DATE(cfg_Year,6,1)>cfg_LastDataDate,"",IFERROR(INDEX(cd_TRIFR_12m,MATCH(MIN(EOMONTH(DATE(cfg_Year,6,1),0),cfg_LastDataDate),cd_Date,0)),"")) | J12: =IF(DATE(cfg_Year,7,1)>cfg_LastDataDate,"",IFERROR(INDEX(cd_TRIFR_12m,MATCH(MIN(EOMONTH(DATE(cfg_Year,7,1),0),cfg_LastDataDate),cd_Date,0)),"")) | K12: =IF(DATE(cfg_Year,8,1)>cfg_LastDataDate,"",IFERROR(INDEX(cd_TRIFR_12m,MATCH(MIN(EOMONTH(DATE(cfg_Year,8,1),0),cfg_LastDataDate),cd_Date,0)),"")) | L12: =IF(DATE(cfg_Year,9,1)>cfg_LastDataDate,"",IFERROR(INDEX(cd_TRIFR_12m,MATCH(MIN(EOMONTH(DATE(cfg_Year,9,1),0),cfg_LastDataDate),cd_Date,0)),"")) | M12: =IF(DATE(cfg_Year,10,1)>cfg_LastDataDate,"",IFERROR(INDEX(cd_TRIFR_12m,MATCH(MIN(EOMONTH(DATE(cfg_Year,10,1),0),cfg_LastDataDate),cd_Date,0)),"")) | N12: =IF(DATE(cfg_Year,11,1)>cfg_LastDataDate,"",IFERROR(INDEX(cd_TRIFR_12m,MATCH(MIN(EOMONTH(DATE(cfg_Year,11,1),0),cfg_LastDataDate),cd_Date,0)),"")) | O12: =IF(DATE(cfg_Year,12,1)>cfg_LastDataDate,"",IFERROR(INDEX(cd_TRIFR_12m,MATCH(MIN(EOMONTH(DATE(cfg_Year,12,1),0),cfg_LastDataDate),cd_Date,0)),"")) | P12: =IFERROR(INDEX(cd_TRIFR_12m,MATCH(MIN(cfg_YearEnd,cfg_LastDataDate),cd_Date,0)),"")
B13: Ore mined (ex-pit) | C13: Actual | D13: =IF(DATE(cfg_Year,1,1)>cfg_LastDataDate,"",IFERROR(INDEX(cd_Ore_Mined_t_MTD,MATCH(MIN(EOMONTH(DATE(cfg_Year,1,1),0),cfg_LastDataDate),cd_Date,0)),"")) | E13: =IF(DATE(cfg_Year,2,1)>cfg_LastDataDate,"",IFERROR(INDEX(cd_Ore_Mined_t_MTD,MATCH(MIN(EOMONTH(DATE(cfg_Year,2,1),0),cfg_LastDataDate),cd_Date,0)),"")) | F13: =IF(DATE(cfg_Year,3,1)>cfg_LastDataDate,"",IFERROR(INDEX(cd_Ore_Mined_t_MTD,MATCH(MIN(EOMONTH(DATE(cfg_Year,3,1),0),cfg_LastDataDate),cd_Date,0)),"")) | G13: =IF(DATE(cfg_Year,4,1)>cfg_LastDataDate,"",IFERROR(INDEX(cd_Ore_Mined_t_MTD,MATCH(MIN(EOMONTH(DATE(cfg_Year,4,1),0),cfg_LastDataDate),cd_Date,0)),"")) | H13: =IF(DATE(cfg_Year,5,1)>cfg_LastDataDate,"",IFERROR(INDEX(cd_Ore_Mined_t_MTD,MATCH(MIN(EOMONTH(DATE(cfg_Year,5,1),0),cfg_LastDataDate),cd_Date,0)),"")) | I13: =IF(DATE(cfg_Year,6,1)>cfg_LastDataDate,"",IFERROR(INDEX(cd_Ore_Mined_t_MTD,MATCH(MIN(EOMONTH(DATE(cfg_Year,6,1),0),cfg_LastDataDate),cd_Date,0)),"")) | J13: =IF(DATE(cfg_Year,7,1)>cfg_LastDataDate,"",IFERROR(INDEX(cd_Ore_Mined_t_MTD,MATCH(MIN(EOMONTH(DATE(cfg_Year,7,1),0),cfg_LastDataDate),cd_Date,0)),"")) | K13: =IF(DATE(cfg_Year,8,1)>cfg_LastDataDate,"",IFERROR(INDEX(cd_Ore_Mined_t_MTD,MATCH(MIN(EOMONTH(DATE(cfg_Year,8,1),0),cfg_LastDataDate),cd_Date,0)),"")) | L13: =IF(DATE(cfg_Year,9,1)>cfg_LastDataDate,"",IFERROR(INDEX(cd_Ore_Mined_t_MTD,MATCH(MIN(EOMONTH(DATE(cfg_Year,9,1),0),cfg_LastDataDate),cd_Date,0)),"")) | M13: =IF(DATE(cfg_Year,10,1)>cfg_LastDataDate,"",IFERROR(INDEX(cd_Ore_Mined_t_MTD,MATCH(MIN(EOMONTH(DATE(cfg_Year,10,1),0),cfg_LastDataDate),cd_Date,0)),"")) | N13: =IF(DATE(cfg_Year,11,1)>cfg_LastDataDate,"",IFERROR(INDEX(cd_Ore_Mined_t_MTD,MATCH(MIN(EOMONTH(DATE(cfg_Year,11,1),0),cfg_LastDataDate),cd_Date,0)),"")) | O13: =IF(DATE(cfg_Year,12,1)>cfg_LastDataDate,"",IFERROR(INDEX(cd_Ore_Mined_t_MTD,MATCH(MIN(EOMONTH(DATE(cfg_Year,12,1),0),cfg_LastDataDate),cd_Date,0)),"")) | P13: =IFERROR(INDEX(cd_Ore_Mined_t_YTD,MATCH(MIN(cfg_YearEnd,cfg_LastDataDate),cd_Date,0)),"")
C14: Budget | D14: =IF(DATE(cfg_Year,1,1)>cfg_LastDataDate,IFERROR(INDEX(cd_Bud_Ore_Mined_t_Month,MATCH(DATE(cfg_Year,1,1),cd_Date,0)),""),IFERROR(INDEX(cd_Bud_Ore_Mined_t_MTD,MATCH(MIN(EOMONTH(DATE(cfg_Year,1,1),0),cfg_LastDataDate),cd_Date,0)),"")) | E14: =IF(DATE(cfg_Year,2,1)>cfg_LastDataDate,IFERROR(INDEX(cd_Bud_Ore_Mined_t_Month,MATCH(DATE(cfg_Year,2,1),cd_Date,0)),""),IFERROR(INDEX(cd_Bud_Ore_Mined_t_MTD,MATCH(MIN(EOMONTH(DATE(cfg_Year,2,1),0),cfg_LastDataDate),cd_Date,0)),"")) | F14: =IF(DATE(cfg_Year,3,1)>cfg_LastDataDate,IFERROR(INDEX(cd_Bud_Ore_Mined_t_Month,MATCH(DATE(cfg_Year,3,1),cd_Date,0)),""),IFERROR(INDEX(cd_Bud_Ore_Mined_t_MTD,MATCH(MIN(EOMONTH(DATE(cfg_Year,3,1),0),cfg_LastDataDate),cd_Date,0)),"")) | G14: =IF(DATE(cfg_Year,4,1)>cfg_LastDataDate,IFERROR(INDEX(cd_Bud_Ore_Mined_t_Month,MATCH(DATE(cfg_Year,4,1),cd_Date,0)),""),IFERROR(INDEX(cd_Bud_Ore_Mined_t_MTD,MATCH(MIN(EOMONTH(DATE(cfg_Year,4,1),0),cfg_LastDataDate),cd_Date,0)),"")) | H14: =IF(DATE(cfg_Year,5,1)>cfg_LastDataDate,IFERROR(INDEX(cd_Bud_Ore_Mined_t_Month,MATCH(DATE(cfg_Year,5,1),cd_Date,0)),""),IFERROR(INDEX(cd_Bud_Ore_Mined_t_MTD,MATCH(MIN(EOMONTH(DATE(cfg_Year,5,1),0),cfg_LastDataDate),cd_Date,0)),"")) | I14: =IF(DATE(cfg_Year,6,1)>cfg_LastDataDate,IFERROR(INDEX(cd_Bud_Ore_Mined_t_Month,MATCH(DATE(cfg_Year,6,1),cd_Date,0)),""),IFERROR(INDEX(cd_Bud_Ore_Mined_t_MTD,MATCH(MIN(EOMONTH(DATE(cfg_Year,6,1),0),cfg_LastDataDate),cd_Date,0)),"")) | J14: =IF(DATE(cfg_Year,7,1)>cfg_LastDataDate,IFERROR(INDEX(cd_Bud_Ore_Mined_t_Month,MATCH(DATE(cfg_Year,7,1),cd_Date,0)),""),IFERROR(INDEX(cd_Bud_Ore_Mined_t_MTD,MATCH(MIN(EOMONTH(DATE(cfg_Year,7,1),0),cfg_LastDataDate),cd_Date,0)),"")) | K14: =IF(DATE(cfg_Year,8,1)>cfg_LastDataDate,IFERROR(INDEX(cd_Bud_Ore_Mined_t_Month,MATCH(DATE(cfg_Year,8,1),cd_Date,0)),""),IFERROR(INDEX(cd_Bud_Ore_Mined_t_MTD,MATCH(MIN(EOMONTH(DATE(cfg_Year,8,1),0),cfg_LastDataDate),cd_Date,0)),"")) | L14: =IF(DATE(cfg_Year,9,1)>cfg_LastDataDate,IFERROR(INDEX(cd_Bud_Ore_Mined_t_Month,MATCH(DATE(cfg_Year,9,1),cd_Date,0)),""),IFERROR(INDEX(cd_Bud_Ore_Mined_t_MTD,MATCH(MIN(EOMONTH(DATE(cfg_Year,9,1),0),cfg_LastDataDate),cd_Date,0)),"")) | M14: =IF(DATE(cfg_Year,10,1)>cfg_LastDataDate,IFERROR(INDEX(cd_Bud_Ore_Mined_t_Month,MATCH(DATE(cfg_Year,10,1),cd_Date,0)),""),IFERROR(INDEX(cd_Bud_Ore_Mined_t_MTD,MATCH(MIN(EOMONTH(DATE(cfg_Year,10,1),0),cfg_LastDataDate),cd_Date,0)),"")) | N14: =IF(DATE(cfg_Year,11,1)>cfg_LastDataDate,IFERROR(INDEX(cd_Bud_Ore_Mined_t_Month,MATCH(DATE(cfg_Year,11,1),cd_Date,0)),""),IFERROR(INDEX(cd_Bud_Ore_Mined_t_MTD,MATCH(MIN(EOMONTH(DATE(cfg_Year,11,1),0),cfg_LastDataDate),cd_Date,0)),"")) | O14: =IF(DATE(cfg_Year,12,1)>cfg_LastDataDate,IFERROR(INDEX(cd_Bud_Ore_Mined_t_Month,MATCH(DATE(cfg_Year,12,1),cd_Date,0)),""),IFERROR(INDEX(cd_Bud_Ore_Mined_t_MTD,MATCH(MIN(EOMONTH(DATE(cfg_Year,12,1),0),cfg_LastDataDate),cd_Date,0)),"")) | P14: =IFERROR(INDEX(cd_Bud_Ore_Mined_t_YTD,MATCH(IF(N(cfg_LastDataDate)>0,MIN(cfg_YearEnd,cfg_LastDataDate),cfg_YearEnd),cd_Date,0)),"")
C15: Variance | D15: =IF(AND(ISNUMBER(D13),ISNUMBER(D14),D14<>0),D13/D14-1,"") | E15: =IF(AND(ISNUMBER(E13),ISNUMBER(E14),E14<>0),E13/E14-1,"") | F15: =IF(AND(ISNUMBER(F13),ISNUMBER(F14),F14<>0),F13/F14-1,"") | G15: =IF(AND(ISNUMBER(G13),ISNUMBER(G14),G14<>0),G13/G14-1,"") | H15: =IF(AND(ISNUMBER(H13),ISNUMBER(H14),H14<>0),H13/H14-1,"") | I15: =IF(AND(ISNUMBER(I13),ISNUMBER(I14),I14<>0),I13/I14-1,"") | J15: =IF(AND(ISNUMBER(J13),ISNUMBER(J14),J14<>0),J13/J14-1,"") | K15: =IF(AND(ISNUMBER(K13),ISNUMBER(K14),K14<>0),K13/K14-1,"") | ... P15: =IF(AND(ISNUMBER(P13),ISNUMBER(P14),P14<>0),P13/P14-1,"")
B17: Ore grade mined | C17: Actual | D17: =IF(DATE(cfg_Year,1,1)>cfg_LastDataDate,"",IFERROR(INDEX(cd_Ore_Grade_gpt_MTD,MATCH(MIN(EOMONTH(DATE(cfg_Year,1,1),0),cfg_LastDataDate),cd_Date,0)),"")) | E17: =IF(DATE(cfg_Year,2,1)>cfg_LastDataDate,"",IFERROR(INDEX(cd_Ore_Grade_gpt_MTD,MATCH(MIN(EOMONTH(DATE(cfg_Year,2,1),0),cfg_LastDataDate),cd_Date,0)),"")) | F17: =IF(DATE(cfg_Year,3,1)>cfg_LastDataDate,"",IFERROR(INDEX(cd_Ore_Grade_gpt_MTD,MATCH(MIN(EOMONTH(DATE(cfg_Year,3,1),0),cfg_LastDataDate),cd_Date,0)),"")) | G17: =IF(DATE(cfg_Year,4,1)>cfg_LastDataDate,"",IFERROR(INDEX(cd_Ore_Grade_gpt_MTD,MATCH(MIN(EOMONTH(DATE(cfg_Year,4,1),0),cfg_LastDataDate),cd_Date,0)),"")) | H17: =IF(DATE(cfg_Year,5,1)>cfg_LastDataDate,"",IFERROR(INDEX(cd_Ore_Grade_gpt_MTD,MATCH(MIN(EOMONTH(DATE(cfg_Year,5,1),0),cfg_LastDataDate),cd_Date,0)),"")) | I17: =IF(DATE(cfg_Year,6,1)>cfg_LastDataDate,"",IFERROR(INDEX(cd_Ore_Grade_gpt_MTD,MATCH(MIN(EOMONTH(DATE(cfg_Year,6,1),0),cfg_LastDataDate),cd_Date,0)),"")) | J17: =IF(DATE(cfg_Year,7,1)>cfg_LastDataDate,"",IFERROR(INDEX(cd_Ore_Grade_gpt_MTD,MATCH(MIN(EOMONTH(DATE(cfg_Year,7,1),0),cfg_LastDataDate),cd_Date,0)),"")) | K17: =IF(DATE(cfg_Year,8,1)>cfg_LastDataDate,"",IFERROR(INDEX(cd_Ore_Grade_gpt_MTD,MATCH(MIN(EOMONTH(DATE(cfg_Year,8,1),0),cfg_LastDataDate),cd_Date,0)),"")) | L17: =IF(DATE(cfg_Year,9,1)>cfg_LastDataDate,"",IFERROR(INDEX(cd_Ore_Grade_gpt_MTD,MATCH(MIN(EOMONTH(DATE(cfg_Year,9,1),0),cfg_LastDataDate),cd_Date,0)),"")) | M17: =IF(DATE(cfg_Year,10,1)>cfg_LastDataDate,"",IFERROR(INDEX(cd_Ore_Grade_gpt_MTD,MATCH(MIN(EOMONTH(DATE(cfg_Year,10,1),0),cfg_LastDataDate),cd_Date,0)),"")) | N17: =IF(DATE(cfg_Year,11,1)>cfg_LastDataDate,"",IFERROR(INDEX(cd_Ore_Grade_gpt_MTD,MATCH(MIN(EOMONTH(DATE(cfg_Year,11,1),0),cfg_LastDataDate),cd_Date,0)),"")) | O17: =IF(DATE(cfg_Year,12,1)>cfg_LastDataDate,"",IFERROR(INDEX(cd_Ore_Grade_gpt_MTD,MATCH(MIN(EOMONTH(DATE(cfg_Year,12,1),0),cfg_LastDataDate),cd_Date,0)),"")) | P17: =IFERROR(INDEX(cd_Ore_Grade_gpt_YTD,MATCH(MIN(cfg_YearEnd,cfg_LastDataDate),cd_Date,0)),"")
C18: Budget | D18: =IF(DATE(cfg_Year,1,1)>cfg_LastDataDate,IFERROR(INDEX(cd_Bud_Ore_Grade_gpt_Month,MATCH(DATE(cfg_Year,1,1),cd_Date,0)),""),IFERROR(INDEX(cd_Bud_Ore_Grade_gpt_MTD,MATCH(MIN(EOMONTH(DATE(cfg_Year,1,1),0),cfg_LastDataDate),cd_Date,0)),"")) | E18: =IF(DATE(cfg_Year,2,1)>cfg_LastDataDate,IFERROR(INDEX(cd_Bud_Ore_Grade_gpt_Month,MATCH(DATE(cfg_Year,2,1),cd_Date,0)),""),IFERROR(INDEX(cd_Bud_Ore_Grade_gpt_MTD,MATCH(MIN(EOMONTH(DATE(cfg_Year,2,1),0),cfg_LastDataDate),cd_Date,0)),"")) | F18: =IF(DATE(cfg_Year,3,1)>cfg_LastDataDate,IFERROR(INDEX(cd_Bud_Ore_Grade_gpt_Month,MATCH(DATE(cfg_Year,3,1),cd_Date,0)),""),IFERROR(INDEX(cd_Bud_Ore_Grade_gpt_MTD,MATCH(MIN(EOMONTH(DATE(cfg_Year,3,1),0),cfg_LastDataDate),cd_Date,0)),"")) | G18: =IF(DATE(cfg_Year,4,1)>cfg_LastDataDate,IFERROR(INDEX(cd_Bud_Ore_Grade_gpt_Month,MATCH(DATE(cfg_Year,4,1),cd_Date,0)),""),IFERROR(INDEX(cd_Bud_Ore_Grade_gpt_MTD,MATCH(MIN(EOMONTH(DATE(cfg_Year,4,1),0),cfg_LastDataDate),cd_Date,0)),"")) | H18: =IF(DATE(cfg_Year,5,1)>cfg_LastDataDate,IFERROR(INDEX(cd_Bud_Ore_Grade_gpt_Month,MATCH(DATE(cfg_Year,5,1),cd_Date,0)),""),IFERROR(INDEX(cd_Bud_Ore_Grade_gpt_MTD,MATCH(MIN(EOMONTH(DATE(cfg_Year,5,1),0),cfg_LastDataDate),cd_Date,0)),"")) | I18: =IF(DATE(cfg_Year,6,1)>cfg_LastDataDate,IFERROR(INDEX(cd_Bud_Ore_Grade_gpt_Month,MATCH(DATE(cfg_Year,6,1),cd_Date,0)),""),IFERROR(INDEX(cd_Bud_Ore_Grade_gpt_MTD,MATCH(MIN(EOMONTH(DATE(cfg_Year,6,1),0),cfg_LastDataDate),cd_Date,0)),"")) | J18: =IF(DATE(cfg_Year,7,1)>cfg_LastDataDate,IFERROR(INDEX(cd_Bud_Ore_Grade_gpt_Month,MATCH(DATE(cfg_Year,7,1),cd_Date,0)),""),IFERROR(INDEX(cd_Bud_Ore_Grade_gpt_MTD,MATCH(MIN(EOMONTH(DATE(cfg_Year,7,1),0),cfg_LastDataDate),cd_Date,0)),"")) | K18: =IF(DATE(cfg_Year,8,1)>cfg_LastDataDate,IFERROR(INDEX(cd_Bud_Ore_Grade_gpt_Month,MATCH(DATE(cfg_Year,8,1),cd_Date,0)),""),IFERROR(INDEX(cd_Bud_Ore_Grade_gpt_MTD,MATCH(MIN(EOMONTH(DATE(cfg_Year,8,1),0),cfg_LastDataDate),cd_Date,0)),"")) | L18: =IF(DATE(cfg_Year,9,1)>cfg_LastDataDate,IFERROR(INDEX(cd_Bud_Ore_Grade_gpt_Month,MATCH(DATE(cfg_Year,9,1),cd_Date,0)),""),IFERROR(INDEX(cd_Bud_Ore_Grade_gpt_MTD,MATCH(MIN(EOMONTH(DATE(cfg_Year,9,1),0),cfg_LastDataDate),cd_Date,0)),"")) | M18: =IF(DATE(cfg_Year,10,1)>cfg_LastDataDate,IFERROR(INDEX(cd_Bud_Ore_Grade_gpt_Month,MATCH(DATE(cfg_Year,10,1),cd_Date,0)),""),IFERROR(INDEX(cd_Bud_Ore_Grade_gpt_MTD,MATCH(MIN(EOMONTH(DATE(cfg_Year,10,1),0),cfg_LastDataDate),cd_Date,0)),"")) | N18: =IF(DATE(cfg_Year,11,1)>cfg_LastDataDate,IFERROR(INDEX(cd_Bud_Ore_Grade_gpt_Month,MATCH(DATE(cfg_Year,11,1),cd_Date,0)),""),IFERROR(INDEX(cd_Bud_Ore_Grade_gpt_MTD,MATCH(MIN(EOMONTH(DATE(cfg_Year,11,1),0),cfg_LastDataDate),cd_Date,0)),"")) | O18: =IF(DATE(cfg_Year,12,1)>cfg_LastDataDate,IFERROR(INDEX(cd_Bud_Ore_Grade_gpt_Month,MATCH(DATE(cfg_Year,12,1),cd_Date,0)),""),IFERROR(INDEX(cd_Bud_Ore_Grade_gpt_MTD,MATCH(MIN(EOMONTH(DATE(cfg_Year,12,1),0),cfg_LastDataDate),cd_Date,0)),"")) | P18: =IFERROR(INDEX(cd_Bud_Ore_Grade_gpt_YTD,MATCH(IF(N(cfg_LastDataDate)>0,MIN(cfg_YearEnd,cfg_LastDataDate),cfg_YearEnd),cd_Date,0)),"")
C19: Variance | D19: =IF(AND(ISNUMBER(D17),ISNUMBER(D18),D18<>0),D17/D18-1,"") | E19: =IF(AND(ISNUMBER(E17),ISNUMBER(E18),E18<>0),E17/E18-1,"") | F19: =IF(AND(ISNUMBER(F17),ISNUMBER(F18),F18<>0),F17/F18-1,"") | G19: =IF(AND(ISNUMBER(G17),ISNUMBER(G18),G18<>0),G17/G18-1,"") | H19: =IF(AND(ISNUMBER(H17),ISNUMBER(H18),H18<>0),H17/H18-1,"") | I19: =IF(AND(ISNUMBER(I17),ISNUMBER(I18),I18<>0),I17/I18-1,"") | J19: =IF(AND(ISNUMBER(J17),ISNUMBER(J18),J18<>0),J17/J18-1,"") | K19: =IF(AND(ISNUMBER(K17),ISNUMBER(K18),K18<>0),K17/K18-1,"") | ... P19: =IF(AND(ISNUMBER(P17),ISNUMBER(P18),P18<>0),P17/P18-1,"")
B21: Contained gold mined | C21: Actual | D21: =IF(DATE(cfg_Year,1,1)>cfg_LastDataDate,"",IFERROR(INDEX(cd_Ore_Mined_oz_MTD,MATCH(MIN(EOMONTH(DATE(cfg_Year,1,1),0),cfg_LastDataDate),cd_Date,0)),"")) | E21: =IF(DATE(cfg_Year,2,1)>cfg_LastDataDate,"",IFERROR(INDEX(cd_Ore_Mined_oz_MTD,MATCH(MIN(EOMONTH(DATE(cfg_Year,2,1),0),cfg_LastDataDate),cd_Date,0)),"")) | F21: =IF(DATE(cfg_Year,3,1)>cfg_LastDataDate,"",IFERROR(INDEX(cd_Ore_Mined_oz_MTD,MATCH(MIN(EOMONTH(DATE(cfg_Year,3,1),0),cfg_LastDataDate),cd_Date,0)),"")) | G21: =IF(DATE(cfg_Year,4,1)>cfg_LastDataDate,"",IFERROR(INDEX(cd_Ore_Mined_oz_MTD,MATCH(MIN(EOMONTH(DATE(cfg_Year,4,1),0),cfg_LastDataDate),cd_Date,0)),"")) | H21: =IF(DATE(cfg_Year,5,1)>cfg_LastDataDate,"",IFERROR(INDEX(cd_Ore_Mined_oz_MTD,MATCH(MIN(EOMONTH(DATE(cfg_Year,5,1),0),cfg_LastDataDate),cd_Date,0)),"")) | I21: =IF(DATE(cfg_Year,6,1)>cfg_LastDataDate,"",IFERROR(INDEX(cd_Ore_Mined_oz_MTD,MATCH(MIN(EOMONTH(DATE(cfg_Year,6,1),0),cfg_LastDataDate),cd_Date,0)),"")) | J21: =IF(DATE(cfg_Year,7,1)>cfg_LastDataDate,"",IFERROR(INDEX(cd_Ore_Mined_oz_MTD,MATCH(MIN(EOMONTH(DATE(cfg_Year,7,1),0),cfg_LastDataDate),cd_Date,0)),"")) | K21: =IF(DATE(cfg_Year,8,1)>cfg_LastDataDate,"",IFERROR(INDEX(cd_Ore_Mined_oz_MTD,MATCH(MIN(EOMONTH(DATE(cfg_Year,8,1),0),cfg_LastDataDate),cd_Date,0)),"")) | L21: =IF(DATE(cfg_Year,9,1)>cfg_LastDataDate,"",IFERROR(INDEX(cd_Ore_Mined_oz_MTD,MATCH(MIN(EOMONTH(DATE(cfg_Year,9,1),0),cfg_LastDataDate),cd_Date,0)),"")) | M21: =IF(DATE(cfg_Year,10,1)>cfg_LastDataDate,"",IFERROR(INDEX(cd_Ore_Mined_oz_MTD,MATCH(MIN(EOMONTH(DATE(cfg_Year,10,1),0),cfg_LastDataDate),cd_Date,0)),"")) | N21: =IF(DATE(cfg_Year,11,1)>cfg_LastDataDate,"",IFERROR(INDEX(cd_Ore_Mined_oz_MTD,MATCH(MIN(EOMONTH(DATE(cfg_Year,11,1),0),cfg_LastDataDate),cd_Date,0)),"")) | O21: =IF(DATE(cfg_Year,12,1)>cfg_LastDataDate,"",IFERROR(INDEX(cd_Ore_Mined_oz_MTD,MATCH(MIN(EOMONTH(DATE(cfg_Year,12,1),0),cfg_LastDataDate),cd_Date,0)),"")) | P21: =IFERROR(INDEX(cd_Ore_Mined_oz_YTD,MATCH(MIN(cfg_YearEnd,cfg_LastDataDate),cd_Date,0)),"")
C22: Budget | D22: =IF(DATE(cfg_Year,1,1)>cfg_LastDataDate,IFERROR(INDEX(cd_Bud_Ore_Mined_oz_Month,MATCH(DATE(cfg_Year,1,1),cd_Date,0)),""),IFERROR(INDEX(cd_Bud_Ore_Mined_oz_MTD,MATCH(MIN(EOMONTH(DATE(cfg_Year,1,1),0),cfg_LastDataDate),cd_Date,0)),"")) | E22: =IF(DATE(cfg_Year,2,1)>cfg_LastDataDate,IFERROR(INDEX(cd_Bud_Ore_Mined_oz_Month,MATCH(DATE(cfg_Year,2,1),cd_Date,0)),""),IFERROR(INDEX(cd_Bud_Ore_Mined_oz_MTD,MATCH(MIN(EOMONTH(DATE(cfg_Year,2,1),0),cfg_LastDataDate),cd_Date,0)),"")) | F22: =IF(DATE(cfg_Year,3,1)>cfg_LastDataDate,IFERROR(INDEX(cd_Bud_Ore_Mined_oz_Month,MATCH(DATE(cfg_Year,3,1),cd_Date,0)),""),IFERROR(INDEX(cd_Bud_Ore_Mined_oz_MTD,MATCH(MIN(EOMONTH(DATE(cfg_Year,3,1),0),cfg_LastDataDate),cd_Date,0)),"")) | G22: =IF(DATE(cfg_Year,4,1)>cfg_LastDataDate,IFERROR(INDEX(cd_Bud_Ore_Mined_oz_Month,MATCH(DATE(cfg_Year,4,1),cd_Date,0)),""),IFERROR(INDEX(cd_Bud_Ore_Mined_oz_MTD,MATCH(MIN(EOMONTH(DATE(cfg_Year,4,1),0),cfg_LastDataDate),cd_Date,0)),"")) | H22: =IF(DATE(cfg_Year,5,1)>cfg_LastDataDate,IFERROR(INDEX(cd_Bud_Ore_Mined_oz_Month,MATCH(DATE(cfg_Year,5,1),cd_Date,0)),""),IFERROR(INDEX(cd_Bud_Ore_Mined_oz_MTD,MATCH(MIN(EOMONTH(DATE(cfg_Year,5,1),0),cfg_LastDataDate),cd_Date,0)),"")) | I22: =IF(DATE(cfg_Year,6,1)>cfg_LastDataDate,IFERROR(INDEX(cd_Bud_Ore_Mined_oz_Month,MATCH(DATE(cfg_Year,6,1),cd_Date,0)),""),IFERROR(INDEX(cd_Bud_Ore_Mined_oz_MTD,MATCH(MIN(EOMONTH(DATE(cfg_Year,6,1),0),cfg_LastDataDate),cd_Date,0)),"")) | J22: =IF(DATE(cfg_Year,7,1)>cfg_LastDataDate,IFERROR(INDEX(cd_Bud_Ore_Mined_oz_Month,MATCH(DATE(cfg_Year,7,1),cd_Date,0)),""),IFERROR(INDEX(cd_Bud_Ore_Mined_oz_MTD,MATCH(MIN(EOMONTH(DATE(cfg_Year,7,1),0),cfg_LastDataDate),cd_Date,0)),"")) | K22: =IF(DATE(cfg_Year,8,1)>cfg_LastDataDate,IFERROR(INDEX(cd_Bud_Ore_Mined_oz_Month,MATCH(DATE(cfg_Year,8,1),cd_Date,0)),""),IFERROR(INDEX(cd_Bud_Ore_Mined_oz_MTD,MATCH(MIN(EOMONTH(DATE(cfg_Year,8,1),0),cfg_LastDataDate),cd_Date,0)),"")) | L22: =IF(DATE(cfg_Year,9,1)>cfg_LastDataDate,IFERROR(INDEX(cd_Bud_Ore_Mined_oz_Month,MATCH(DATE(cfg_Year,9,1),cd_Date,0)),""),IFERROR(INDEX(cd_Bud_Ore_Mined_oz_MTD,MATCH(MIN(EOMONTH(DATE(cfg_Year,9,1),0),cfg_LastDataDate),cd_Date,0)),"")) | M22: =IF(DATE(cfg_Year,10,1)>cfg_LastDataDate,IFERROR(INDEX(cd_Bud_Ore_Mined_oz_Month,MATCH(DATE(cfg_Year,10,1),cd_Date,0)),""),IFERROR(INDEX(cd_Bud_Ore_Mined_oz_MTD,MATCH(MIN(EOMONTH(DATE(cfg_Year,10,1),0),cfg_LastDataDate),cd_Date,0)),"")) | N22: =IF(DATE(cfg_Year,11,1)>cfg_LastDataDate,IFERROR(INDEX(cd_Bud_Ore_Mined_oz_Month,MATCH(DATE(cfg_Year,11,1),cd_Date,0)),""),IFERROR(INDEX(cd_Bud_Ore_Mined_oz_MTD,MATCH(MIN(EOMONTH(DATE(cfg_Year,11,1),0),cfg_LastDataDate),cd_Date,0)),"")) | O22: =IF(DATE(cfg_Year,12,1)>cfg_LastDataDate,IFERROR(INDEX(cd_Bud_Ore_Mined_oz_Month,MATCH(DATE(cfg_Year,12,1),cd_Date,0)),""),IFERROR(INDEX(cd_Bud_Ore_Mined_oz_MTD,MATCH(MIN(EOMONTH(DATE(cfg_Year,12,1),0),cfg_LastDataDate),cd_Date,0)),"")) | P22: =IFERROR(INDEX(cd_Bud_Ore_Mined_oz_YTD,MATCH(IF(N(cfg_LastDataDate)>0,MIN(cfg_YearEnd,cfg_LastDataDate),cfg_YearEnd),cd_Date,0)),"")
C23: Variance | D23: =IF(AND(ISNUMBER(D21),ISNUMBER(D22),D22<>0),D21/D22-1,"") | E23: =IF(AND(ISNUMBER(E21),ISNUMBER(E22),E22<>0),E21/E22-1,"") | F23: =IF(AND(ISNUMBER(F21),ISNUMBER(F22),F22<>0),F21/F22-1,"") | G23: =IF(AND(ISNUMBER(G21),ISNUMBER(G22),G22<>0),G21/G22-1,"") | H23: =IF(AND(ISNUMBER(H21),ISNUMBER(H22),H22<>0),H21/H22-1,"") | I23: =IF(AND(ISNUMBER(I21),ISNUMBER(I22),I22<>0),I21/I22-1,"") | J23: =IF(AND(ISNUMBER(J21),ISNUMBER(J22),J22<>0),J21/J22-1,"") | K23: =IF(AND(ISNUMBER(K21),ISNUMBER(K22),K22<>0),K21/K22-1,"") | ... P23: =IF(AND(ISNUMBER(P21),ISNUMBER(P22),P22<>0),P21/P22-1,"")
B25: Waste mined | C25: Actual | D25: =IF(DATE(cfg_Year,1,1)>cfg_LastDataDate,"",IFERROR(INDEX(cd_Waste_t_MTD,MATCH(MIN(EOMONTH(DATE(cfg_Year,1,1),0),cfg_LastDataDate),cd_Date,0)),"")) | E25: =IF(DATE(cfg_Year,2,1)>cfg_LastDataDate,"",IFERROR(INDEX(cd_Waste_t_MTD,MATCH(MIN(EOMONTH(DATE(cfg_Year,2,1),0),cfg_LastDataDate),cd_Date,0)),"")) | F25: =IF(DATE(cfg_Year,3,1)>cfg_LastDataDate,"",IFERROR(INDEX(cd_Waste_t_MTD,MATCH(MIN(EOMONTH(DATE(cfg_Year,3,1),0),cfg_LastDataDate),cd_Date,0)),"")) | G25: =IF(DATE(cfg_Year,4,1)>cfg_LastDataDate,"",IFERROR(INDEX(cd_Waste_t_MTD,MATCH(MIN(EOMONTH(DATE(cfg_Year,4,1),0),cfg_LastDataDate),cd_Date,0)),"")) | H25: =IF(DATE(cfg_Year,5,1)>cfg_LastDataDate,"",IFERROR(INDEX(cd_Waste_t_MTD,MATCH(MIN(EOMONTH(DATE(cfg_Year,5,1),0),cfg_LastDataDate),cd_Date,0)),"")) | I25: =IF(DATE(cfg_Year,6,1)>cfg_LastDataDate,"",IFERROR(INDEX(cd_Waste_t_MTD,MATCH(MIN(EOMONTH(DATE(cfg_Year,6,1),0),cfg_LastDataDate),cd_Date,0)),"")) | J25: =IF(DATE(cfg_Year,7,1)>cfg_LastDataDate,"",IFERROR(INDEX(cd_Waste_t_MTD,MATCH(MIN(EOMONTH(DATE(cfg_Year,7,1),0),cfg_LastDataDate),cd_Date,0)),"")) | K25: =IF(DATE(cfg_Year,8,1)>cfg_LastDataDate,"",IFERROR(INDEX(cd_Waste_t_MTD,MATCH(MIN(EOMONTH(DATE(cfg_Year,8,1),0),cfg_LastDataDate),cd_Date,0)),"")) | L25: =IF(DATE(cfg_Year,9,1)>cfg_LastDataDate,"",IFERROR(INDEX(cd_Waste_t_MTD,MATCH(MIN(EOMONTH(DATE(cfg_Year,9,1),0),cfg_LastDataDate),cd_Date,0)),"")) | M25: =IF(DATE(cfg_Year,10,1)>cfg_LastDataDate,"",IFERROR(INDEX(cd_Waste_t_MTD,MATCH(MIN(EOMONTH(DATE(cfg_Year,10,1),0),cfg_LastDataDate),cd_Date,0)),"")) | N25: =IF(DATE(cfg_Year,11,1)>cfg_LastDataDate,"",IFERROR(INDEX(cd_Waste_t_MTD,MATCH(MIN(EOMONTH(DATE(cfg_Year,11,1),0),cfg_LastDataDate),cd_Date,0)),"")) | O25: =IF(DATE(cfg_Year,12,1)>cfg_LastDataDate,"",IFERROR(INDEX(cd_Waste_t_MTD,MATCH(MIN(EOMONTH(DATE(cfg_Year,12,1),0),cfg_LastDataDate),cd_Date,0)),"")) | P25: =IFERROR(INDEX(cd_Waste_t_YTD,MATCH(MIN(cfg_YearEnd,cfg_LastDataDate),cd_Date,0)),"")
C26: Budget | D26: =IF(DATE(cfg_Year,1,1)>cfg_LastDataDate,IFERROR(INDEX(cd_Bud_Waste_t_Month,MATCH(DATE(cfg_Year,1,1),cd_Date,0)),""),IFERROR(INDEX(cd_Bud_Waste_t_MTD,MATCH(MIN(EOMONTH(DATE(cfg_Year,1,1),0),cfg_LastDataDate),cd_Date,0)),"")) | E26: =IF(DATE(cfg_Year,2,1)>cfg_LastDataDate,IFERROR(INDEX(cd_Bud_Waste_t_Month,MATCH(DATE(cfg_Year,2,1),cd_Date,0)),""),IFERROR(INDEX(cd_Bud_Waste_t_MTD,MATCH(MIN(EOMONTH(DATE(cfg_Year,2,1),0),cfg_LastDataDate),cd_Date,0)),"")) | F26: =IF(DATE(cfg_Year,3,1)>cfg_LastDataDate,IFERROR(INDEX(cd_Bud_Waste_t_Month,MATCH(DATE(cfg_Year,3,1),cd_Date,0)),""),IFERROR(INDEX(cd_Bud_Waste_t_MTD,MATCH(MIN(EOMONTH(DATE(cfg_Year,3,1),0),cfg_LastDataDate),cd_Date,0)),"")) | G26: =IF(DATE(cfg_Year,4,1)>cfg_LastDataDate,IFERROR(INDEX(cd_Bud_Waste_t_Month,MATCH(DATE(cfg_Year,4,1),cd_Date,0)),""),IFERROR(INDEX(cd_Bud_Waste_t_MTD,MATCH(MIN(EOMONTH(DATE(cfg_Year,4,1),0),cfg_LastDataDate),cd_Date,0)),"")) | H26: =IF(DATE(cfg_Year,5,1)>cfg_LastDataDate,IFERROR(INDEX(cd_Bud_Waste_t_Month,MATCH(DATE(cfg_Year,5,1),cd_Date,0)),""),IFERROR(INDEX(cd_Bud_Waste_t_MTD,MATCH(MIN(EOMONTH(DATE(cfg_Year,5,1),0),cfg_LastDataDate),cd_Date,0)),"")) | I26: =IF(DATE(cfg_Year,6,1)>cfg_LastDataDate,IFERROR(INDEX(cd_Bud_Waste_t_Month,MATCH(DATE(cfg_Year,6,1),cd_Date,0)),""),IFERROR(INDEX(cd_Bud_Waste_t_MTD,MATCH(MIN(EOMONTH(DATE(cfg_Year,6,1),0),cfg_LastDataDate),cd_Date,0)),"")) | J26: =IF(DATE(cfg_Year,7,1)>cfg_LastDataDate,IFERROR(INDEX(cd_Bud_Waste_t_Month,MATCH(DATE(cfg_Year,7,1),cd_Date,0)),""),IFERROR(INDEX(cd_Bud_Waste_t_MTD,MATCH(MIN(EOMONTH(DATE(cfg_Year,7,1),0),cfg_LastDataDate),cd_Date,0)),"")) | K26: =IF(DATE(cfg_Year,8,1)>cfg_LastDataDate,IFERROR(INDEX(cd_Bud_Waste_t_Month,MATCH(DATE(cfg_Year,8,1),cd_Date,0)),""),IFERROR(INDEX(cd_Bud_Waste_t_MTD,MATCH(MIN(EOMONTH(DATE(cfg_Year,8,1),0),cfg_LastDataDate),cd_Date,0)),"")) | L26: =IF(DATE(cfg_Year,9,1)>cfg_LastDataDate,IFERROR(INDEX(cd_Bud_Waste_t_Month,MATCH(DATE(cfg_Year,9,1),cd_Date,0)),""),IFERROR(INDEX(cd_Bud_Waste_t_MTD,MATCH(MIN(EOMONTH(DATE(cfg_Year,9,1),0),cfg_LastDataDate),cd_Date,0)),"")) | M26: =IF(DATE(cfg_Year,10,1)>cfg_LastDataDate,IFERROR(INDEX(cd_Bud_Waste_t_Month,MATCH(DATE(cfg_Year,10,1),cd_Date,0)),""),IFERROR(INDEX(cd_Bud_Waste_t_MTD,MATCH(MIN(EOMONTH(DATE(cfg_Year,10,1),0),cfg_LastDataDate),cd_Date,0)),"")) | N26: =IF(DATE(cfg_Year,11,1)>cfg_LastDataDate,IFERROR(INDEX(cd_Bud_Waste_t_Month,MATCH(DATE(cfg_Year,11,1),cd_Date,0)),""),IFERROR(INDEX(cd_Bud_Waste_t_MTD,MATCH(MIN(EOMONTH(DATE(cfg_Year,11,1),0),cfg_LastDataDate),cd_Date,0)),"")) | O26: =IF(DATE(cfg_Year,12,1)>cfg_LastDataDate,IFERROR(INDEX(cd_Bud_Waste_t_Month,MATCH(DATE(cfg_Year,12,1),cd_Date,0)),""),IFERROR(INDEX(cd_Bud_Waste_t_MTD,MATCH(MIN(EOMONTH(DATE(cfg_Year,12,1),0),cfg_LastDataDate),cd_Date,0)),"")) | P26: =IFERROR(INDEX(cd_Bud_Waste_t_YTD,MATCH(IF(N(cfg_LastDataDate)>0,MIN(cfg_YearEnd,cfg_LastDataDate),cfg_YearEnd),cd_Date,0)),"")
C27: Variance | D27: =IF(AND(ISNUMBER(D25),ISNUMBER(D26),D26<>0),D25/D26-1,"") | E27: =IF(AND(ISNUMBER(E25),ISNUMBER(E26),E26<>0),E25/E26-1,"") | F27: =IF(AND(ISNUMBER(F25),ISNUMBER(F26),F26<>0),F25/F26-1,"") | G27: =IF(AND(ISNUMBER(G25),ISNUMBER(G26),G26<>0),G25/G26-1,"") | H27: =IF(AND(ISNUMBER(H25),ISNUMBER(H26),H26<>0),H25/H26-1,"") | I27: =IF(AND(ISNUMBER(I25),ISNUMBER(I26),I26<>0),I25/I26-1,"") | J27: =IF(AND(ISNUMBER(J25),ISNUMBER(J26),J26<>0),J25/J26-1,"") | K27: =IF(AND(ISNUMBER(K25),ISNUMBER(K26),K26<>0),K25/K26-1,"") | ... P27: =IF(AND(ISNUMBER(P25),ISNUMBER(P26),P26<>0),P25/P26-1,"")
B29: Total material moved | C29: Actual | D29: =IF(DATE(cfg_Year,1,1)>cfg_LastDataDate,"",IFERROR(INDEX(cd_TMM_t_MTD,MATCH(MIN(EOMONTH(DATE(cfg_Year,1,1),0),cfg_LastDataDate),cd_Date,0)),"")) | E29: =IF(DATE(cfg_Year,2,1)>cfg_LastDataDate,"",IFERROR(INDEX(cd_TMM_t_MTD,MATCH(MIN(EOMONTH(DATE(cfg_Year,2,1),0),cfg_LastDataDate),cd_Date,0)),"")) | F29: =IF(DATE(cfg_Year,3,1)>cfg_LastDataDate,"",IFERROR(INDEX(cd_TMM_t_MTD,MATCH(MIN(EOMONTH(DATE(cfg_Year,3,1),0),cfg_LastDataDate),cd_Date,0)),"")) | G29: =IF(DATE(cfg_Year,4,1)>cfg_LastDataDate,"",IFERROR(INDEX(cd_TMM_t_MTD,MATCH(MIN(EOMONTH(DATE(cfg_Year,4,1),0),cfg_LastDataDate),cd_Date,0)),"")) | H29: =IF(DATE(cfg_Year,5,1)>cfg_LastDataDate,"",IFERROR(INDEX(cd_TMM_t_MTD,MATCH(MIN(EOMONTH(DATE(cfg_Year,5,1),0),cfg_LastDataDate),cd_Date,0)),"")) | I29: =IF(DATE(cfg_Year,6,1)>cfg_LastDataDate,"",IFERROR(INDEX(cd_TMM_t_MTD,MATCH(MIN(EOMONTH(DATE(cfg_Year,6,1),0),cfg_LastDataDate),cd_Date,0)),"")) | J29: =IF(DATE(cfg_Year,7,1)>cfg_LastDataDate,"",IFERROR(INDEX(cd_TMM_t_MTD,MATCH(MIN(EOMONTH(DATE(cfg_Year,7,1),0),cfg_LastDataDate),cd_Date,0)),"")) | K29: =IF(DATE(cfg_Year,8,1)>cfg_LastDataDate,"",IFERROR(INDEX(cd_TMM_t_MTD,MATCH(MIN(EOMONTH(DATE(cfg_Year,8,1),0),cfg_LastDataDate),cd_Date,0)),"")) | L29: =IF(DATE(cfg_Year,9,1)>cfg_LastDataDate,"",IFERROR(INDEX(cd_TMM_t_MTD,MATCH(MIN(EOMONTH(DATE(cfg_Year,9,1),0),cfg_LastDataDate),cd_Date,0)),"")) | M29: =IF(DATE(cfg_Year,10,1)>cfg_LastDataDate,"",IFERROR(INDEX(cd_TMM_t_MTD,MATCH(MIN(EOMONTH(DATE(cfg_Year,10,1),0),cfg_LastDataDate),cd_Date,0)),"")) | N29: =IF(DATE(cfg_Year,11,1)>cfg_LastDataDate,"",IFERROR(INDEX(cd_TMM_t_MTD,MATCH(MIN(EOMONTH(DATE(cfg_Year,11,1),0),cfg_LastDataDate),cd_Date,0)),"")) | O29: =IF(DATE(cfg_Year,12,1)>cfg_LastDataDate,"",IFERROR(INDEX(cd_TMM_t_MTD,MATCH(MIN(EOMONTH(DATE(cfg_Year,12,1),0),cfg_LastDataDate),cd_Date,0)),"")) | P29: =IFERROR(INDEX(cd_TMM_t_YTD,MATCH(MIN(cfg_YearEnd,cfg_LastDataDate),cd_Date,0)),"")
C30: Budget | D30: =IF(DATE(cfg_Year,1,1)>cfg_LastDataDate,IFERROR(INDEX(cd_Bud_TMM_t_Month,MATCH(DATE(cfg_Year,1,1),cd_Date,0)),""),IFERROR(INDEX(cd_Bud_TMM_t_MTD,MATCH(MIN(EOMONTH(DATE(cfg_Year,1,1),0),cfg_LastDataDate),cd_Date,0)),"")) | E30: =IF(DATE(cfg_Year,2,1)>cfg_LastDataDate,IFERROR(INDEX(cd_Bud_TMM_t_Month,MATCH(DATE(cfg_Year,2,1),cd_Date,0)),""),IFERROR(INDEX(cd_Bud_TMM_t_MTD,MATCH(MIN(EOMONTH(DATE(cfg_Year,2,1),0),cfg_LastDataDate),cd_Date,0)),"")) | F30: =IF(DATE(cfg_Year,3,1)>cfg_LastDataDate,IFERROR(INDEX(cd_Bud_TMM_t_Month,MATCH(DATE(cfg_Year,3,1),cd_Date,0)),""),IFERROR(INDEX(cd_Bud_TMM_t_MTD,MATCH(MIN(EOMONTH(DATE(cfg_Year,3,1),0),cfg_LastDataDate),cd_Date,0)),"")) | G30: =IF(DATE(cfg_Year,4,1)>cfg_LastDataDate,IFERROR(INDEX(cd_Bud_TMM_t_Month,MATCH(DATE(cfg_Year,4,1),cd_Date,0)),""),IFERROR(INDEX(cd_Bud_TMM_t_MTD,MATCH(MIN(EOMONTH(DATE(cfg_Year,4,1),0),cfg_LastDataDate),cd_Date,0)),"")) | H30: =IF(DATE(cfg_Year,5,1)>cfg_LastDataDate,IFERROR(INDEX(cd_Bud_TMM_t_Month,MATCH(DATE(cfg_Year,5,1),cd_Date,0)),""),IFERROR(INDEX(cd_Bud_TMM_t_MTD,MATCH(MIN(EOMONTH(DATE(cfg_Year,5,1),0),cfg_LastDataDate),cd_Date,0)),"")) | I30: =IF(DATE(cfg_Year,6,1)>cfg_LastDataDate,IFERROR(INDEX(cd_Bud_TMM_t_Month,MATCH(DATE(cfg_Year,6,1),cd_Date,0)),""),IFERROR(INDEX(cd_Bud_TMM_t_MTD,MATCH(MIN(EOMONTH(DATE(cfg_Year,6,1),0),cfg_LastDataDate),cd_Date,0)),"")) | J30: =IF(DATE(cfg_Year,7,1)>cfg_LastDataDate,IFERROR(INDEX(cd_Bud_TMM_t_Month,MATCH(DATE(cfg_Year,7,1),cd_Date,0)),""),IFERROR(INDEX(cd_Bud_TMM_t_MTD,MATCH(MIN(EOMONTH(DATE(cfg_Year,7,1),0),cfg_LastDataDate),cd_Date,0)),"")) | K30: =IF(DATE(cfg_Year,8,1)>cfg_LastDataDate,IFERROR(INDEX(cd_Bud_TMM_t_Month,MATCH(DATE(cfg_Year,8,1),cd_Date,0)),""),IFERROR(INDEX(cd_Bud_TMM_t_MTD,MATCH(MIN(EOMONTH(DATE(cfg_Year,8,1),0),cfg_LastDataDate),cd_Date,0)),"")) | L30: =IF(DATE(cfg_Year,9,1)>cfg_LastDataDate,IFERROR(INDEX(cd_Bud_TMM_t_Month,MATCH(DATE(cfg_Year,9,1),cd_Date,0)),""),IFERROR(INDEX(cd_Bud_TMM_t_MTD,MATCH(MIN(EOMONTH(DATE(cfg_Year,9,1),0),cfg_LastDataDate),cd_Date,0)),"")) | M30: =IF(DATE(cfg_Year,10,1)>cfg_LastDataDate,IFERROR(INDEX(cd_Bud_TMM_t_Month,MATCH(DATE(cfg_Year,10,1),cd_Date,0)),""),IFERROR(INDEX(cd_Bud_TMM_t_MTD,MATCH(MIN(EOMONTH(DATE(cfg_Year,10,1),0),cfg_LastDataDate),cd_Date,0)),"")) | N30: =IF(DATE(cfg_Year,11,1)>cfg_LastDataDate,IFERROR(INDEX(cd_Bud_TMM_t_Month,MATCH(DATE(cfg_Year,11,1),cd_Date,0)),""),IFERROR(INDEX(cd_Bud_TMM_t_MTD,MATCH(MIN(EOMONTH(DATE(cfg_Year,11,1),0),cfg_LastDataDate),cd_Date,0)),"")) | O30: =IF(DATE(cfg_Year,12,1)>cfg_LastDataDate,IFERROR(INDEX(cd_Bud_TMM_t_Month,MATCH(DATE(cfg_Year,12,1),cd_Date,0)),""),IFERROR(INDEX(cd_Bud_TMM_t_MTD,MATCH(MIN(EOMONTH(DATE(cfg_Year,12,1),0),cfg_LastDataDate),cd_Date,0)),"")) | P30: =IFERROR(INDEX(cd_Bud_TMM_t_YTD,MATCH(IF(N(cfg_LastDataDate)>0,MIN(cfg_YearEnd,cfg_LastDataDate),cfg_YearEnd),cd_Date,0)),"")
C31: Variance | D31: =IF(AND(ISNUMBER(D29),ISNUMBER(D30),D30<>0),D29/D30-1,"") | E31: =IF(AND(ISNUMBER(E29),ISNUMBER(E30),E30<>0),E29/E30-1,"") | F31: =IF(AND(ISNUMBER(F29),ISNUMBER(F30),F30<>0),F29/F30-1,"") | G31: =IF(AND(ISNUMBER(G29),ISNUMBER(G30),G30<>0),G29/G30-1,"") | H31: =IF(AND(ISNUMBER(H29),ISNUMBER(H30),H30<>0),H29/H30-1,"") | I31: =IF(AND(ISNUMBER(I29),ISNUMBER(I30),I30<>0),I29/I30-1,"") | J31: =IF(AND(ISNUMBER(J29),ISNUMBER(J30),J30<>0),J29/J30-1,"") | K31: =IF(AND(ISNUMBER(K29),ISNUMBER(K30),K30<>0),K29/K30-1,"") | ... P31: =IF(AND(ISNUMBER(P29),ISNUMBER(P30),P30<>0),P29/P30-1,"")
B33: Strip ratio (waste : ore) | C33: Actual | D33: =IF(DATE(cfg_Year,1,1)>cfg_LastDataDate,"",IFERROR(INDEX(cd_Strip_Ratio_MTD,MATCH(MIN(EOMONTH(DATE(cfg_Year,1,1),0),cfg_LastDataDate),cd_Date,0)),"")) | E33: =IF(DATE(cfg_Year,2,1)>cfg_LastDataDate,"",IFERROR(INDEX(cd_Strip_Ratio_MTD,MATCH(MIN(EOMONTH(DATE(cfg_Year,2,1),0),cfg_LastDataDate),cd_Date,0)),"")) | F33: =IF(DATE(cfg_Year,3,1)>cfg_LastDataDate,"",IFERROR(INDEX(cd_Strip_Ratio_MTD,MATCH(MIN(EOMONTH(DATE(cfg_Year,3,1),0),cfg_LastDataDate),cd_Date,0)),"")) | G33: =IF(DATE(cfg_Year,4,1)>cfg_LastDataDate,"",IFERROR(INDEX(cd_Strip_Ratio_MTD,MATCH(MIN(EOMONTH(DATE(cfg_Year,4,1),0),cfg_LastDataDate),cd_Date,0)),"")) | H33: =IF(DATE(cfg_Year,5,1)>cfg_LastDataDate,"",IFERROR(INDEX(cd_Strip_Ratio_MTD,MATCH(MIN(EOMONTH(DATE(cfg_Year,5,1),0),cfg_LastDataDate),cd_Date,0)),"")) | I33: =IF(DATE(cfg_Year,6,1)>cfg_LastDataDate,"",IFERROR(INDEX(cd_Strip_Ratio_MTD,MATCH(MIN(EOMONTH(DATE(cfg_Year,6,1),0),cfg_LastDataDate),cd_Date,0)),"")) | J33: =IF(DATE(cfg_Year,7,1)>cfg_LastDataDate,"",IFERROR(INDEX(cd_Strip_Ratio_MTD,MATCH(MIN(EOMONTH(DATE(cfg_Year,7,1),0),cfg_LastDataDate),cd_Date,0)),"")) | K33: =IF(DATE(cfg_Year,8,1)>cfg_LastDataDate,"",IFERROR(INDEX(cd_Strip_Ratio_MTD,MATCH(MIN(EOMONTH(DATE(cfg_Year,8,1),0),cfg_LastDataDate),cd_Date,0)),"")) | L33: =IF(DATE(cfg_Year,9,1)>cfg_LastDataDate,"",IFERROR(INDEX(cd_Strip_Ratio_MTD,MATCH(MIN(EOMONTH(DATE(cfg_Year,9,1),0),cfg_LastDataDate),cd_Date,0)),"")) | M33: =IF(DATE(cfg_Year,10,1)>cfg_LastDataDate,"",IFERROR(INDEX(cd_Strip_Ratio_MTD,MATCH(MIN(EOMONTH(DATE(cfg_Year,10,1),0),cfg_LastDataDate),cd_Date,0)),"")) | N33: =IF(DATE(cfg_Year,11,1)>cfg_LastDataDate,"",IFERROR(INDEX(cd_Strip_Ratio_MTD,MATCH(MIN(EOMONTH(DATE(cfg_Year,11,1),0),cfg_LastDataDate),cd_Date,0)),"")) | O33: =IF(DATE(cfg_Year,12,1)>cfg_LastDataDate,"",IFERROR(INDEX(cd_Strip_Ratio_MTD,MATCH(MIN(EOMONTH(DATE(cfg_Year,12,1),0),cfg_LastDataDate),cd_Date,0)),"")) | P33: =IFERROR(INDEX(cd_Strip_Ratio_YTD,MATCH(MIN(cfg_YearEnd,cfg_LastDataDate),cd_Date,0)),"")
