Workbook
Name lst_Shift: Lists!$A$6:INDEX(Lists!$A:$A,COUNTA(Lists!$A:$A))
Name lst_Material: Lists!$C$6:INDEX(Lists!$C:$C,COUNTA(Lists!$C:$C))
Name lst_Area: Lists!$E$6:INDEX(Lists!$E:$E,COUNTA(Lists!$E:$E))
Name lst_Equipment_Class: Lists!$G$6:INDEX(Lists!$G:$G,COUNTA(Lists!$G:$G))
Name lst_Gold_Movement_Type: Lists!$I$6:INDEX(Lists!$I:$I,COUNTA(Lists!$I:$I))
Name lst_Yes_No: Lists!$K$6:INDEX(Lists!$K:$K,COUNTA(Lists!$K:$K))
Name lst_Source_Type: Lists!$M$6:INDEX(Lists!$M:$M,COUNTA(Lists!$M:$M))
Name lst_Destination_Type: Lists!$O$6:INDEX(Lists!$O:$O,COUNTA(Lists!$O:$O))
Name lst_Source: Lists!$R$6:INDEX(Lists!$R:$R,COUNTA(Lists!$R:$R))
Name lst_Destination: Lists!$U$6:INDEX(Lists!$U:$U,COUNTA(Lists!$U:$U))
Name cfg_Site: Config!$B$5
Name cfg_Company: Config!$B$6
Name cfg_Year: Config!$B$7
Name cfg_YearStart: Config!$B$8
Name cfg_YearEnd: Config!$B$9
Name cfg_TroyOz: Config!$B$10
Name cfg_PriorLTIDate: Config!$B$11
Name cfg_LastDataDate: Config!$B$12
Name cfg_ReportTitle: Config!$B$13
Name cd_Date: Calc_Daily!$A$2:$A$366
Name cd_Month: Calc_Daily!$B$2:$B$366
Name cd_Day: Calc_Daily!$C$2:$C$366
Name cd_Days_In_Month: Calc_Daily!$D$2:$D$366
Name cd_Month_Start: Calc_Daily!$E$2:$E$366
Name cd_Ore_Mined_t: Calc_Daily!$F$2:$F$366
Name cd_Ore_Mined_t_MTD: Calc_Daily!$G$2:$G$366
Name cd_Ore_Mined_t_YTD: Calc_Daily!$H$2:$H$366
Name cd_Ore_Mined_oz: Calc_Daily!$I$2:$I$366
Name cd_Ore_Mined_oz_MTD: Calc_Daily!$J$2:$J$366
Name cd_Ore_Mined_oz_YTD: Calc_Daily!$K$2:$K$366
Name cd_Ore_Grade_gpt: Calc_Daily!$L$2:$L$366
Name cd_Ore_Grade_gpt_MTD: Calc_Daily!$M$2:$M$366
Name cd_Ore_Grade_gpt_YTD: Calc_Daily!$N$2:$N$366
Name cd_Waste_t: Calc_Daily!$O$2:$O$366
Name cd_Waste_t_MTD: Calc_Daily!$P$2:$P$366
Name cd_Waste_t_YTD: Calc_Daily!$Q$2:$Q$366
Name cd_TMM_t: Calc_Daily!$R$2:$R$366
Name cd_TMM_t_MTD: Calc_Daily!$S$2:$S$366
Name cd_TMM_t_YTD: Calc_Daily!$T$2:$T$366
Name cd_Strip_Ratio: Calc_Daily!$U$2:$U$366
Name cd_Strip_Ratio_MTD: Calc_Daily!$V$2:$V$366
Name cd_Strip_Ratio_YTD: Calc_Daily!$W$2:$W$366
Name cd_Rehandle_t: Calc_Daily!$X$2:$X$366
Name cd_Rehandle_t_MTD: Calc_Daily!$Y$2:$Y$366
Name cd_Rehandle_t_YTD: Calc_Daily!$Z$2:$Z$366
Name cd_Drill_m: Calc_Daily!$AA$2:$AA$366
Name cd_Drill_m_MTD: Calc_Daily!$AB$2:$AB$366
Name cd_Drill_m_YTD: Calc_Daily!$AC$2:$AC$366
Name cd_Blast_t: Calc_Daily!$AD$2:$AD$366
Name cd_Blast_t_MTD: Calc_Daily!$AE$2:$AE$366
Name cd_Blast_t_YTD: Calc_Daily!$AF$2:$AF$366
Name cd_Explosives_kg: Calc_Daily!$AG$2:$AG$366
Name cd_Explosives_kg_MTD: Calc_Daily!$AH$2:$AH$366
Name cd_Explosives_kg_YTD: Calc_Daily!$AI$2:$AI$366
Name cd_Powder_Factor_kgpt: Calc_Daily!$AJ$2:$AJ$366
Name cd_Powder_Factor_kgpt_MTD: Calc_Daily!$AK$2:$AK$366
Name cd_Powder_Factor_kgpt_YTD: Calc_Daily!$AL$2:$AL$366
Name cd_Diesel_Mining_L: Calc_Daily!$AM$2:$AM$366
Name cd_Diesel_Mining_L_MTD: Calc_Daily!$AN$2:$AN$366
Name cd_Diesel_Mining_L_YTD: Calc_Daily!$AO$2:$AO$366

Sheet README
B2: Mako Gold Mine Production System, 2026
B3: Petowal Mining Company S.A.. Version 0.1.0. Generated workbook: do not restructure by hand; change the schema and regenerate.
B5: How the workbook works
B6: 1. Inputs are the green tabs: Plant, Mining_Movements, Mining_Daily, Fleet, Safety, Gold, Commentary, Budget. Each is an Excel table. Type in the blue-headed columns only; grey-headed columns are formulas that fill automatically.
B7: 2. Calc_Daily rebuilds every KPI per day from the tables (day, month to date, year to date, budget). Daily_Report, Monthly_Summary and Dashboard read only from Calc_Daily.
B8: 3. There are no links to other workbooks and no macros. Copying the file anywhere keeps it working.
B9: 4. Lists holds every drop-down. Add a new pit, stockpile or equipment class there; do not type free text into list columns.
B10: 5. Config holds the year, the stockpile opening balances (survey at 1 January) and the prior-year safety history used for rolling 12-month rates.
B12: Daily routine
B13: Plant: enter the row for the day (dates are pre-filled). Mining: add one movement row per source, material and destination; add the Mining_Daily row and one Fleet row per equipment class. HSE: enter the Safety row. Everyone: one Commentary row per topic. Then open Daily_Report, check the date in C5, and print or export to PDF.
B15: Rules
B16: Do not insert columns inside tables, rename headers or move sheets. Add rows at the bottom of a table only. Blank means not reported; zero means reported as zero. Grades in g/t, tonnes dry metric, gold in troy ounces (31.1035 g).
... B22: Schema and generator: mps_schema.json and build_workbook.py in the MPS tools folder. Report issues to the Director, Operations and Projects.

Sheet Daily_Report
B2: =cfg_ReportTitle
B3: =cfg_Company&" | "&cfg_Site
L4: row
B5: Report date | C5: =MAX(cfg_YearStart,MIN(TODAY()-1,cfg_YearEnd,IF(N(cfg_LastDataDate)>0,cfg_LastDataDate,cfg_YearEnd))) | F5: Type a date to change the report day. To restore the default enter =MIN(TODAY()-1,cfg_LastDataDate) | L5: =IFERROR(MATCH($C$5,cd_Date,0),NA())
B6: ="Data to "&IF(N(cfg_LastDataDate)>0,TEXT(cfg_LastDataDate,"dd mmm yyyy"),"(no plant data yet)")&" | Week "&_xlfn.ISOWEEKNUM($C$5)&" | Day "&DAY($C$5)&" of "&DAY(EOMONTH($C$5,0))
B8: SAFETY | C8: Unit | D8: Day | E8: MTD | F8: MTD budget | G8: Var % | H8: YTD | I8: YTD budget | J8: Var %
B9: Hours worked | C9: h | D9: =IFERROR(INDEX(cd_Hours_Worked,rpt_Row),"") | E9: =IFERROR(INDEX(cd_Hours_Worked_MTD,rpt_Row),"") | F9: =IFERROR(INDEX(cd_Bud_Hours_Worked_MTD,rpt_Row),"") | G9: =IF(AND(ISNUMBER(F9),ISNUMBER(E9),F9<>0),E9/F9-1,"") | H9: =IFERROR(INDEX(cd_Hours_Worked_YTD,rpt_Row),"") | I9: =IFERROR(INDEX(cd_Bud_Hours_Worked_YTD,rpt_Row),"") | J9: =IF(AND(ISNUMBER(I9),ISNUMBER(H9),I9<>0),H9/I9-1,"")
B10: Recordable injuries | D10: =IFERROR(INDEX(cd_Recordables,rpt_Row),"") | E10: =IFERROR(INDEX(cd_Recordables_MTD,rpt_Row),"") | H10: =IFERROR(INDEX(cd_Recordables_YTD,rpt_Row),"")
B11: Lost time injuries | D11: =IFERROR(INDEX(cd_LTI,rpt_Row),"") | E11: =IFERROR(INDEX(cd_LTI_MTD,rpt_Row),"") | H11: =IFERROR(INDEX(cd_LTI_YTD,rpt_Row),"")
B12: Restricted work injuries | D12: =IFERROR(INDEX(cd_RWI,rpt_Row),"") | E12: =IFERROR(INDEX(cd_RWI_MTD,rpt_Row),"") | H12: =IFERROR(INDEX(cd_RWI_YTD,rpt_Row),"")
B13: Medical treatment injuries | D13: =IFERROR(INDEX(cd_MTI,rpt_Row),"") | E13: =IFERROR(INDEX(cd_MTI_MTD,rpt_Row),"") | H13: =IFERROR(INDEX(cd_MTI_YTD,rpt_Row),"")
B14: First aid injuries | D14: =IFERROR(INDEX(cd_FAI,rpt_Row),"") | E14: =IFERROR(INDEX(cd_FAI_MTD,rpt_Row),"") | H14: =IFERROR(INDEX(cd_FAI_YTD,rpt_Row),"")
B15: Near misses | D15: =IFERROR(INDEX(cd_Near_Miss,rpt_Row),"") | E15: =IFERROR(INDEX(cd_Near_Miss_MTD,rpt_Row),"") | H15: =IFERROR(INDEX(cd_Near_Miss_YTD,rpt_Row),"")
B16: Hazard reports | D16: =IFERROR(INDEX(cd_Hazard_Reports,rpt_Row),"") | E16: =IFERROR(INDEX(cd_Hazard_Reports_MTD,rpt_Row),"") | H16: =IFERROR(INDEX(cd_Hazard_Reports_YTD,rpt_Row),"")
B17: High potential incidents | D17: =IFERROR(INDEX(cd_HPI,rpt_Row),"") | E17: =IFERROR(INDEX(cd_HPI_MTD,rpt_Row),"") | H17: =IFERROR(INDEX(cd_HPI_YTD,rpt_Row),"")
B18: Environmental incidents | D18: =IFERROR(INDEX(cd_Env_Incidents,rpt_Row),"") | E18: =IFERROR(INDEX(cd_Env_Incidents_MTD,rpt_Row),"") | H18: =IFERROR(INDEX(cd_Env_Incidents_YTD,rpt_Row),"")
B19: Community incidents | D19: =IFERROR(INDEX(cd_Community_Incidents,rpt_Row),"") | E19: =IFERROR(INDEX(cd_Community_Incidents_MTD,rpt_Row),"") | H19: =IFERROR(INDEX(cd_Community_Incidents_YTD,rpt_Row),"")
B20: Vehicle incidents | D20: =IFERROR(INDEX(cd_Vehicle_Incidents,rpt_Row),"") | E20: =IFERROR(INDEX(cd_Vehicle_Incidents_MTD,rpt_Row),"") | H20: =IFERROR(INDEX(cd_Vehicle_Incidents_YTD,rpt_Row),"")
B21: TRIFR, rolling 12 months + MTD | D21: =IFERROR(INDEX(cd_TRIFR_12m,rpt_Row),"")
B22: LTIFR, rolling 12 months + MTD | D22: =IFERROR(INDEX(cd_LTIFR_12m,rpt_Row),"")
B23: Days since last LTI | D23: =IFERROR(INDEX(cd_Days_Since_LTI,rpt_Row),"")
B25: MINING | C25: Unit | D25: Day | E25: MTD | F25: MTD budget | G25: Var % | H25: YTD | I25: YTD budget | J25: Var %
B26: Ore mined (ex-pit) | C26: t | D26: =IFERROR(INDEX(cd_Ore_Mined_t,rpt_Row),"") | E26: =IFERROR(INDEX(cd_Ore_Mined_t_MTD,rpt_Row),"") | F26: =IFERROR(INDEX(cd_Bud_Ore_Mined_t_MTD,rpt_Row),"") | G26: =IF(AND(ISNUMBER(F26),ISNUMBER(E26),F26<>0),E26/F26-1,"") | H26: =IFERROR(INDEX(cd_Ore_Mined_t_YTD,rpt_Row),"") | I26: =IFERROR(INDEX(cd_Bud_Ore_Mined_t_YTD,rpt_Row),"") | J26: =IF(AND(ISNUMBER(I26),ISNUMBER(H26),I26<>0),H26/I26-1,"")
B27: Ore grade mined | C27: g/t | D27: =IFERROR(INDEX(cd_Ore_Grade_gpt,rpt_Row),"") | E27: =IFERROR(INDEX(cd_Ore_Grade_gpt_MTD,rpt_Row),"") | F27: =IFERROR(INDEX(cd_Bud_Ore_Grade_gpt_MTD,rpt_Row),"") | G27: =IF(AND(ISNUMBER(F27),ISNUMBER(E27),F27<>0),E27/F27-1,"") | H27: =IFERROR(INDEX(cd_Ore_Grade_gpt_YTD,rpt_Row),"") | I27: =IFERROR(INDEX(cd_Bud_Ore_Grade_gpt_YTD,rpt_Row),"") | J27: =IF(AND(ISNUMBER(I27),ISNUMBER(H27),I27<>0),H27/I27-1,"")
B28: Contained gold mined | C28: oz | D28: =IFERROR(INDEX(cd_Ore_Mined_oz,rpt_Row),"") | E28: =IFERROR(INDEX(cd_Ore_Mined_oz_MTD,rpt_Row),"") | F28: =IFERROR(INDEX(cd_Bud_Ore_Mined_oz_MTD,rpt_Row),"") | G28: =IF(AND(ISNUMBER(F28),ISNUMBER(E28),F28<>0),E28/F28-1,"") | H28: =IFERROR(INDEX(cd_Ore_Mined_oz_YTD,rpt_Row),"") | I28: =IFERROR(INDEX(cd_Bud_Ore_Mined_oz_YTD,rpt_Row),"") | J28: =IF(AND(ISNUMBER(I28),ISNUMBER(H28),I28<>0),H28/I28-1,"")
B29: Waste mined | C29: t | D29: =IFERROR(INDEX(cd_Waste_t,rpt_Row),"") | E29: =IFERROR(INDEX(cd_Waste_t_MTD,rpt_Row),"") | F29: =IFERROR(INDEX(cd_Bud_Waste_t_MTD,rpt_Row),"") | G29: =IF(AND(ISNUMBER(F29),ISNUMBER(E29),F29<>0),E29/F29-1,"") | H29: =IFERROR(INDEX(cd_Waste_t_YTD,rpt_Row),"") | I29: =IFERROR(INDEX(cd_Bud_Waste_t_YTD,rpt_Row),"") | J29: =IF(AND(ISNUMBER(I29),ISNUMBER(H29),I29<>0),H29/I29-1,"")
B30: Total material moved | C30: t | D30: =IFERROR(INDEX(cd_TMM_t,rpt_Row),"") | E30: =IFERROR(INDEX(cd_TMM_t_MTD,rpt_Row),"") | F30: =IFERROR(INDEX(cd_Bud_TMM_t_MTD,rpt_Row),"") | G30: =IF(AND(ISNUMBER(F30),ISNUMBER(E30),F30<>0),E30/F30-1,"") | H30: =IFERROR(INDEX(cd_TMM_t_YTD,rpt_Row),"") | I30: =IFERROR(INDEX(cd_Bud_TMM_t_YTD,rpt_Row),"") | J30: =IF(AND(ISNUMBER(I30),ISNUMBER(H30),I30<>0),H30/I30-1,"")
B31: Strip ratio (waste : ore) | D31: =IFERROR(INDEX(cd_Strip_Ratio,rpt_Row),"") | E31: =IFERROR(INDEX(cd_Strip_Ratio_MTD,rpt_Row),"") | F31: =IFERROR(INDEX(cd_Bud_Strip_Ratio_MTD,rpt_Row),"") | G31: =IF(AND(ISNUMBER(F31),ISNUMBER(E31),F31<>0),E31/F31-1,"") | H31: =IFERROR(INDEX(cd_Strip_Ratio_YTD,rpt_Row),"") | I31: =IFERROR(INDEX(cd_Bud_Strip_Ratio_YTD,rpt_Row),"") | J31: =IF(AND(ISNUMBER(I31),ISNUMBER(H31),I31<>0),H31/I31-1,"")
B32: Rehandle from stockpiles | C32: t | D32: =IFERROR(INDEX(cd_Rehandle_t,rpt_Row),"") | E32: =IFERROR(INDEX(cd_Rehandle_t_MTD,rpt_Row),"") | H32: =IFERROR(INDEX(cd_Rehandle_t_YTD,rpt_Row),"")
B33: Drilled | C33: m | D33: =IFERROR(INDEX(cd_Drill_m,rpt_Row),"") | E33: =IFERROR(INDEX(cd_Drill_m_MTD,rpt_Row),"") | F33: =IFERROR(INDEX(cd_Bud_Drill_m_MTD,rpt_Row),"") | G33: =IF(AND(ISNUMBER(F33),ISNUMBER(E33),F33<>0),E33/F33-1,"") | H33: =IFERROR(INDEX(cd_Drill_m_YTD,rpt_Row),"") | I33: =IFERROR(INDEX(cd_Bud_Drill_m_YTD,rpt_Row),"") | J33: =IF(AND(ISNUMBER(I33),ISNUMBER(H33),I33<>0),H33/I33-1,"")
B34: Blasted | C34: t | D34: =IFERROR(INDEX(cd_Blast_t,rpt_Row),"") | E34: =IFERROR(INDEX(cd_Blast_t_MTD,rpt_Row),"") | H34: =IFERROR(INDEX(cd_Blast_t_YTD,rpt_Row),"")
B35: Powder factor | C35: kg/t | D35: =IFERROR(INDEX(cd_Powder_Factor_kgpt,rpt_Row),"") | E35: =IFERROR(INDEX(cd_Powder_Factor_kgpt_MTD,rpt_Row),"") | H35: =IFERROR(INDEX(cd_Powder_Factor_kgpt_YTD,rpt_Row),"")
B36: Mining diesel | C36: L | D36: =IFERROR(INDEX(cd_Diesel_Mining_L,rpt_Row),"") | E36: =IFERROR(INDEX(cd_Diesel_Mining_L_MTD,rpt_Row),"") | F36: =IFERROR(INDEX(cd_Bud_Diesel_Mining_L_MTD,rpt_Row),"") | G36: =IF(AND(ISNUMBER(F36),ISNUMBER(E36),F36<>0),E36/F36-1,"") | H36: =IFERROR(INDEX(cd_Diesel_Mining_L_YTD,rpt_Row),"") | I36: =IFERROR(INDEX(cd_Bud_Diesel_Mining_L_YTD,rpt_Row),"") | J36: =IF(AND(ISNUMBER(I36),ISNUMBER(H36),I36<>0),H36/I36-1,"")
B37: Excavator availability | C37: % | D37: =IFERROR(INDEX(cd_Exc_Availability_pct,rpt_Row),"") | E37: =IFERROR(INDEX(cd_Exc_Availability_pct_MTD,rpt_Row),"") | H37: =IFERROR(INDEX(cd_Exc_Availability_pct_YTD,rpt_Row),"")
B38: Excavator utilisation | C38: % | D38: =IFERROR(INDEX(cd_Exc_Utilisation_pct,rpt_Row),"") | E38: =IFERROR(INDEX(cd_Exc_Utilisation_pct_MTD,rpt_Row),"") | H38: =IFERROR(INDEX(cd_Exc_Utilisation_pct_YTD,rpt_Row),"")
B39: Truck availability | C39: % | D39: =IFERROR(INDEX(cd_Trk_Availability_pct,rpt_Row),"") | E39: =IFERROR(INDEX(cd_Trk_Availability_pct_MTD,rpt_Row),"") | H39: =IFERROR(INDEX(cd_Trk_Availability_pct_YTD,rpt_Row),"")
B40: Truck utilisation | C40: % | D40: =IFERROR(INDEX(cd_Trk_Utilisation_pct,rpt_Row),"") | E40: =IFERROR(INDEX(cd_Trk_Utilisation_pct_MTD,rpt_Row),"") | H40: =IFERROR(INDEX(cd_Trk_Utilisation_pct_YTD,rpt_Row),"")
B42: PROCESSING | C42: Unit | D42: Day | E42: MTD | F42: MTD budget | G42: Var % | H42: YTD | I42: YTD budget | J42: Var %
B43: Crushed | C43: t | D43: =IFERROR(INDEX(cd_Crushed_t,rpt_Row),"") | E43: =IFERROR(INDEX(cd_Crushed_t_MTD,rpt_Row),"") | H43: =IFERROR(INDEX(cd_Crushed_t_YTD,rpt_Row),"")
B44: Milled | C44: t | D44: =IFERROR(INDEX(cd_Milled_t,rpt_Row),"") | E44: =IFERROR(INDEX(cd_Milled_t_MTD,rpt_Row),"") | F44: =IFERROR(INDEX(cd_Bud_Milled_t_MTD,rpt_Row),"") | G44: =IF(AND(ISNUMBER(F44),ISNUMBER(E44),F44<>0),E44/F44-1,"") | H44: =IFERROR(INDEX(cd_Milled_t_YTD,rpt_Row),"") | I44: =IFERROR(INDEX(cd_Bud_Milled_t_YTD,rpt_Row),"") | J44: =IF(AND(ISNUMBER(I44),ISNUMBER(H44),I44<>0),H44/I44-1,"")
...

Sheet Dashboard
B2: =cfg_Site&" dashboard "&cfg_Year
B3: ="Data to "&IF(N(cfg_LastDataDate)>0,TEXT(cfg_LastDataDate,"dd mmm yyyy"),"(no plant data yet)")

Sheet Monthly_Summary
B2: =cfg_Site&" monthly summary "&cfg_Year
B3: ="Actuals to "&IF(N(cfg_LastDataDate)>0,TEXT(cfg_LastDataDate,"dd mmm yyyy"),"(no plant data yet)")&". Budget from the Budget sheet. Ratios are month values, not averages of days."
B5: KPI | D5: 46023 | E5: 46054 | F5: 46082 | G5: 46113 | H5: 46143 | I5: 46174 | J5: 46204 | K5: 46235 | L5: 46266 | M5: 46296 | N5: 46327 | O5: 46357 | P5: Year
B6: Hours worked | C6: Actual | D6: =IF(DATE(cfg_Year,1,1)>cfg_LastDataDate,"",IFERROR(INDEX(cd_Hours_Worked_MTD,MATCH(MIN(EOMONTH(DATE(cfg_Year,1,1),0),cfg_LastDataDate),cd_Date,0)),"")) | E6: =IF(DATE(cfg_Year,2,1)>cfg_LastDataDate,"",IFERROR(INDEX(cd_Hours_Worked_MTD,MATCH(MIN(EOMONTH(DATE(cfg_Year,2,1),0),cfg_LastDataDate),cd_Date,0)),"")) | F6: =IF(DATE(cfg_Year,3,1)>cfg_LastDataDate,"",IFERROR(INDEX(cd_Hours_Worked_MTD,MATCH(MIN(EOMONTH(DATE(cfg_Year,3,1),0),cfg_LastDataDate),cd_Date,0)),"")) | G6: =IF(DATE(cfg_Year,4,1)>cfg_LastDataDate,"",IFERROR(INDEX(cd_Hours_Worked_MTD,MATCH(MIN(EOMONTH(DATE(cfg_Year,4,1),0),cfg_LastDataDate),cd_Date,0)),"")) | H6: =IF(DATE(cfg_Year,5,1)>cfg_LastDataDate,"",IFERROR(INDEX(cd_Hours_Worked_MTD,MATCH(MIN(EOMONTH(DATE(cfg_Year,5,1),0),cfg_LastDataDate),cd_Date,0)),"")) | I6: =IF(DATE(cfg_Year,6,1)>cfg_LastDataDate,"",IFERROR(INDEX(cd_Hours_Worked_MTD,MATCH(MIN(EOMONTH(DATE(cfg_Year,6,1),0),cfg_LastDataDate),cd_Date,0)),"")) | J6: =IF(DATE(cfg_Year,7,1)>cfg_LastDataDate,"",IFERROR(INDEX(cd_Hours_Worked_MTD,MATCH(MIN(EOMONTH(DATE(cfg_Year,7,1),0),cfg_LastDataDate),cd_Date,0)),"")) | K6: =IF(DATE(cfg_Year,8,1)>cfg_LastDataDate,"",IFERROR(INDEX(cd_Hours_Worked_MTD,MATCH(MIN(EOMONTH(DATE(cfg_Year,8,1),0),cfg_LastDataDate),cd_Date,0)),"")) | L6: =IF(DATE(cfg_Year,9,1)>cfg_LastDataDate,"",IFERROR(INDEX(cd_Hours_Worked_MTD,MATCH(MIN(EOMONTH(DATE(cfg_Year,9,1),0),cfg_LastDataDate),cd_Date,0)),"")) | M6: =IF(DATE(cfg_Year,10,1)>cfg_LastDataDate,"",IFERROR(INDEX(cd_Hours_Worked_MTD,MATCH(MIN(EOMONTH(DATE(cfg_Year,10,1),0),cfg_LastDataDate),cd_Date,0)),"")) | N6: =IF(DATE(cfg_Year,11,1)>cfg_LastDataDate,"",IFERROR(INDEX(cd_Hours_Worked_MTD,MATCH(MIN(EOMONTH(DATE(cfg_Year,11,1),0),cfg_LastDataDate),cd_Date,0)),"")) | O6: =IF(DATE(cfg_Year,12,1)>cfg_LastDataDate,"",IFERROR(INDEX(cd_Hours_Worked_MTD,MATCH(MIN(EOMONTH(DATE(cfg_Year,12,1),0),cfg_LastDataDate),cd_Date,0)),"")) | P6: =IFERROR(INDEX(cd_Hours_Worked_YTD,MATCH(MIN(cfg_YearEnd,cfg_LastDataDate),cd_Date,0)),"")
C7: Budget | D7: =IFERROR(INDEX(cd_Bud_Hours_Worked_Month,MATCH(DATE(cfg_Year,1,1),cd_Date,0)),"") | E7: =IFERROR(INDEX(cd_Bud_Hours_Worked_Month,MATCH(DATE(cfg_Year,2,1),cd_Date,0)),"") | F7: =IFERROR(INDEX(cd_Bud_Hours_Worked_Month,MATCH(DATE(cfg_Year,3,1),cd_Date,0)),"") | G7: =IFERROR(INDEX(cd_Bud_Hours_Worked_Month,MATCH(DATE(cfg_Year,4,1),cd_Date,0)),"") | H7: =IFERROR(INDEX(cd_Bud_Hours_Worked_Month,MATCH(DATE(cfg_Year,5,1),cd_Date,0)),"") | I7: =IFERROR(INDEX(cd_Bud_Hours_Worked_Month,MATCH(DATE(cfg_Year,6,1),cd_Date,0)),"") | J7: =IFERROR(INDEX(cd_Bud_Hours_Worked_Month,MATCH(DATE(cfg_Year,7,1),cd_Date,0)),"") | K7: =IFERROR(INDEX(cd_Bud_Hours_Worked_Month,MATCH(DATE(cfg_Year,8,1),cd_Date,0)),"") | L7: =IFERROR(INDEX(cd_Bud_Hours_Worked_Month,MATCH(DATE(cfg_Year,9,1),cd_Date,0)),"") | M7: =IFERROR(INDEX(cd_Bud_Hours_Worked_Month,MATCH(DATE(cfg_Year,10,1),cd_Date,0)),"") | N7: =IFERROR(INDEX(cd_Bud_Hours_Worked_Month,MATCH(DATE(cfg_Year,11,1),cd_Date,0)),"") | O7: =IFERROR(INDEX(cd_Bud_Hours_Worked_Month,MATCH(DATE(cfg_Year,12,1),cd_Date,0)),"") | P7: =IFERROR(INDEX(cd_Bud_Hours_Worked_YTD,MATCH(cfg_YearEnd,cd_Date,0)),"")
C8: Variance | D8: =IF(AND(ISNUMBER(D6),ISNUMBER(D7),D7<>0),D6/D7-1,"") | E8: =IF(AND(ISNUMBER(E6),ISNUMBER(E7),E7<>0),E6/E7-1,"") | F8: =IF(AND(ISNUMBER(F6),ISNUMBER(F7),F7<>0),F6/F7-1,"") | G8: =IF(AND(ISNUMBER(G6),ISNUMBER(G7),G7<>0),G6/G7-1,"") | H8: =IF(AND(ISNUMBER(H6),ISNUMBER(H7),H7<>0),H6/H7-1,"") | I8: =IF(AND(ISNUMBER(I6),ISNUMBER(I7),I7<>0),I6/I7-1,"") | J8: =IF(AND(ISNUMBER(J6),ISNUMBER(J7),J7<>0),J6/J7-1,"") | K8: =IF(AND(ISNUMBER(K6),ISNUMBER(K7),K7<>0),K6/K7-1,"") | ... P8: =IF(AND(ISNUMBER(P6),ISNUMBER(P7),P7<>0),P6/P7-1,"")
B10: Recordable injuries | C10: Actual | D10: =IF(DATE(cfg_Year,1,1)>cfg_LastDataDate,"",IFERROR(INDEX(cd_Recordables_MTD,MATCH(MIN(EOMONTH(DATE(cfg_Year,1,1),0),cfg_LastDataDate),cd_Date,0)),"")) | E10: =IF(DATE(cfg_Year,2,1)>cfg_LastDataDate,"",IFERROR(INDEX(cd_Recordables_MTD,MATCH(MIN(EOMONTH(DATE(cfg_Year,2,1),0),cfg_LastDataDate),cd_Date,0)),"")) | F10: =IF(DATE(cfg_Year,3,1)>cfg_LastDataDate,"",IFERROR(INDEX(cd_Recordables_MTD,MATCH(MIN(EOMONTH(DATE(cfg_Year,3,1),0),cfg_LastDataDate),cd_Date,0)),"")) | G10: =IF(DATE(cfg_Year,4,1)>cfg_LastDataDate,"",IFERROR(INDEX(cd_Recordables_MTD,MATCH(MIN(EOMONTH(DATE(cfg_Year,4,1),0),cfg_LastDataDate),cd_Date,0)),"")) | H10: =IF(DATE(cfg_Year,5,1)>cfg_LastDataDate,"",IFERROR(INDEX(cd_Recordables_MTD,MATCH(MIN(EOMONTH(DATE(cfg_Year,5,1),0),cfg_LastDataDate),cd_Date,0)),"")) | I10: =IF(DATE(cfg_Year,6,1)>cfg_LastDataDate,"",IFERROR(INDEX(cd_Recordables_MTD,MATCH(MIN(EOMONTH(DATE(cfg_Year,6,1),0),cfg_LastDataDate),cd_Date,0)),"")) | J10: =IF(DATE(cfg_Year,7,1)>cfg_LastDataDate,"",IFERROR(INDEX(cd_Recordables_MTD,MATCH(MIN(EOMONTH(DATE(cfg_Year,7,1),0),cfg_LastDataDate),cd_Date,0)),"")) | K10: =IF(DATE(cfg_Year,8,1)>cfg_LastDataDate,"",IFERROR(INDEX(cd_Recordables_MTD,MATCH(MIN(EOMONTH(DATE(cfg_Year,8,1),0),cfg_LastDataDate),cd_Date,0)),"")) | L10: =IF(DATE(cfg_Year,9,1)>cfg_LastDataDate,"",IFERROR(INDEX(cd_Recordables_MTD,MATCH(MIN(EOMONTH(DATE(cfg_Year,9,1),0),cfg_LastDataDate),cd_Date,0)),"")) | M10: =IF(DATE(cfg_Year,10,1)>cfg_LastDataDate,"",IFERROR(INDEX(cd_Recordables_MTD,MATCH(MIN(EOMONTH(DATE(cfg_Year,10,1),0),cfg_LastDataDate),cd_Date,0)),"")) | N10: =IF(DATE(cfg_Year,11,1)>cfg_LastDataDate,"",IFERROR(INDEX(cd_Recordables_MTD,MATCH(MIN(EOMONTH(DATE(cfg_Year,11,1),0),cfg_LastDataDate),cd_Date,0)),"")) | O10: =IF(DATE(cfg_Year,12,1)>cfg_LastDataDate,"",IFERROR(INDEX(cd_Recordables_MTD,MATCH(MIN(EOMONTH(DATE(cfg_Year,12,1),0),cfg_LastDataDate),cd_Date,0)),"")) | P10: =IFERROR(INDEX(cd_Recordables_YTD,MATCH(MIN(cfg_YearEnd,cfg_LastDataDate),cd_Date,0)),"")
B11: Lost time injuries | C11: Actual | D11: =IF(DATE(cfg_Year,1,1)>cfg_LastDataDate,"",IFERROR(INDEX(cd_LTI_MTD,MATCH(MIN(EOMONTH(DATE(cfg_Year,1,1),0),cfg_LastDataDate),cd_Date,0)),"")) | E11: =IF(DATE(cfg_Year,2,1)>cfg_LastDataDate,"",IFERROR(INDEX(cd_LTI_MTD,MATCH(MIN(EOMONTH(DATE(cfg_Year,2,1),0),cfg_LastDataDate),cd_Date,0)),"")) | F11: =IF(DATE(cfg_Year,3,1)>cfg_LastDataDate,"",IFERROR(INDEX(cd_LTI_MTD,MATCH(MIN(EOMONTH(DATE(cfg_Year,3,1),0),cfg_LastDataDate),cd_Date,0)),"")) | G11: =IF(DATE(cfg_Year,4,1)>cfg_LastDataDate,"",IFERROR(INDEX(cd_LTI_MTD,MATCH(MIN(EOMONTH(DATE(cfg_Year,4,1),0),cfg_LastDataDate),cd_Date,0)),"")) | H11: =IF(DATE(cfg_Year,5,1)>cfg_LastDataDate,"",IFERROR(INDEX(cd_LTI_MTD,MATCH(MIN(EOMONTH(DATE(cfg_Year,5,1),0),cfg_LastDataDate),cd_Date,0)),"")) | I11: =IF(DATE(cfg_Year,6,1)>cfg_LastDataDate,"",IFERROR(INDEX(cd_LTI_MTD,MATCH(MIN(EOMONTH(DATE(cfg_Year,6,1),0),cfg_LastDataDate),cd_Date,0)),"")) | J11: =IF(DATE(cfg_Year,7,1)>cfg_LastDataDate,"",IFERROR(INDEX(cd_LTI_MTD,MATCH(MIN(EOMONTH(DATE(cfg_Year,7,1),0),cfg_LastDataDate),cd_Date,0)),"")) | K11: =IF(DATE(cfg_Year,8,1)>cfg_LastDataDate,"",IFERROR(INDEX(cd_LTI_MTD,MATCH(MIN(EOMONTH(DATE(cfg_Year,8,1),0),cfg_LastDataDate),cd_Date,0)),"")) | L11: =IF(DATE(cfg_Year,9,1)>cfg_LastDataDate,"",IFERROR(INDEX(cd_LTI_MTD,MATCH(MIN(EOMONTH(DATE(cfg_Year,9,1),0),cfg_LastDataDate),cd_Date,0)),"")) | M11: =IF(DATE(cfg_Year,10,1)>cfg_LastDataDate,"",IFERROR(INDEX(cd_LTI_MTD,MATCH(MIN(EOMONTH(DATE(cfg_Year,10,1),0),cfg_LastDataDate),cd_Date,0)),"")) | N11: =IF(DATE(cfg_Year,11,1)>cfg_LastDataDate,"",IFERROR(INDEX(cd_LTI_MTD,MATCH(MIN(EOMONTH(DATE(cfg_Year,11,1),0),cfg_LastDataDate),cd_Date,0)),"")) | O11: =IF(DATE(cfg_Year,12,1)>cfg_LastDataDate,"",IFERROR(INDEX(cd_LTI_MTD,MATCH(MIN(EOMONTH(DATE(cfg_Year,12,1),0),cfg_LastDataDate),cd_Date,0)),"")) | P11: =IFERROR(INDEX(cd_LTI_YTD,MATCH(MIN(cfg_YearEnd,cfg_LastDataDate),cd_Date,0)),"")
B12: TRIFR, rolling 12 months + MTD | C12: Actual | D12: =IF(DATE(cfg_Year,1,1)>cfg_LastDataDate,"",IFERROR(INDEX(cd_TRIFR_12m,MATCH(MIN(EOMONTH(DATE(cfg_Year,1,1),0),cfg_LastDataDate),cd_Date,0)),"")) | E12: =IF(DATE(cfg_Year,2,1)>cfg_LastDataDate,"",IFERROR(INDEX(cd_TRIFR_12m,MATCH(MIN(EOMONTH(DATE(cfg_Year,2,1),0),cfg_LastDataDate),cd_Date,0)),"")) | F12: =IF(DATE(cfg_Year,3,1)>cfg_LastDataDate,"",IFERROR(INDEX(cd_TRIFR_12m,MATCH(MIN(EOMONTH(DATE(cfg_Year,3,1),0),cfg_LastDataDate),cd_Date,0)),"")) | G12: =IF(DATE(cfg_Year,4,1)>cfg_LastDataDate,"",IFERROR(INDEX(cd_TRIFR_12m,MATCH(MIN(EOMONTH(DATE(cfg_Year,4,1),0),cfg_LastDataDate),cd_Date,0)),"")) | H12: =IF(DATE(cfg_Year,5,1)>cfg_LastDataDate,"",IFERROR(INDEX(cd_TRIFR_12m,MATCH(MIN(EOMONTH(DATE(cfg_Year,5,1),0),cfg_LastDataDate),cd_Date,0)),"")) | I12: =IF(DATE(cfg_Year,6,1)>cfg_LastDataDate,"",IFERROR(INDEX(cd_TRIFR_12m,MATCH(MIN(EOMONTH(DATE(cfg_Year,6,1),0),cfg_LastDataDate),cd_Date,0)),"")) | J12: =IF(DATE(cfg_Year,7,1)>cfg_LastDataDate,"",IFERROR(INDEX(cd_TRIFR_12m,MATCH(MIN(EOMONTH(DATE(cfg_Year,7,1),0),cfg_LastDataDate),cd_Date,0)),"")) | K12: =IF(DATE(cfg_Year,8,1)>cfg_LastDataDate,"",IFERROR(INDEX(cd_TRIFR_12m,MATCH(MIN(EOMONTH(DATE(cfg_Year,8,1),0),cfg_LastDataDate),cd_Date,0)),"")) | L12: =IF(DATE(cfg_Year,9,1)>cfg_LastDataDate,"",IFERROR(INDEX(cd_TRIFR_12m,MATCH(MIN(EOMONTH(DATE(cfg_Year,9,1),0),cfg_LastDataDate),cd_Date,0)),"")) | M12: =IF(DATE(cfg_Year,10,1)>cfg_LastDataDate,"",IFERROR(INDEX(cd_TRIFR_12m,MATCH(MIN(EOMONTH(DATE(cfg_Year,10,1),0),cfg_LastDataDate),cd_Date,0)),"")) | N12: =IF(DATE(cfg_Year,11,1)>cfg_LastDataDate,"",IFERROR(INDEX(cd_TRIFR_12m,MATCH(MIN(EOMONTH(DATE(cfg_Year,11,1),0),cfg_LastDataDate),cd_Date,0)),"")) | O12: =IF(DATE(cfg_Year,12,1)>cfg_LastDataDate,"",IFERROR(INDEX(cd_TRIFR_12m,MATCH(MIN(EOMONTH(DATE(cfg_Year,12,1),0),cfg_LastDataDate),cd_Date,0)),"")) | P12: =IFERROR(INDEX(cd_TRIFR_12m,MATCH(MIN(cfg_YearEnd,cfg_LastDataDate),cd_Date,0)),"")
B13: Ore mined (ex-pit) | C13: Actual | D13: =IF(DATE(cfg_Year,1,1)>cfg_LastDataDate,"",IFERROR(INDEX(cd_Ore_Mined_t_MTD,MATCH(MIN(EOMONTH(DATE(cfg_Year,1,1),0),cfg_LastDataDate),cd_Date,0)),"")) | E13: =IF(DATE(cfg_Year,2,1)>cfg_LastDataDate,"",IFERROR(INDEX(cd_Ore_Mined_t_MTD,MATCH(MIN(EOMONTH(DATE(cfg_Year,2,1),0),cfg_LastDataDate),cd_Date,0)),"")) | F13: =IF(DATE(cfg_Year,3,1)>cfg_LastDataDate,"",IFERROR(INDEX(cd_Ore_Mined_t_MTD,MATCH(MIN(EOMONTH(DATE(cfg_Year,3,1),0),cfg_LastDataDate),cd_Date,0)),"")) | G13: =IF(DATE(cfg_Year,4,1)>cfg_LastDataDate,"",IFERROR(INDEX(cd_Ore_Mined_t_MTD,MATCH(MIN(EOMONTH(DATE(cfg_Year,4,1),0),cfg_LastDataDate),cd_Date,0)),"")) | H13: =IF(DATE(cfg_Year,5,1)>cfg_LastDataDate,"",IFERROR(INDEX(cd_Ore_Mined_t_MTD,MATCH(MIN(EOMONTH(DATE(cfg_Year,5,1),0),cfg_LastDataDate),cd_Date,0)),"")) | I13: =IF(DATE(cfg_Year,6,1)>cfg_LastDataDate,"",IFERROR(INDEX(cd_Ore_Mined_t_MTD,MATCH(MIN(EOMONTH(DATE(cfg_Year,6,1),0),cfg_LastDataDate),cd_Date,0)),"")) | J13: =IF(DATE(cfg_Year,7,1)>cfg_LastDataDate,"",IFERROR(INDEX(cd_Ore_Mined_t_MTD,MATCH(MIN(EOMONTH(DATE(cfg_Year,7,1),0),cfg_LastDataDate),cd_Date,0)),"")) | K13: =IF(DATE(cfg_Year,8,1)>cfg_LastDataDate,"",IFERROR(INDEX(cd_Ore_Mined_t_MTD,MATCH(MIN(EOMONTH(DATE(cfg_Year,8,1),0),cfg_LastDataDate),cd_Date,0)),"")) | L13: =IF(DATE(cfg_Year,9,1)>cfg_LastDataDate,"",IFERROR(INDEX(cd_Ore_Mined_t_MTD,MATCH(MIN(EOMONTH(DATE(cfg_Year,9,1),0),cfg_LastDataDate),cd_Date,0)),"")) | M13: =IF(DATE(cfg_Year,10,1)>cfg_LastDataDate,"",IFERROR(INDEX(cd_Ore_Mined_t_MTD,MATCH(MIN(EOMONTH(DATE(cfg_Year,10,1),0),cfg_LastDataDate),cd_Date,0)),"")) | N13: =IF(DATE(cfg_Year,11,1)>cfg_LastDataDate,"",IFERROR(INDEX(cd_Ore_Mined_t_MTD,MATCH(MIN(EOMONTH(DATE(cfg_Year,11,1),0),cfg_LastDataDate),cd_Date,0)),"")) | O13: =IF(DATE(cfg_Year,12,1)>cfg_LastDataDate,"",IFERROR(INDEX(cd_Ore_Mined_t_MTD,MATCH(MIN(EOMONTH(DATE(cfg_Year,12,1),0),cfg_LastDataDate),cd_Date,0)),"")) | P13: =IFERROR(INDEX(cd_Ore_Mined_t_YTD,MATCH(MIN(cfg_YearEnd,cfg_LastDataDate),cd_Date,0)),"")
C14: Budget | D14: =IFERROR(INDEX(cd_Bud_Ore_Mined_t_Month,MATCH(DATE(cfg_Year,1,1),cd_Date,0)),"") | E14: =IFERROR(INDEX(cd_Bud_Ore_Mined_t_Month,MATCH(DATE(cfg_Year,2,1),cd_Date,0)),"") | F14: =IFERROR(INDEX(cd_Bud_Ore_Mined_t_Month,MATCH(DATE(cfg_Year,3,1),cd_Date,0)),"") | G14: =IFERROR(INDEX(cd_Bud_Ore_Mined_t_Month,MATCH(DATE(cfg_Year,4,1),cd_Date,0)),"") | H14: =IFERROR(INDEX(cd_Bud_Ore_Mined_t_Month,MATCH(DATE(cfg_Year,5,1),cd_Date,0)),"") | I14: =IFERROR(INDEX(cd_Bud_Ore_Mined_t_Month,MATCH(DATE(cfg_Year,6,1),cd_Date,0)),"") | J14: =IFERROR(INDEX(cd_Bud_Ore_Mined_t_Month,MATCH(DATE(cfg_Year,7,1),cd_Date,0)),"") | K14: =IFERROR(INDEX(cd_Bud_Ore_Mined_t_Month,MATCH(DATE(cfg_Year,8,1),cd_Date,0)),"") | L14: =IFERROR(INDEX(cd_Bud_Ore_Mined_t_Month,MATCH(DATE(cfg_Year,9,1),cd_Date,0)),"") | M14: =IFERROR(INDEX(cd_Bud_Ore_Mined_t_Month,MATCH(DATE(cfg_Year,10,1),cd_Date,0)),"") | N14: =IFERROR(INDEX(cd_Bud_Ore_Mined_t_Month,MATCH(DATE(cfg_Year,11,1),cd_Date,0)),"") | O14: =IFERROR(INDEX(cd_Bud_Ore_Mined_t_Month,MATCH(DATE(cfg_Year,12,1),cd_Date,0)),"") | P14: =IFERROR(INDEX(cd_Bud_Ore_Mined_t_YTD,MATCH(cfg_YearEnd,cd_Date,0)),"")
C15: Variance | D15: =IF(AND(ISNUMBER(D13),ISNUMBER(D14),D14<>0),D13/D14-1,"") | E15: =IF(AND(ISNUMBER(E13),ISNUMBER(E14),E14<>0),E13/E14-1,"") | F15: =IF(AND(ISNUMBER(F13),ISNUMBER(F14),F14<>0),F13/F14-1,"") | G15: =IF(AND(ISNUMBER(G13),ISNUMBER(G14),G14<>0),G13/G14-1,"") | H15: =IF(AND(ISNUMBER(H13),ISNUMBER(H14),H14<>0),H13/H14-1,"") | I15: =IF(AND(ISNUMBER(I13),ISNUMBER(I14),I14<>0),I13/I14-1,"") | J15: =IF(AND(ISNUMBER(J13),ISNUMBER(J14),J14<>0),J13/J14-1,"") | K15: =IF(AND(ISNUMBER(K13),ISNUMBER(K14),K14<>0),K13/K14-1,"") | ... P15: =IF(AND(ISNUMBER(P13),ISNUMBER(P14),P14<>0),P13/P14-1,"")
B17: Ore grade mined | C17: Actual | D17: =IF(DATE(cfg_Year,1,1)>cfg_LastDataDate,"",IFERROR(INDEX(cd_Ore_Grade_gpt_MTD,MATCH(MIN(EOMONTH(DATE(cfg_Year,1,1),0),cfg_LastDataDate),cd_Date,0)),"")) | E17: =IF(DATE(cfg_Year,2,1)>cfg_LastDataDate,"",IFERROR(INDEX(cd_Ore_Grade_gpt_MTD,MATCH(MIN(EOMONTH(DATE(cfg_Year,2,1),0),cfg_LastDataDate),cd_Date,0)),"")) | F17: =IF(DATE(cfg_Year,3,1)>cfg_LastDataDate,"",IFERROR(INDEX(cd_Ore_Grade_gpt_MTD,MATCH(MIN(EOMONTH(DATE(cfg_Year,3,1),0),cfg_LastDataDate),cd_Date,0)),"")) | G17: =IF(DATE(cfg_Year,4,1)>cfg_LastDataDate,"",IFERROR(INDEX(cd_Ore_Grade_gpt_MTD,MATCH(MIN(EOMONTH(DATE(cfg_Year,4,1),0),cfg_LastDataDate),cd_Date,0)),"")) | H17: =IF(DATE(cfg_Year,5,1)>cfg_LastDataDate,"",IFERROR(INDEX(cd_Ore_Grade_gpt_MTD,MATCH(MIN(EOMONTH(DATE(cfg_Year,5,1),0),cfg_LastDataDate),cd_Date,0)),"")) | I17: =IF(DATE(cfg_Year,6,1)>cfg_LastDataDate,"",IFERROR(INDEX(cd_Ore_Grade_gpt_MTD,MATCH(MIN(EOMONTH(DATE(cfg_Year,6,1),0),cfg_LastDataDate),cd_Date,0)),"")) | J17: =IF(DATE(cfg_Year,7,1)>cfg_LastDataDate,"",IFERROR(INDEX(cd_Ore_Grade_gpt_MTD,MATCH(MIN(EOMONTH(DATE(cfg_Year,7,1),0),cfg_LastDataDate),cd_Date,0)),"")) | K17: =IF(DATE(cfg_Year,8,1)>cfg_LastDataDate,"",IFERROR(INDEX(cd_Ore_Grade_gpt_MTD,MATCH(MIN(EOMONTH(DATE(cfg_Year,8,1),0),cfg_LastDataDate),cd_Date,0)),"")) | L17: =IF(DATE(cfg_Year,9,1)>cfg_LastDataDate,"",IFERROR(INDEX(cd_Ore_Grade_gpt_MTD,MATCH(MIN(EOMONTH(DATE(cfg_Year,9,1),0),cfg_LastDataDate),cd_Date,0)),"")) | M17: =IF(DATE(cfg_Year,10,1)>cfg_LastDataDate,"",IFERROR(INDEX(cd_Ore_Grade_gpt_MTD,MATCH(MIN(EOMONTH(DATE(cfg_Year,10,1),0),cfg_LastDataDate),cd_Date,0)),"")) | N17: =IF(DATE(cfg_Year,11,1)>cfg_LastDataDate,"",IFERROR(INDEX(cd_Ore_Grade_gpt_MTD,MATCH(MIN(EOMONTH(DATE(cfg_Year,11,1),0),cfg_LastDataDate),cd_Date,0)),"")) | O17: =IF(DATE(cfg_Year,12,1)>cfg_LastDataDate,"",IFERROR(INDEX(cd_Ore_Grade_gpt_MTD,MATCH(MIN(EOMONTH(DATE(cfg_Year,12,1),0),cfg_LastDataDate),cd_Date,0)),"")) | P17: =IFERROR(INDEX(cd_Ore_Grade_gpt_YTD,MATCH(MIN(cfg_YearEnd,cfg_LastDataDate),cd_Date,0)),"")
C18: Budget | D18: =IFERROR(INDEX(cd_Bud_Ore_Grade_gpt_Month,MATCH(DATE(cfg_Year,1,1),cd_Date,0)),"") | E18: =IFERROR(INDEX(cd_Bud_Ore_Grade_gpt_Month,MATCH(DATE(cfg_Year,2,1),cd_Date,0)),"") | F18: =IFERROR(INDEX(cd_Bud_Ore_Grade_gpt_Month,MATCH(DATE(cfg_Year,3,1),cd_Date,0)),"") | G18: =IFERROR(INDEX(cd_Bud_Ore_Grade_gpt_Month,MATCH(DATE(cfg_Year,4,1),cd_Date,0)),"") | H18: =IFERROR(INDEX(cd_Bud_Ore_Grade_gpt_Month,MATCH(DATE(cfg_Year,5,1),cd_Date,0)),"") | I18: =IFERROR(INDEX(cd_Bud_Ore_Grade_gpt_Month,MATCH(DATE(cfg_Year,6,1),cd_Date,0)),"") | J18: =IFERROR(INDEX(cd_Bud_Ore_Grade_gpt_Month,MATCH(DATE(cfg_Year,7,1),cd_Date,0)),"") | K18: =IFERROR(INDEX(cd_Bud_Ore_Grade_gpt_Month,MATCH(DATE(cfg_Year,8,1),cd_Date,0)),"") | L18: =IFERROR(INDEX(cd_Bud_Ore_Grade_gpt_Month,MATCH(DATE(cfg_Year,9,1),cd_Date,0)),"") | M18: =IFERROR(INDEX(cd_Bud_Ore_Grade_gpt_Month,MATCH(DATE(cfg_Year,10,1),cd_Date,0)),"") | N18: =IFERROR(INDEX(cd_Bud_Ore_Grade_gpt_Month,MATCH(DATE(cfg_Year,11,1),cd_Date,0)),"") | O18: =IFERROR(INDEX(cd_Bud_Ore_Grade_gpt_Month,MATCH(DATE(cfg_Year,12,1),cd_Date,0)),"") | P18: =IFERROR(INDEX(cd_Bud_Ore_Grade_gpt_YTD,MATCH(cfg_YearEnd,cd_Date,0)),"")
C19: Variance | D19: =IF(AND(ISNUMBER(D17),ISNUMBER(D18),D18<>0),D17/D18-1,"") | E19: =IF(AND(ISNUMBER(E17),ISNUMBER(E18),E18<>0),E17/E18-1,"") | F19: =IF(AND(ISNUMBER(F17),ISNUMBER(F18),F18<>0),F17/F18-1,"") | G19: =IF(AND(ISNUMBER(G17),ISNUMBER(G18),G18<>0),G17/G18-1,"") | H19: =IF(AND(ISNUMBER(H17),ISNUMBER(H18),H18<>0),H17/H18-1,"") | I19: =IF(AND(ISNUMBER(I17),ISNUMBER(I18),I18<>0),I17/I18-1,"") | J19: =IF(AND(ISNUMBER(J17),ISNUMBER(J18),J18<>0),J17/J18-1,"") | K19: =IF(AND(ISNUMBER(K17),ISNUMBER(K18),K18<>0),K17/K18-1,"") | ... P19: =IF(AND(ISNUMBER(P17),ISNUMBER(P18),P18<>0),P17/P18-1,"")
B21: Contained gold mined | C21: Actual | D21: =IF(DATE(cfg_Year,1,1)>cfg_LastDataDate,"",IFERROR(INDEX(cd_Ore_Mined_oz_MTD,MATCH(MIN(EOMONTH(DATE(cfg_Year,1,1),0),cfg_LastDataDate),cd_Date,0)),"")) | E21: =IF(DATE(cfg_Year,2,1)>cfg_LastDataDate,"",IFERROR(INDEX(cd_Ore_Mined_oz_MTD,MATCH(MIN(EOMONTH(DATE(cfg_Year,2,1),0),cfg_LastDataDate),cd_Date,0)),"")) | F21: =IF(DATE(cfg_Year,3,1)>cfg_LastDataDate,"",IFERROR(INDEX(cd_Ore_Mined_oz_MTD,MATCH(MIN(EOMONTH(DATE(cfg_Year,3,1),0),cfg_LastDataDate),cd_Date,0)),"")) | G21: =IF(DATE(cfg_Year,4,1)>cfg_LastDataDate,"",IFERROR(INDEX(cd_Ore_Mined_oz_MTD,MATCH(MIN(EOMONTH(DATE(cfg_Year,4,1),0),cfg_LastDataDate),cd_Date,0)),"")) | H21: =IF(DATE(cfg_Year,5,1)>cfg_LastDataDate,"",IFERROR(INDEX(cd_Ore_Mined_oz_MTD,MATCH(MIN(EOMONTH(DATE(cfg_Year,5,1),0),cfg_LastDataDate),cd_Date,0)),"")) | I21: =IF(DATE(cfg_Year,6,1)>cfg_LastDataDate,"",IFERROR(INDEX(cd_Ore_Mined_oz_MTD,MATCH(MIN(EOMONTH(DATE(cfg_Year,6,1),0),cfg_LastDataDate),cd_Date,0)),"")) | J21: =IF(DATE(cfg_Year,7,1)>cfg_LastDataDate,"",IFERROR(INDEX(cd_Ore_Mined_oz_MTD,MATCH(MIN(EOMONTH(DATE(cfg_Year,7,1),0),cfg_LastDataDate),cd_Date,0)),"")) | K21: =IF(DATE(cfg_Year,8,1)>cfg_LastDataDate,"",IFERROR(INDEX(cd_Ore_Mined_oz_MTD,MATCH(MIN(EOMONTH(DATE(cfg_Year,8,1),0),cfg_LastDataDate),cd_Date,0)),"")) | L21: =IF(DATE(cfg_Year,9,1)>cfg_LastDataDate,"",IFERROR(INDEX(cd_Ore_Mined_oz_MTD,MATCH(MIN(EOMONTH(DATE(cfg_Year,9,1),0),cfg_LastDataDate),cd_Date,0)),"")) | M21: =IF(DATE(cfg_Year,10,1)>cfg_LastDataDate,"",IFERROR(INDEX(cd_Ore_Mined_oz_MTD,MATCH(MIN(EOMONTH(DATE(cfg_Year,10,1),0),cfg_LastDataDate),cd_Date,0)),"")) | N21: =IF(DATE(cfg_Year,11,1)>cfg_LastDataDate,"",IFERROR(INDEX(cd_Ore_Mined_oz_MTD,MATCH(MIN(EOMONTH(DATE(cfg_Year,11,1),0),cfg_LastDataDate),cd_Date,0)),"")) | O21: =IF(DATE(cfg_Year,12,1)>cfg_LastDataDate,"",IFERROR(INDEX(cd_Ore_Mined_oz_MTD,MATCH(MIN(EOMONTH(DATE(cfg_Year,12,1),0),cfg_LastDataDate),cd_Date,0)),"")) | P21: =IFERROR(INDEX(cd_Ore_Mined_oz_YTD,MATCH(MIN(cfg_YearEnd,cfg_LastDataDate),cd_Date,0)),"")
C22: Budget | D22: =IFERROR(INDEX(cd_Bud_Ore_Mined_oz_Month,MATCH(DATE(cfg_Year,1,1),cd_Date,0)),"") | E22: =IFERROR(INDEX(cd_Bud_Ore_Mined_oz_Month,MATCH(DATE(cfg_Year,2,1),cd_Date,0)),"") | F22: =IFERROR(INDEX(cd_Bud_Ore_Mined_oz_Month,MATCH(DATE(cfg_Year,3,1),cd_Date,0)),"") | G22: =IFERROR(INDEX(cd_Bud_Ore_Mined_oz_Month,MATCH(DATE(cfg_Year,4,1),cd_Date,0)),"") | H22: =IFERROR(INDEX(cd_Bud_Ore_Mined_oz_Month,MATCH(DATE(cfg_Year,5,1),cd_Date,0)),"") | I22: =IFERROR(INDEX(cd_Bud_Ore_Mined_oz_Month,MATCH(DATE(cfg_Year,6,1),cd_Date,0)),"") | J22: =IFERROR(INDEX(cd_Bud_Ore_Mined_oz_Month,MATCH(DATE(cfg_Year,7,1),cd_Date,0)),"") | K22: =IFERROR(INDEX(cd_Bud_Ore_Mined_oz_Month,MATCH(DATE(cfg_Year,8,1),cd_Date,0)),"") | L22: =IFERROR(INDEX(cd_Bud_Ore_Mined_oz_Month,MATCH(DATE(cfg_Year,9,1),cd_Date,0)),"") | M22: =IFERROR(INDEX(cd_Bud_Ore_Mined_oz_Month,MATCH(DATE(cfg_Year,10,1),cd_Date,0)),"") | N22: =IFERROR(INDEX(cd_Bud_Ore_Mined_oz_Month,MATCH(DATE(cfg_Year,11,1),cd_Date,0)),"") | O22: =IFERROR(INDEX(cd_Bud_Ore_Mined_oz_Month,MATCH(DATE(cfg_Year,12,1),cd_Date,0)),"") | P22: =IFERROR(INDEX(cd_Bud_Ore_Mined_oz_YTD,MATCH(cfg_YearEnd,cd_Date,0)),"")
C23: Variance | D23: =IF(AND(ISNUMBER(D21),ISNUMBER(D22),D22<>0),D21/D22-1,"") | E23: =IF(AND(ISNUMBER(E21),ISNUMBER(E22),E22<>0),E21/E22-1,"") | F23: =IF(AND(ISNUMBER(F21),ISNUMBER(F22),F22<>0),F21/F22-1,"") | G23: =IF(AND(ISNUMBER(G21),ISNUMBER(G22),G22<>0),G21/G22-1,"") | H23: =IF(AND(ISNUMBER(H21),ISNUMBER(H22),H22<>0),H21/H22-1,"") | I23: =IF(AND(ISNUMBER(I21),ISNUMBER(I22),I22<>0),I21/I22-1,"") | J23: =IF(AND(ISNUMBER(J21),ISNUMBER(J22),J22<>0),J21/J22-1,"") | K23: =IF(AND(ISNUMBER(K21),ISNUMBER(K22),K22<>0),K21/K22-1,"") | ... P23: =IF(AND(ISNUMBER(P21),ISNUMBER(P22),P22<>0),P21/P22-1,"")
B25: Waste mined | C25: Actual | D25: =IF(DATE(cfg_Year,1,1)>cfg_LastDataDate,"",IFERROR(INDEX(cd_Waste_t_MTD,MATCH(MIN(EOMONTH(DATE(cfg_Year,1,1),0),cfg_LastDataDate),cd_Date,0)),"")) | E25: =IF(DATE(cfg_Year,2,1)>cfg_LastDataDate,"",IFERROR(INDEX(cd_Waste_t_MTD,MATCH(MIN(EOMONTH(DATE(cfg_Year,2,1),0),cfg_LastDataDate),cd_Date,0)),"")) | F25: =IF(DATE(cfg_Year,3,1)>cfg_LastDataDate,"",IFERROR(INDEX(cd_Waste_t_MTD,MATCH(MIN(EOMONTH(DATE(cfg_Year,3,1),0),cfg_LastDataDate),cd_Date,0)),"")) | G25: =IF(DATE(cfg_Year,4,1)>cfg_LastDataDate,"",IFERROR(INDEX(cd_Waste_t_MTD,MATCH(MIN(EOMONTH(DATE(cfg_Year,4,1),0),cfg_LastDataDate),cd_Date,0)),"")) | H25: =IF(DATE(cfg_Year,5,1)>cfg_LastDataDate,"",IFERROR(INDEX(cd_Waste_t_MTD,MATCH(MIN(EOMONTH(DATE(cfg_Year,5,1),0),cfg_LastDataDate),cd_Date,0)),"")) | I25: =IF(DATE(cfg_Year,6,1)>cfg_LastDataDate,"",IFERROR(INDEX(cd_Waste_t_MTD,MATCH(MIN(EOMONTH(DATE(cfg_Year,6,1),0),cfg_LastDataDate),cd_Date,0)),"")) | J25: =IF(DATE(cfg_Year,7,1)>cfg_LastDataDate,"",IFERROR(INDEX(cd_Waste_t_MTD,MATCH(MIN(EOMONTH(DATE(cfg_Year,7,1),0),cfg_LastDataDate),cd_Date,0)),"")) | K25: =IF(DATE(cfg_Year,8,1)>cfg_LastDataDate,"",IFERROR(INDEX(cd_Waste_t_MTD,MATCH(MIN(EOMONTH(DATE(cfg_Year,8,1),0),cfg_LastDataDate),cd_Date,0)),"")) | L25: =IF(DATE(cfg_Year,9,1)>cfg_LastDataDate,"",IFERROR(INDEX(cd_Waste_t_MTD,MATCH(MIN(EOMONTH(DATE(cfg_Year,9,1),0),cfg_LastDataDate),cd_Date,0)),"")) | M25: =IF(DATE(cfg_Year,10,1)>cfg_LastDataDate,"",IFERROR(INDEX(cd_Waste_t_MTD,MATCH(MIN(EOMONTH(DATE(cfg_Year,10,1),0),cfg_LastDataDate),cd_Date,0)),"")) | N25: =IF(DATE(cfg_Year,11,1)>cfg_LastDataDate,"",IFERROR(INDEX(cd_Waste_t_MTD,MATCH(MIN(EOMONTH(DATE(cfg_Year,11,1),0),cfg_LastDataDate),cd_Date,0)),"")) | O25: =IF(DATE(cfg_Year,12,1)>cfg_LastDataDate,"",IFERROR(INDEX(cd_Waste_t_MTD,MATCH(MIN(EOMONTH(DATE(cfg_Year,12,1),0),cfg_LastDataDate),cd_Date,0)),"")) | P25: =IFERROR(INDEX(cd_Waste_t_YTD,MATCH(MIN(cfg_YearEnd,cfg_LastDataDate),cd_Date,0)),"")
C26: Budget | D26: =IFERROR(INDEX(cd_Bud_Waste_t_Month,MATCH(DATE(cfg_Year,1,1),cd_Date,0)),"") | E26: =IFERROR(INDEX(cd_Bud_Waste_t_Month,MATCH(DATE(cfg_Year,2,1),cd_Date,0)),"") | F26: =IFERROR(INDEX(cd_Bud_Waste_t_Month,MATCH(DATE(cfg_Year,3,1),cd_Date,0)),"") | G26: =IFERROR(INDEX(cd_Bud_Waste_t_Month,MATCH(DATE(cfg_Year,4,1),cd_Date,0)),"") | H26: =IFERROR(INDEX(cd_Bud_Waste_t_Month,MATCH(DATE(cfg_Year,5,1),cd_Date,0)),"") | I26: =IFERROR(INDEX(cd_Bud_Waste_t_Month,MATCH(DATE(cfg_Year,6,1),cd_Date,0)),"") | J26: =IFERROR(INDEX(cd_Bud_Waste_t_Month,MATCH(DATE(cfg_Year,7,1),cd_Date,0)),"") | K26: =IFERROR(INDEX(cd_Bud_Waste_t_Month,MATCH(DATE(cfg_Year,8,1),cd_Date,0)),"") | L26: =IFERROR(INDEX(cd_Bud_Waste_t_Month,MATCH(DATE(cfg_Year,9,1),cd_Date,0)),"") | M26: =IFERROR(INDEX(cd_Bud_Waste_t_Month,MATCH(DATE(cfg_Year,10,1),cd_Date,0)),"") | N26: =IFERROR(INDEX(cd_Bud_Waste_t_Month,MATCH(DATE(cfg_Year,11,1),cd_Date,0)),"") | O26: =IFERROR(INDEX(cd_Bud_Waste_t_Month,MATCH(DATE(cfg_Year,12,1),cd_Date,0)),"") | P26: =IFERROR(INDEX(cd_Bud_Waste_t_YTD,MATCH(cfg_YearEnd,cd_Date,0)),"")
C27: Variance | D27: =IF(AND(ISNUMBER(D25),ISNUMBER(D26),D26<>0),D25/D26-1,"") | E27: =IF(AND(ISNUMBER(E25),ISNUMBER(E26),E26<>0),E25/E26-1,"") | F27: =IF(AND(ISNUMBER(F25),ISNUMBER(F26),F26<>0),F25/F26-1,"") | G27: =IF(AND(ISNUMBER(G25),ISNUMBER(G26),G26<>0),G25/G26-1,"") | H27: =IF(AND(ISNUMBER(H25),ISNUMBER(H26),H26<>0),H25/H26-1,"") | I27: =IF(AND(ISNUMBER(I25),ISNUMBER(I26),I26<>0),I25/I26-1,"") | J27: =IF(AND(ISNUMBER(J25),ISNUMBER(J26),J26<>0),J25/J26-1,"") | K27: =IF(AND(ISNUMBER(K25),ISNUMBER(K26),K26<>0),K25/K26-1,"") | ... P27: =IF(AND(ISNUMBER(P25),ISNUMBER(P26),P26<>0),P25/P26-1,"")
B29: Total material moved | C29: Actual | D29: =IF(DATE(cfg_Year,1,1)>cfg_LastDataDate,"",IFERROR(INDEX(cd_TMM_t_MTD,MATCH(MIN(EOMONTH(DATE(cfg_Year,1,1),0),cfg_LastDataDate),cd_Date,0)),"")) | E29: =IF(DATE(cfg_Year,2,1)>cfg_LastDataDate,"",IFERROR(INDEX(cd_TMM_t_MTD,MATCH(MIN(EOMONTH(DATE(cfg_Year,2,1),0),cfg_LastDataDate),cd_Date,0)),"")) | F29: =IF(DATE(cfg_Year,3,1)>cfg_LastDataDate,"",IFERROR(INDEX(cd_TMM_t_MTD,MATCH(MIN(EOMONTH(DATE(cfg_Year,3,1),0),cfg_LastDataDate),cd_Date,0)),"")) | G29: =IF(DATE(cfg_Year,4,1)>cfg_LastDataDate,"",IFERROR(INDEX(cd_TMM_t_MTD,MATCH(MIN(EOMONTH(DATE(cfg_Year,4,1),0),cfg_LastDataDate),cd_Date,0)),"")) | H29: =IF(DATE(cfg_Year,5,1)>cfg_LastDataDate,"",IFERROR(INDEX(cd_TMM_t_MTD,MATCH(MIN(EOMONTH(DATE(cfg_Year,5,1),0),cfg_LastDataDate),cd_Date,0)),"")) | I29: =IF(DATE(cfg_Year,6,1)>cfg_LastDataDate,"",IFERROR(INDEX(cd_TMM_t_MTD,MATCH(MIN(EOMONTH(DATE(cfg_Year,6,1),0),cfg_LastDataDate),cd_Date,0)),"")) | J29: =IF(DATE(cfg_Year,7,1)>cfg_LastDataDate,"",IFERROR(INDEX(cd_TMM_t_MTD,MATCH(MIN(EOMONTH(DATE(cfg_Year,7,1),0),cfg_LastDataDate),cd_Date,0)),"")) | K29: =IF(DATE(cfg_Year,8,1)>cfg_LastDataDate,"",IFERROR(INDEX(cd_TMM_t_MTD,MATCH(MIN(EOMONTH(DATE(cfg_Year,8,1),0),cfg_LastDataDate),cd_Date,0)),"")) | L29: =IF(DATE(cfg_Year,9,1)>cfg_LastDataDate,"",IFERROR(INDEX(cd_TMM_t_MTD,MATCH(MIN(EOMONTH(DATE(cfg_Year,9,1),0),cfg_LastDataDate),cd_Date,0)),"")) | M29: =IF(DATE(cfg_Year,10,1)>cfg_LastDataDate,"",IFERROR(INDEX(cd_TMM_t_MTD,MATCH(MIN(EOMONTH(DATE(cfg_Year,10,1),0),cfg_LastDataDate),cd_Date,0)),"")) | N29: =IF(DATE(cfg_Year,11,1)>cfg_LastDataDate,"",IFERROR(INDEX(cd_TMM_t_MTD,MATCH(MIN(EOMONTH(DATE(cfg_Year,11,1),0),cfg_LastDataDate),cd_Date,0)),"")) | O29: =IF(DATE(cfg_Year,12,1)>cfg_LastDataDate,"",IFERROR(INDEX(cd_TMM_t_MTD,MATCH(MIN(EOMONTH(DATE(cfg_Year,12,1),0),cfg_LastDataDate),cd_Date,0)),"")) | P29: =IFERROR(INDEX(cd_TMM_t_YTD,MATCH(MIN(cfg_YearEnd,cfg_LastDataDate),cd_Date,0)),"")
C30: Budget | D30: =IFERROR(INDEX(cd_Bud_TMM_t_Month,MATCH(DATE(cfg_Year,1,1),cd_Date,0)),"") | E30: =IFERROR(INDEX(cd_Bud_TMM_t_Month,MATCH(DATE(cfg_Year,2,1),cd_Date,0)),"") | F30: =IFERROR(INDEX(cd_Bud_TMM_t_Month,MATCH(DATE(cfg_Year,3,1),cd_Date,0)),"") | G30: =IFERROR(INDEX(cd_Bud_TMM_t_Month,MATCH(DATE(cfg_Year,4,1),cd_Date,0)),"") | H30: =IFERROR(INDEX(cd_Bud_TMM_t_Month,MATCH(DATE(cfg_Year,5,1),cd_Date,0)),"") | I30: =IFERROR(INDEX(cd_Bud_TMM_t_Month,MATCH(DATE(cfg_Year,6,1),cd_Date,0)),"") | J30: =IFERROR(INDEX(cd_Bud_TMM_t_Month,MATCH(DATE(cfg_Year,7,1),cd_Date,0)),"") | K30: =IFERROR(INDEX(cd_Bud_TMM_t_Month,MATCH(DATE(cfg_Year,8,1),cd_Date,0)),"") | L30: =IFERROR(INDEX(cd_Bud_TMM_t_Month,MATCH(DATE(cfg_Year,9,1),cd_Date,0)),"") | M30: =IFERROR(INDEX(cd_Bud_TMM_t_Month,MATCH(DATE(cfg_Year,10,1),cd_Date,0)),"") | N30: =IFERROR(INDEX(cd_Bud_TMM_t_Month,MATCH(DATE(cfg_Year,11,1),cd_Date,0)),"") | O30: =IFERROR(INDEX(cd_Bud_TMM_t_Month,MATCH(DATE(cfg_Year,12,1),cd_Date,0)),"") | P30: =IFERROR(INDEX(cd_Bud_TMM_t_YTD,MATCH(cfg_YearEnd,cd_Date,0)),"")
C31: Variance | D31: =IF(AND(ISNUMBER(D29),ISNUMBER(D30),D30<>0),D29/D30-1,"") | E31: =IF(AND(ISNUMBER(E29),ISNUMBER(E30),E30<>0),E29/E30-1,"") | F31: =IF(AND(ISNUMBER(F29),ISNUMBER(F30),F30<>0),F29/F30-1,"") | G31: =IF(AND(ISNUMBER(G29),ISNUMBER(G30),G30<>0),G29/G30-1,"") | H31: =IF(AND(ISNUMBER(H29),ISNUMBER(H30),H30<>0),H29/H30-1,"") | I31: =IF(AND(ISNUMBER(I29),ISNUMBER(I30),I30<>0),I29/I30-1,"") | J31: =IF(AND(ISNUMBER(J29),ISNUMBER(J30),J30<>0),J29/J30-1,"") | K31: =IF(AND(ISNUMBER(K29),ISNUMBER(K30),K30<>0),K29/K30-1,"") | ... P31: =IF(AND(ISNUMBER(P29),ISNUMBER(P30),P30<>0),P29/P30-1,"")
B33: Strip ratio (waste : ore) | C33: Actual | D33: =IF(DATE(cfg_Year,1,1)>cfg_LastDataDate,"",IFERROR(INDEX(cd_Strip_Ratio_MTD,MATCH(MIN(EOMONTH(DATE(cfg_Year,1,1),0),cfg_LastDataDate),cd_Date,0)),"")) | E33: =IF(DATE(cfg_Year,2,1)>cfg_LastDataDate,"",IFERROR(INDEX(cd_Strip_Ratio_MTD,MATCH(MIN(EOMONTH(DATE(cfg_Year,2,1),0),cfg_LastDataDate),cd_Date,0)),"")) | F33: =IF(DATE(cfg_Year,3,1)>cfg_LastDataDate,"",IFERROR(INDEX(cd_Strip_Ratio_MTD,MATCH(MIN(EOMONTH(DATE(cfg_Year,3,1),0),cfg_LastDataDate),cd_Date,0)),"")) | G33: =IF(DATE(cfg_Year,4,1)>cfg_LastDataDate,"",IFERROR(INDEX(cd_Strip_Ratio_MTD,MATCH(MIN(EOMONTH(DATE(cfg_Year,4,1),0),cfg_LastDataDate),cd_Date,0)),"")) | H33: =IF(DATE(cfg_Year,5,1)>cfg_LastDataDate,"",IFERROR(INDEX(cd_Strip_Ratio_MTD,MATCH(MIN(EOMONTH(DATE(cfg_Year,5,1),0),cfg_LastDataDate),cd_Date,0)),"")) | I33: =IF(DATE(cfg_Year,6,1)>cfg_LastDataDate,"",IFERROR(INDEX(cd_Strip_Ratio_MTD,MATCH(MIN(EOMONTH(DATE(cfg_Year,6,1),0),cfg_LastDataDate),cd_Date,0)),"")) | J33: =IF(DATE(cfg_Year,7,1)>cfg_LastDataDate,"",IFERROR(INDEX(cd_Strip_Ratio_MTD,MATCH(MIN(EOMONTH(DATE(cfg_Year,7,1),0),cfg_LastDataDate),cd_Date,0)),"")) | K33: =IF(DATE(cfg_Year,8,1)>cfg_LastDataDate,"",IFERROR(INDEX(cd_Strip_Ratio_MTD,MATCH(MIN(EOMONTH(DATE(cfg_Year,8,1),0),cfg_LastDataDate),cd_Date,0)),"")) | L33: =IF(DATE(cfg_Year,9,1)>cfg_LastDataDate,"",IFERROR(INDEX(cd_Strip_Ratio_MTD,MATCH(MIN(EOMONTH(DATE(cfg_Year,9,1),0),cfg_LastDataDate),cd_Date,0)),"")) | M33: =IF(DATE(cfg_Year,10,1)>cfg_LastDataDate,"",IFERROR(INDEX(cd_Strip_Ratio_MTD,MATCH(MIN(EOMONTH(DATE(cfg_Year,10,1),0),cfg_LastDataDate),cd_Date,0)),"")) | N33: =IF(DATE(cfg_Year,11,1)>cfg_LastDataDate,"",IFERROR(INDEX(cd_Strip_Ratio_MTD,MATCH(MIN(EOMONTH(DATE(cfg_Year,11,1),0),cfg_LastDataDate),cd_Date,0)),"")) | O33: =IF(DATE(cfg_Year,12,1)>cfg_LastDataDate,"",IFERROR(INDEX(cd_Strip_Ratio_MTD,MATCH(MIN(EOMONTH(DATE(cfg_Year,12,1),0),cfg_LastDataDate),cd_Date,0)),"")) | P33: =IFERROR(INDEX(cd_Strip_Ratio_YTD,MATCH(MIN(cfg_YearEnd,cfg_LastDataDate),cd_Date,0)),"")
C34: Budget | D34: =IFERROR(INDEX(cd_Bud_Strip_Ratio_Month,MATCH(DATE(cfg_Year,1,1),cd_Date,0)),"") | E34: =IFERROR(INDEX(cd_Bud_Strip_Ratio_Month,MATCH(DATE(cfg_Year,2,1),cd_Date,0)),"") | F34: =IFERROR(INDEX(cd_Bud_Strip_Ratio_Month,MATCH(DATE(cfg_Year,3,1),cd_Date,0)),"") | G34: =IFERROR(INDEX(cd_Bud_Strip_Ratio_Month,MATCH(DATE(cfg_Year,4,1),cd_Date,0)),"") | H34: =IFERROR(INDEX(cd_Bud_Strip_Ratio_Month,MATCH(DATE(cfg_Year,5,1),cd_Date,0)),"") | I34: =IFERROR(INDEX(cd_Bud_Strip_Ratio_Month,MATCH(DATE(cfg_Year,6,1),cd_Date,0)),"") | J34: =IFERROR(INDEX(cd_Bud_Strip_Ratio_Month,MATCH(DATE(cfg_Year,7,1),cd_Date,0)),"") | K34: =IFERROR(INDEX(cd_Bud_Strip_Ratio_Month,MATCH(DATE(cfg_Year,8,1),cd_Date,0)),"") | L34: =IFERROR(INDEX(cd_Bud_Strip_Ratio_Month,MATCH(DATE(cfg_Year,9,1),cd_Date,0)),"") | M34: =IFERROR(INDEX(cd_Bud_Strip_Ratio_Month,MATCH(DATE(cfg_Year,10,1),cd_Date,0)),"") | N34: =IFERROR(INDEX(cd_Bud_Strip_Ratio_Month,MATCH(DATE(cfg_Year,11,1),cd_Date,0)),"") | O34: =IFERROR(INDEX(cd_Bud_Strip_Ratio_Month,MATCH(DATE(cfg_Year,12,1),cd_Date,0)),"") | P34: =IFERROR(INDEX(cd_Bud_Strip_Ratio_YTD,MATCH(cfg_YearEnd,cd_Date,0)),"")
C35: Variance | D35: =IF(AND(ISNUMBER(D33),ISNUMBER(D34),D34<>0),D33/D34-1,"") | E35: =IF(AND(ISNUMBER(E33),ISNUMBER(E34),E34<>0),E33/E34-1,"") | F35: =IF(AND(ISNUMBER(F33),ISNUMBER(F34),F34<>0),F33/F34-1,"") | G35: =IF(AND(ISNUMBER(G33),ISNUMBER(G34),G34<>0),G33/G34-1,"") | H35: =IF(AND(ISNUMBER(H33),ISNUMBER(H34),H34<>0),H33/H34-1,"") | I35: =IF(AND(ISNUMBER(I33),ISNUMBER(I34),I34<>0),I33/I34-1,"") | J35: =IF(AND(ISNUMBER(J33),ISNUMBER(J34),J34<>0),J33/J34-1,"") | K35: =IF(AND(ISNUMBER(K33),ISNUMBER(K34),K34<>0),K33/K34-1,"") | ... P35: =IF(AND(ISNUMBER(P33),ISNUMBER(P34),P34<>0),P33/P34-1,"")
B37: Drilled | C37: Actual | D37: =IF(DATE(cfg_Year,1,1)>cfg_LastDataDate,"",IFERROR(INDEX(cd_Drill_m_MTD,MATCH(MIN(EOMONTH(DATE(cfg_Year,1,1),0),cfg_LastDataDate),cd_Date,0)),"")) | E37: =IF(DATE(cfg_Year,2,1)>cfg_LastDataDate,"",IFERROR(INDEX(cd_Drill_m_MTD,MATCH(MIN(EOMONTH(DATE(cfg_Year,2,1),0),cfg_LastDataDate),cd_Date,0)),"")) | F37: =IF(DATE(cfg_Year,3,1)>cfg_LastDataDate,"",IFERROR(INDEX(cd_Drill_m_MTD,MATCH(MIN(EOMONTH(DATE(cfg_Year,3,1),0),cfg_LastDataDate),cd_Date,0)),"")) | G37: =IF(DATE(cfg_Year,4,1)>cfg_LastDataDate,"",IFERROR(INDEX(cd_Drill_m_MTD,MATCH(MIN(EOMONTH(DATE(cfg_Year,4,1),0),cfg_LastDataDate),cd_Date,0)),"")) | H37: =IF(DATE(cfg_Year,5,1)>cfg_LastDataDate,"",IFERROR(INDEX(cd_Drill_m_MTD,MATCH(MIN(EOMONTH(DATE(cfg_Year,5,1),0),cfg_LastDataDate),cd_Date,0)),"")) | I37: =IF(DATE(cfg_Year,6,1)>cfg_LastDataDate,"",IFERROR(INDEX(cd_Drill_m_MTD,MATCH(MIN(EOMONTH(DATE(cfg_Year,6,1),0),cfg_LastDataDate),cd_Date,0)),"")) | J37: =IF(DATE(cfg_Year,7,1)>cfg_LastDataDate,"",IFERROR(INDEX(cd_Drill_m_MTD,MATCH(MIN(EOMONTH(DATE(cfg_Year,7,1),0),cfg_LastDataDate),cd_Date,0)),"")) | K37: =IF(DATE(cfg_Year,8,1)>cfg_LastDataDate,"",IFERROR(INDEX(cd_Drill_m_MTD,MATCH(MIN(EOMONTH(DATE(cfg_Year,8,1),0),cfg_LastDataDate),cd_Date,0)),"")) | L37: =IF(DATE(cfg_Year,9,1)>cfg_LastDataDate,"",IFERROR(INDEX(cd_Drill_m_MTD,MATCH(MIN(EOMONTH(DATE(cfg_Year,9,1),0),cfg_LastDataDate),cd_Date,0)),"")) | M37: =IF(DATE(cfg_Year,10,1)>cfg_LastDataDate,"",IFERROR(INDEX(cd_Drill_m_MTD,MATCH(MIN(EOMONTH(DATE(cfg_Year,10,1),0),cfg_LastDataDate),cd_Date,0)),"")) | N37: =IF(DATE(cfg_Year,11,1)>cfg_LastDataDate,"",IFERROR(INDEX(cd_Drill_m_MTD,MATCH(MIN(EOMONTH(DATE(cfg_Year,11,1),0),cfg_LastDataDate),cd_Date,0)),"")) | O37: =IF(DATE(cfg_Year,12,1)>cfg_LastDataDate,"",IFERROR(INDEX(cd_Drill_m_MTD,MATCH(MIN(EOMONTH(DATE(cfg_Year,12,1),0),cfg_LastDataDate),cd_Date,0)),"")) | P37: =IFERROR(INDEX(cd_Drill_m_YTD,MATCH(MIN(cfg_YearEnd,cfg_LastDataDate),cd_Date,0)),"")
C38: Budget | D38: =IFERROR(INDEX(cd_Bud_Drill_m_Month,MATCH(DATE(cfg_Year,1,1),cd_Date,0)),"") | E38: =IFERROR(INDEX(cd_Bud_Drill_m_Month,MATCH(DATE(cfg_Year,2,1),cd_Date,0)),"") | F38: =IFERROR(INDEX(cd_Bud_Drill_m_Month,MATCH(DATE(cfg_Year,3,1),cd_Date,0)),"") | G38: =IFERROR(INDEX(cd_Bud_Drill_m_Month,MATCH(DATE(cfg_Year,4,1),cd_Date,0)),"") | H38: =IFERROR(INDEX(cd_Bud_Drill_m_Month,MATCH(DATE(cfg_Year,5,1),cd_Date,0)),"") | I38: =IFERROR(INDEX(cd_Bud_Drill_m_Month,MATCH(DATE(cfg_Year,6,1),cd_Date,0)),"") | J38: =IFERROR(INDEX(cd_Bud_Drill_m_Month,MATCH(DATE(cfg_Year,7,1),cd_Date,0)),"") | K38: =IFERROR(INDEX(cd_Bud_Drill_m_Month,MATCH(DATE(cfg_Year,8,1),cd_Date,0)),"") | L38: =IFERROR(INDEX(cd_Bud_Drill_m_Month,MATCH(DATE(cfg_Year,9,1),cd_Date,0)),"") | M38: =IFERROR(INDEX(cd_Bud_Drill_m_Month,MATCH(DATE(cfg_Year,10,1),cd_Date,0)),"") | N38: =IFERROR(INDEX(cd_Bud_Drill_m_Month,MATCH(DATE(cfg_Year,11,1),cd_Date,0)),"") | O38: =IFERROR(INDEX(cd_Bud_Drill_m_Month,MATCH(DATE(cfg_Year,12,1),cd_Date,0)),"") | P38: =IFERROR(INDEX(cd_Bud_Drill_m_YTD,MATCH(cfg_YearEnd,cd_Date,0)),"")
C39: Variance | D39: =IF(AND(ISNUMBER(D37),ISNUMBER(D38),D38<>0),D37/D38-1,"") | E39: =IF(AND(ISNUMBER(E37),ISNUMBER(E38),E38<>0),E37/E38-1,"") | F39: =IF(AND(ISNUMBER(F37),ISNUMBER(F38),F38<>0),F37/F38-1,"") | G39: =IF(AND(ISNUMBER(G37),ISNUMBER(G38),G38<>0),G37/G38-1,"") | H39: =IF(AND(ISNUMBER(H37),ISNUMBER(H38),H38<>0),H37/H38-1,"") | I39: =IF(AND(ISNUMBER(I37),ISNUMBER(I38),I38<>0),I37/I38-1,"") | J39: =IF(AND(ISNUMBER(J37),ISNUMBER(J38),J38<>0),J37/J38-1,"") | K39: =IF(AND(ISNUMBER(K37),ISNUMBER(K38),K38<>0),K37/K38-1,"") | ... P39: =IF(AND(ISNUMBER(P37),ISNUMBER(P38),P38<>0),P37/P38-1,"")
B41: Milled | C41: Actual | D41: =IF(DATE(cfg_Year,1,1)>cfg_LastDataDate,"",IFERROR(INDEX(cd_Milled_t_MTD,MATCH(MIN(EOMONTH(DATE(cfg_Year,1,1),0),cfg_LastDataDate),cd_Date,0)),"")) | E41: =IF(DATE(cfg_Year,2,1)>cfg_LastDataDate,"",IFERROR(INDEX(cd_Milled_t_MTD,MATCH(MIN(EOMONTH(DATE(cfg_Year,2,1),0),cfg_LastDataDate),cd_Date,0)),"")) | F41: =IF(DATE(cfg_Year,3,1)>cfg_LastDataDate,"",IFERROR(INDEX(cd_Milled_t_MTD,MATCH(MIN(EOMONTH(DATE(cfg_Year,3,1),0),cfg_LastDataDate),cd_Date,0)),"")) | G41: =IF(DATE(cfg_Year,4,1)>cfg_LastDataDate,"",IFERROR(INDEX(cd_Milled_t_MTD,MATCH(MIN(EOMONTH(DATE(cfg_Year,4,1),0),cfg_LastDataDate),cd_Date,0)),"")) | H41: =IF(DATE(cfg_Year,5,1)>cfg_LastDataDate,"",IFERROR(INDEX(cd_Milled_t_MTD,MATCH(MIN(EOMONTH(DATE(cfg_Year,5,1),0),cfg_LastDataDate),cd_Date,0)),"")) | I41: =IF(DATE(cfg_Year,6,1)>cfg_LastDataDate,"",IFERROR(INDEX(cd_Milled_t_MTD,MATCH(MIN(EOMONTH(DATE(cfg_Year,6,1),0),cfg_LastDataDate),cd_Date,0)),"")) | J41: =IF(DATE(cfg_Year,7,1)>cfg_LastDataDate,"",IFERROR(INDEX(cd_Milled_t_MTD,MATCH(MIN(EOMONTH(DATE(cfg_Year,7,1),0),cfg_LastDataDate),cd_Date,0)),"")) | K41: =IF(DATE(cfg_Year,8,1)>cfg_LastDataDate,"",IFERROR(INDEX(cd_Milled_t_MTD,MATCH(MIN(EOMONTH(DATE(cfg_Year,8,1),0),cfg_LastDataDate),cd_Date,0)),"")) | L41: =IF(DATE(cfg_Year,9,1)>cfg_LastDataDate,"",IFERROR(INDEX(cd_Milled_t_MTD,MATCH(MIN(EOMONTH(DATE(cfg_Year,9,1),0),cfg_LastDataDate),cd_Date,0)),"")) | M41: =IF(DATE(cfg_Year,10,1)>cfg_LastDataDate,"",IFERROR(INDEX(cd_Milled_t_MTD,MATCH(MIN(EOMONTH(DATE(cfg_Year,10,1),0),cfg_LastDataDate),cd_Date,0)),"")) | N41: =IF(DATE(cfg_Year,11,1)>cfg_LastDataDate,"",IFERROR(INDEX(cd_Milled_t_MTD,MATCH(MIN(EOMONTH(DATE(cfg_Year,11,1),0),cfg_LastDataDate),cd_Date,0)),"")) | O41: =IF(DATE(cfg_Year,12,1)>cfg_LastDataDate,"",IFERROR(INDEX(cd_Milled_t_MTD,MATCH(MIN(EOMONTH(DATE(cfg_Year,12,1),0),cfg_LastDataDate),cd_Date,0)),"")) | P41: =IFERROR(INDEX(cd_Milled_t_YTD,MATCH(MIN(cfg_YearEnd,cfg_LastDataDate),cd_Date,0)),"")
C42: Budget | D42: =IFERROR(INDEX(cd_Bud_Milled_t_Month,MATCH(DATE(cfg_Year,1,1),cd_Date,0)),"") | E42: =IFERROR(INDEX(cd_Bud_Milled_t_Month,MATCH(DATE(cfg_Year,2,1),cd_Date,0)),"") | F42: =IFERROR(INDEX(cd_Bud_Milled_t_Month,MATCH(DATE(cfg_Year,3,1),cd_Date,0)),"") | G42: =IFERROR(INDEX(cd_Bud_Milled_t_Month,MATCH(DATE(cfg_Year,4,1),cd_Date,0)),"") | H42: =IFERROR(INDEX(cd_Bud_Milled_t_Month,MATCH(DATE(cfg_Year,5,1),cd_Date,0)),"") | I42: =IFERROR(INDEX(cd_Bud_Milled_t_Month,MATCH(DATE(cfg_Year,6,1),cd_Date,0)),"") | J42: =IFERROR(INDEX(cd_Bud_Milled_t_Month,MATCH(DATE(cfg_Year,7,1),cd_Date,0)),"") | K42: =IFERROR(INDEX(cd_Bud_Milled_t_Month,MATCH(DATE(cfg_Year,8,1),cd_Date,0)),"") | L42: =IFERROR(INDEX(cd_Bud_Milled_t_Month,MATCH(DATE(cfg_Year,9,1),cd_Date,0)),"") | M42: =IFERROR(INDEX(cd_Bud_Milled_t_Month,MATCH(DATE(cfg_Year,10,1),cd_Date,0)),"") | N42: =IFERROR(INDEX(cd_Bud_Milled_t_Month,MATCH(DATE(cfg_Year,11,1),cd_Date,0)),"") | O42: =IFERROR(INDEX(cd_Bud_Milled_t_Month,MATCH(DATE(cfg_Year,12,1),cd_Date,0)),"") | P42: =IFERROR(INDEX(cd_Bud_Milled_t_YTD,MATCH(cfg_YearEnd,cd_Date,0)),"")
C43: Variance | D43: =IF(AND(ISNUMBER(D41),ISNUMBER(D42),D42<>0),D41/D42-1,"") | E43: =IF(AND(ISNUMBER(E41),ISNUMBER(E42),E42<>0),E41/E42-1,"") | F43: =IF(AND(ISNUMBER(F41),ISNUMBER(F42),F42<>0),F41/F42-1,"") | G43: =IF(AND(ISNUMBER(G41),ISNUMBER(G42),G42<>0),G41/G42-1,"") | H43: =IF(AND(ISNUMBER(H41),ISNUMBER(H42),H42<>0),H41/H42-1,"") | I43: =IF(AND(ISNUMBER(I41),ISNUMBER(I42),I42<>0),I41/I42-1,"") | J43: =IF(AND(ISNUMBER(J41),ISNUMBER(J42),J42<>0),J41/J42-1,"") | K43: =IF(AND(ISNUMBER(K41),ISNUMBER(K42),K42<>0),K41/K42-1,"") | ... P43: =IF(AND(ISNUMBER(P41),ISNUMBER(P42),P42<>0),P41/P42-1,"")
B45: Head grade | C45: Actual | D45: =IF(DATE(cfg_Year,1,1)>cfg_LastDataDate,"",IFERROR(INDEX(cd_Head_Grade_gpt_MTD,MATCH(MIN(EOMONTH(DATE(cfg_Year,1,1),0),cfg_LastDataDate),cd_Date,0)),"")) | E45: =IF(DATE(cfg_Year,2,1)>cfg_LastDataDate,"",IFERROR(INDEX(cd_Head_Grade_gpt_MTD,MATCH(MIN(EOMONTH(DATE(cfg_Year,2,1),0),cfg_LastDataDate),cd_Date,0)),"")) | F45: =IF(DATE(cfg_Year,3,1)>cfg_LastDataDate,"",IFERROR(INDEX(cd_Head_Grade_gpt_MTD,MATCH(MIN(EOMONTH(DATE(cfg_Year,3,1),0),cfg_LastDataDate),cd_Date,0)),"")) | G45: =IF(DATE(cfg_Year,4,1)>cfg_LastDataDate,"",IFERROR(INDEX(cd_Head_Grade_gpt_MTD,MATCH(MIN(EOMONTH(DATE(cfg_Year,4,1),0),cfg_LastDataDate),cd_Date,0)),"")) | H45: =IF(DATE(cfg_Year,5,1)>cfg_LastDataDate,"",IFERROR(INDEX(cd_Head_Grade_gpt_MTD,MATCH(MIN(EOMONTH(DATE(cfg_Year,5,1),0),cfg_LastDataDate),cd_Date,0)),"")) | I45: =IF(DATE(cfg_Year,6,1)>cfg_LastDataDate,"",IFERROR(INDEX(cd_Head_Grade_gpt_MTD,MATCH(MIN(EOMONTH(DATE(cfg_Year,6,1),0),cfg_LastDataDate),cd_Date,0)),"")) | J45: =IF(DATE(cfg_Year,7,1)>cfg_LastDataDate,"",IFERROR(INDEX(cd_Head_Grade_gpt_MTD,MATCH(MIN(EOMONTH(DATE(cfg_Year,7,1),0),cfg_LastDataDate),cd_Date,0)),"")) | K45: =IF(DATE(cfg_Year,8,1)>cfg_LastDataDate,"",IFERROR(INDEX(cd_Head_Grade_gpt_MTD,MATCH(MIN(EOMONTH(DATE(cfg_Year,8,1),0),cfg_LastDataDate),cd_Date,0)),"")) | L45: =IF(DATE(cfg_Year,9,1)>cfg_LastDataDate,"",IFERROR(INDEX(cd_Head_Grade_gpt_MTD,MATCH(MIN(EOMONTH(DATE(cfg_Year,9,1),0),cfg_LastDataDate),cd_Date,0)),"")) | M45: =IF(DATE(cfg_Year,10,1)>cfg_LastDataDate,"",IFERROR(INDEX(cd_Head_Grade_gpt_MTD,MATCH(MIN(EOMONTH(DATE(cfg_Year,10,1),0),cfg_LastDataDate),cd_Date,0)),"")) | N45: =IF(DATE(cfg_Year,11,1)>cfg_LastDataDate,"",IFERROR(INDEX(cd_Head_Grade_gpt_MTD,MATCH(MIN(EOMONTH(DATE(cfg_Year,11,1),0),cfg_LastDataDate),cd_Date,0)),"")) | O45: =IF(DATE(cfg_Year,12,1)>cfg_LastDataDate,"",IFERROR(INDEX(cd_Head_Grade_gpt_MTD,MATCH(MIN(EOMONTH(DATE(cfg_Year,12,1),0),cfg_LastDataDate),cd_Date,0)),"")) | P45: =IFERROR(INDEX(cd_Head_Grade_gpt_YTD,MATCH(MIN(cfg_YearEnd,cfg_LastDataDate),cd_Date,0)),"")
C46: Budget | D46: =IFERROR(INDEX(cd_Bud_Head_Grade_gpt_Month,MATCH(DATE(cfg_Year,1,1),cd_Date,0)),"") | E46: =IFERROR(INDEX(cd_Bud_Head_Grade_gpt_Month,MATCH(DATE(cfg_Year,2,1),cd_Date,0)),"") | F46: =IFERROR(INDEX(cd_Bud_Head_Grade_gpt_Month,MATCH(DATE(cfg_Year,3,1),cd_Date,0)),"") | G46: =IFERROR(INDEX(cd_Bud_Head_Grade_gpt_Month,MATCH(DATE(cfg_Year,4,1),cd_Date,0)),"") | H46: =IFERROR(INDEX(cd_Bud_Head_Grade_gpt_Month,MATCH(DATE(cfg_Year,5,1),cd_Date,0)),"") | I46: =IFERROR(INDEX(cd_Bud_Head_Grade_gpt_Month,MATCH(DATE(cfg_Year,6,1),cd_Date,0)),"") | J46: =IFERROR(INDEX(cd_Bud_Head_Grade_gpt_Month,MATCH(DATE(cfg_Year,7,1),cd_Date,0)),"") | K46: =IFERROR(INDEX(cd_Bud_Head_Grade_gpt_Month,MATCH(DATE(cfg_Year,8,1),cd_Date,0)),"") | L46: =IFERROR(INDEX(cd_Bud_Head_Grade_gpt_Month,MATCH(DATE(cfg_Year,9,1),cd_Date,0)),"") | M46: =IFERROR(INDEX(cd_Bud_Head_Grade_gpt_Month,MATCH(DATE(cfg_Year,10,1),cd_Date,0)),"") | N46: =IFERROR(INDEX(cd_Bud_Head_Grade_gpt_Month,MATCH(DATE(cfg_Year,11,1),cd_Date,0)),"") | O46: =IFERROR(INDEX(cd_Bud_Head_Grade_gpt_Month,MATCH(DATE(cfg_Year,12,1),cd_Date,0)),"") | P46: =IFERROR(INDEX(cd_Bud_Head_Grade_gpt_YTD,MATCH(cfg_YearEnd,cd_Date,0)),"")
C47: Variance | D47: =IF(AND(ISNUMBER(D45),ISNUMBER(D46),D46<>0),D45/D46-1,"") | E47: =IF(AND(ISNUMBER(E45),ISNUMBER(E46),E46<>0),E45/E46-1,"") | F47: =IF(AND(ISNUMBER(F45),ISNUMBER(F46),F46<>0),F45/F46-1,"") | G47: =IF(AND(ISNUMBER(G45),ISNUMBER(G46),G46<>0),G45/G46-1,"") | H47: =IF(AND(ISNUMBER(H45),ISNUMBER(H46),H46<>0),H45/H46-1,"") | I47: =IF(AND(ISNUMBER(I45),ISNUMBER(I46),I46<>0),I45/I46-1,"") | J47: =IF(AND(ISNUMBER(J45),ISNUMBER(J46),J46<>0),J45/J46-1,"") | K47: =IF(AND(ISNUMBER(K45),ISNUMBER(K46),K46<>0),K45/K46-1,"") | ... P47: =IF(AND(ISNUMBER(P45),ISNUMBER(P46),P46<>0),P45/P46-1,"")
B49: Recovery | C49: Actual | D49: =IF(DATE(cfg_Year,1,1)>cfg_LastDataDate,"",IFERROR(INDEX(cd_Recovery_pct_MTD,MATCH(MIN(EOMONTH(DATE(cfg_Year,1,1),0),cfg_LastDataDate),cd_Date,0)),"")) | E49: =IF(DATE(cfg_Year,2,1)>cfg_LastDataDate,"",IFERROR(INDEX(cd_Recovery_pct_MTD,MATCH(MIN(EOMONTH(DATE(cfg_Year,2,1),0),cfg_LastDataDate),cd_Date,0)),"")) | F49: =IF(DATE(cfg_Year,3,1)>cfg_LastDataDate,"",IFERROR(INDEX(cd_Recovery_pct_MTD,MATCH(MIN(EOMONTH(DATE(cfg_Year,3,1),0),cfg_LastDataDate),cd_Date,0)),"")) | G49: =IF(DATE(cfg_Year,4,1)>cfg_LastDataDate,"",IFERROR(INDEX(cd_Recovery_pct_MTD,MATCH(MIN(EOMONTH(DATE(cfg_Year,4,1),0),cfg_LastDataDate),cd_Date,0)),"")) | H49: =IF(DATE(cfg_Year,5,1)>cfg_LastDataDate,"",IFERROR(INDEX(cd_Recovery_pct_MTD,MATCH(MIN(EOMONTH(DATE(cfg_Year,5,1),0),cfg_LastDataDate),cd_Date,0)),"")) | I49: =IF(DATE(cfg_Year,6,1)>cfg_LastDataDate,"",IFERROR(INDEX(cd_Recovery_pct_MTD,MATCH(MIN(EOMONTH(DATE(cfg_Year,6,1),0),cfg_LastDataDate),cd_Date,0)),"")) | J49: =IF(DATE(cfg_Year,7,1)>cfg_LastDataDate,"",IFERROR(INDEX(cd_Recovery_pct_MTD,MATCH(MIN(EOMONTH(DATE(cfg_Year,7,1),0),cfg_LastDataDate),cd_Date,0)),"")) | K49: =IF(DATE(cfg_Year,8,1)>cfg_LastDataDate,"",IFERROR(INDEX(cd_Recovery_pct_MTD,MATCH(MIN(EOMONTH(DATE(cfg_Year,8,1),0),cfg_LastDataDate),cd_Date,0)),"")) | L49: =IF(DATE(cfg_Year,9,1)>cfg_LastDataDate,"",IFERROR(INDEX(cd_Recovery_pct_MTD,MATCH(MIN(EOMONTH(DATE(cfg_Year,9,1),0),cfg_LastDataDate),cd_Date,0)),"")) | M49: =IF(DATE(cfg_Year,10,1)>cfg_LastDataDate,"",IFERROR(INDEX(cd_Recovery_pct_MTD,MATCH(MIN(EOMONTH(DATE(cfg_Year,10,1),0),cfg_LastDataDate),cd_Date,0)),"")) | N49: =IF(DATE(cfg_Year,11,1)>cfg_LastDataDate,"",IFERROR(INDEX(cd_Recovery_pct_MTD,MATCH(MIN(EOMONTH(DATE(cfg_Year,11,1),0),cfg_LastDataDate),cd_Date,0)),"")) | O49: =IF(DATE(cfg_Year,12,1)>cfg_LastDataDate,"",IFERROR(INDEX(cd_Recovery_pct_MTD,MATCH(MIN(EOMONTH(DATE(cfg_Year,12,1),0),cfg_LastDataDate),cd_Date,0)),"")) | P49: =IFERROR(INDEX(cd_Recovery_pct_YTD,MATCH(MIN(cfg_YearEnd,cfg_LastDataDate),cd_Date,0)),"")
